Workbook

Sheet EN PROCESO (Alfa)
A1: Asignado a | B1: # REQ | C1: Requerimiento | D1: Detalle del requerimiento | E1: Proceso | F1: ESTADO | G1: % | H1: Dias estimados desarrollo | I1: F.Asignado | J1: Fecha inicio | K1: Fecha estimada de entrega | L1: Finalizado | M1: Dias total desarrollo | N1: Fecha compromiso cliente | O1: TEST | P1: PRODUCCION | Q1: OBSERVACIONES | R1: Visible | S1: OBSERVACIONES ALFA
A2: MAURICIO | B2: PRV_2025_001_1 | C2: REVISIÓN DE LIQUIDACIÓN PARA PAGO, | E2: Previsional | F2: FINALIZADO | G2: 100 | H2: =IF(OR(J2="",K2="",K2<J2),0,NETWORKDAYS(J2,K2,fESTIVOS!$A$2:$A$53)) -> 90 | J2: 45691 | K2: 45821 | L2: 45824 | M2: =IF(OR(J2="",AND(L2="",TODAY()<J2),AND(L2<>"",L2<J2)),0, IF(L2="", NETWORKDAYS(J2,TODAY(),fESTIVOS!$A$2:$A$53), NETWORKDAYS(J2,L2,fESTIVOS!$A$2:$A$53) ) ) -> 91 | P2: 45843 | Q2: Se notifica por par parte del jefe de unidad inconsistencias en Vistas de las fuentes de información entregadas. Carecen de data necesaria, 09/06/2025 :El requerimirneo fue pausado 12 mayo de 2025 10/06/2025: Hoy se definira si se contunua con el desarrollo o continua pausado. 11/06/2025: Ya se cuenta con los permisos y el query para la vista. Se sincronizan las reclamaciones de Cifren, pero falta integrar las de Plus (montadas en AWS) y ajustar la identificación del origen de cada reclamación. Se estima que este requerimiento adicional tomará un día de trabajo Iniciando el 12 de Junio 13/06/2025: Se obtuvo respuesta positiva sobre permisos para acceder a la vista de Plus. Sin embargo, falta que la vista tenga datos reales para completar la sincronización. 16/06/2025 : Se completó la primera fase de validación y hoy se trabaja en la parte de gestión de pagos, cliente realizara pruebas hoy 17/06/2025: Se realizan en ajustes en la mañana de hallasgoz reportados por el cliente tras las pruebas, y se entregaran al cliente para sus pruebas. 18/06/2025: Se adaptó el grid y los reportes a los distintos roles/permisos. También se incorporaron nuevos campos a solicitud del cliente; pendiente Pruebas por el cliente. 19/06/2025; supero pruebas del cliente y se aprueba paso a produccion para el dia sabado 21 de Junio.. 24/06/2025; Alfa aplazó el paso a produccion para el 5 de julio, debido a que tenían actualizaciones pendientes. Además, dependemos de la disponibilidad de ciertas vistas en el ambiente de producción para continuar con el proceso. 07/07/2025: Se realiza paso a produccion el 5 de julio. | R2: TRUE
A3: MAURICIO | B3: PRV_2025_001_2 | C3: VALIDACIÓN DE LOTE PARA PAGO, NOTIFICACIÓN DE PAGO | E3: Previsional | F3: FINALIZADO | G3: 100 | H3: =IF(OR(J3="",K3="",K3<J3),0,NETWORKDAYS(J3,K3,fESTIVOS!$A$2:$A$53)) -> 3 | I3: 45824 | J3: 45824 | K3: 45826 | L3: 45827 | M3: =IF(OR(J3="",AND(L3="",TODAY()<J3),AND(L3<>"",L3<J3)),0, IF(L3="", NETWORKDAYS(J3,TODAY(),fESTIVOS!$A$2:$A$53), NETWORKDAYS(J3,L3,fESTIVOS!$A$2:$A$53) ) ) -> 4 | P3: 45843 | Q3: El 16 de junio se inicia desarrollo confecha estimada de finalizacion 18 de junio. 18/06/2025: El 17 de junio se desarrollan dos informes adicionales: tesorería y porvenir, con definición de estructura en curso. 19/06/2025: Entrega al cliente para pruebas 19 de junio, Cliente solicita ajuste de vistas y campos necesarios para el proceso. 24/06/2025; Alfa aplazó el paso a produccion para el 5 de julio, debido a que tenían actualizaciones pendientes 07/07/2025: Se realiza paso a produccion el 5 de julio. | R3: TRUE
A4: MAURICIO | B4: PRV_2025_004 | C4: AUXILIOS FUNERARIOS PAGO AUX. FUNERARIOS | E4: Previsional | F4: FINALIZADO | G4: 100 | H4: =IF(OR(J4="",K4="",K4<J4),0,NETWORKDAYS(J4,K4,fESTIVOS!$A$2:$A$53)) -> 4 | J4: 45827 | K4: 45833 | L4: 45841 | M4: =IF(OR(J4="",AND(L4="",TODAY()<J4),AND(L4<>"",L4<J4)),0, IF(L4="", NETWORKDAYS(J4,TODAY(),fESTIVOS!$A$2:$A$53), NETWORKDAYS(J4,L4,fESTIVOS!$A$2:$A$53) ) ) -> 9 | P4: 45843 | Q4: Cargue de formatos de formalización y consolidado 100% Opción de edición y opción de histórico del flujo 100% Se notifica por par parte del jefe de unidad inconsistencias en Vistas de las fuentes de información entregadas. Carecen de data necesaria 09/06/2025 :El requerimirneo fue pausado el 6 de junio de 2025. 16/06/2025: Se comenzarán el jueves 19 de junio. Ya se están creando las vistas necesarias para ese flujo 19/06/2025: Inicio del desarrollo. 20/06/2025:No se pudo avanzar ayer 19 de junio por ajustes requeridos por el cliente para PRV_2025_001 VALIDACIÓN DE LOTE PARA PAGO,NOTIFICACIÓN DE PAGO, Se retomara desarrollo 24 de junio. 24/06/2025; Se encuentra sincronizando data, se estiman 2 dias para finalizar. 25/06/2025:Se ajustó la lógica del requerimiento tras diferenciarlo claramente del flujo de pagos. Se avanzó en la creación de vistas y en la sincronización inicial de datos. Se espera tener el desarrollo listo para pruebas el jueves 26. Se planea agregar botones para sincronización (Pago,auxilio y exportar) diferenciada según permisos,crear tabla de auxilios x año, ajustar campos (encabezados)de la vista de gestion y ajustar modulo de consulta. 26/06/2025: Se avanzó satisfactoriamente en la creación de la tabla de auxilios por año, el ajuste de encabezados en la vista de gestión y la incorporación de los botones de sincronización según permisos. PENDIENTE, Está pendiente la solución del error en la sincronización masiva, lo cual impide avanzar con la exportación y cargue de información. También sigue sin ajustes el módulo de consulta para auxilios. 27/06/2025: pendiente: 1. asignar opcion de pendientes 2. Ver consolidado pagos. (se envia masivamente y aprueba por el flujo para pasar a pagos). 3. Generar informe radicacion pagos plus. Se estima toda la entrega para hoy 01/07/2025: Se ha avanzado en un 75% del desarrollo, incluyendo funcionalidades principales. El cierre del tema está previsto para hoy, Faltan por implementar la generación de informes, la edición de fecha de siniestro y valor, así como la opción de marcar como pendiente. 02/07/2025:El desarrollo del módulo de auxilios funerarios presenta un avance estimado del 90%. Ya se encuentra implementada la funcionalidad principal, incluyendo la creación de vistas, funciones de sincronización y flujo de radicación hasta aprobación. Se están finalizando los ajustes a los reportes en Excel, Se programó una sesión de revisión hoy a las 2:00 p.m. para validación funcional y ajuste de pendientes. 04/07/2025: Se resolvió un error en la validación de pagos, el módulo ya está funcional. Se finalizó el desarrollo y se ajustaron validaciones necesarias para la gestión masiva y manual. Solo queda pendiente la validación del cliente, ya que la sesión programada fue cancelada. 07/07/2025: Se Pasado a producción el 5 de julio sin habilitar el menú. Faltan validaciones finales por el cliiente. 16/07/2025: Las pruebas no se han culminado por un error en el sistema del cliente al cargar unos registros. Sin estos registros no puedo ver la data que necesitamos en Imagine. 29/07/2025: Se proyecta acompañar al àrea para realizar pruebas con los recursos existentes para ya dejar cerrado el requerimiento 01/08/2025: Hoy se retoma el módulo con el cliente, para validar que se tiene hasta el momento, funcionalidad y posibles desviaciones, para dar gestion y cierre del requerimiento 04/08/2025: Se continùa validaciones y ajustes correspondientes para proyectar paso a producciòn el viernes 08 de agosto 12/08/2025: Debido a incidencia presentada en la conexión Plus + UAT , no fue posible el paso a producciòn el viernes 08 de agosto, por tanto se proyecta el despliegue para el viernes 15 de agosto 20/08/2025: Despliegue a produccion realizado en 15 de Agosto. | R4: TRUE | S4: 15/07/2025 Ya se encuenra en produccion
A5: MAURICIO | B5: PRV_2025_009 | C5: DESARROLLO PREVISIONALES INCAPACIDADES | E5: Previsional | F5: FINALIZADO | G5: 100 | H5: =IF(OR(J5="",K5="",K5<J5),0,NETWORKDAYS(J5,K5,fESTIVOS!$A$2:$A$53)) -> 3 | I5: 45817 | J5: 45817 | K5: 45819 | L5: 45820 | M5: =IF(OR(J5="",AND(L5="",TODAY()<J5),AND(L5<>"",L5<J5)),0, IF(L5="", NETWORKDAYS(J5,TODAY(),fESTIVOS!$A$2:$A$53), NETWORKDAYS(J5,L5,fESTIVOS!$A$2:$A$53) ) ) -> 4 | P5: 45843 | Q5: 09/06/2025: El Objetivo Automatizar el cálculo de incapacidades en el sistema Imagine, replicando el proceso manual actual utilizado por los liquidadores y presentando los resultados en un formato claro y compatible con Excel.\niniciara con el desarrollo. 11/06/2025: Mauricio completó la función de cálculo y está terminando el formulario de consulta. Planea entregar el requerimiento completo hoy para subir a pruebas el jueves. 13/06/2025: Ya fue entregado en ambiente de pruebas para validación del cliente. Está funcionando correctamente y aplicando los cálculos según lo solicitado. 9/06/2025: Paso a produccion para el 21 de junio. 24/06/2025: Fala aplazó el paso a produccion para el 5 de julio, debido a que tenían actualizaciones pendientes. 07/07/2025: Igual que Auxilios se paso a producciòn el 5 de julio sin habilitar el menu. Se requiere validación del cliente para habilitar. 16/07/2025: Requerimiento funcional en produccion con el menu habiitado. | R5: TRUE | S5: 15/07/2025 Ya se encuenra en produccion
A6: MAURICIO | B6: PRV_2025_007 | C6: CALCULO IBL | E6: Previsional | F6: FINALIZADO | G6: 100 | H6: =IF(OR(J6="",K6="",K6<J6),0,NETWORKDAYS(J6,K6,fESTIVOS!$A$2:$A$53)) -> 2 | I6: 45817 | J6: 45841 | K6: 45842 | L6: 45842 | M6: =IF(OR(J6="",AND(L6="",TODAY()<J6),AND(L6<>"",L6<J6)),0, IF(L6="", NETWORKDAYS(J6,TODAY(),fESTIVOS!$A$2:$A$53), NETWORKDAYS(J6,L6,fESTIVOS!$A$2:$A$53) ) ) -> 2 | P6: 45852 | Q6: 11/06/2025: Continuara con el desarrollo tras finalizar req PRV_2025_001 REVISIÓN DE LIQUIDACIÓN PARA PAGO 13/06/2025:Se programó su inicio para hoy. Mauricio confirmara la estimación del tiempo de desarrollo. 16/06/2025: Se requiere una sesion con Carlos, Jenry, Mauricio y Fabio para entender el detalle de validaciones. Aún no se tiene fecha ni estimación. 04/07/2015:Se inicia desarrollo con un avance del 20%. Se ajustaron funciones en Postgres para cálculos correctos según las vistas generadas. El siguiente paso es crear la funcionalidad de consulta por cédula o siniestro y desplegar cálculos de acuerdo a la fecha indicada. Se estima finalizar req hoy para realizar paso a produccion el 5 de julio. 07/07/2025: Se realizo paso a producciòn el 5 de Julio sin habiitar el menu, Faltan pruebas formales del cliente para habilitación final. 11/07/2025: El 10 de julio se realizó un ajuste para excluir los casos con auxilios funerarios. Ahora, el sistema valida que el origen del caso sea únicamente incapacidad o supervivencia; en caso contrario, se lanza una alerta. 16/07/2025: Se realiza paso a producción el 14 de julio en la noche. | R6: TRUE | S6: 10/07/2025 Posterior a pruebas se solicito ajuste a Mauricio para que no mostrara informacion diferentes a cod_origen 1,2 15/07/2025 Ya se encuenra en produccion
A7: MAURICIO | B7: PRV_2025_005 | C7: HISTORIA LABORAL | E7: Rentas | F7: FINALIZADO | G7: 100 | H7: =IF(OR(J7="",K7="",K7<J7),0,NETWORKDAYS(J7,K7,fESTIVOS!$A$2:$A$53)) -> 0 | I7: 45817 | J7: 45845 | L7: 45847 | M7: =IF(OR(J7="",AND(L7="",TODAY()<J7),AND(L7<>"",L7<J7)),0, IF(L7="", NETWORKDAYS(J7,TODAY(),fESTIVOS!$A$2:$A$53), NETWORKDAYS(J7,L7,fESTIVOS!$A$2:$A$53) ) ) -> 3 | P7: 45852 | Q7: 11/06/2025: Continuara con el desarrollo tras finalizar req PRV_2025_007 CALCULO IBL 07/07/2025: Inicia desarrollo 08/07/2025: Se reporta un avance del 50 % entre analisis y desarrollo del requerimeinto. 09/07/2025: Se Finaliza desarrollo y se entrega al cliente para pruebas. 14/07/2025: El 10 de julio se ajustó el reporte para incluir los períodos que existen en Multifondos pero no en Alfa. Adicionalmente, se incorporó una nueva columna que muestra el salario mensualizado proveniente de Porvenir. Los cambios ya fueron implementados y se encuentran listos para validación. 16/07/2025: Se realiza paso a producción el 14 de julio en la noche. | R7: TRUE | S7: 10/07/2025 Posterior a pruebas se solicito a Mauricio ajustes para visualizar los periodos a los cuales no se realizo analisis y tambien columna adicional para periodos falsos con calculo de el valor del los dias (Valor salario MF * 30) / Dias cotizados 11/07/2025: El 10 de julio se ajustó el reporte para incluir periodos que existan en multifondos pero no en Alfa. Se agregó una columna adicional para mostrar el salario mensualizado proveniente de Porvenir. Cambios ya implementados y listos para validación. 15/07/2025 Ya se encuenra en produccion
A8: MAURICIO | B8: AJUST_REN_2025_001_1 | C8: INCLUIR VALIDACION DOCUMENTAL PARA NUEVO ORIGEN SUSTITUCION PENSIONAL I | E8: Rentas | F8: FINALIZADO | G8: 100 | H8: =IF(OR(J8="",K8="",K8<J8),0,NETWORKDAYS(J8,K8,fESTIVOS!$A$2:$A$53)) -> 0 | I8: 45834 | J8: 45848 | L8: 45822 | M8: =IF(OR(J8="",AND(L8="",TODAY()<J8),AND(L8<>"",L8<J8)),0, IF(L8="", NETWORKDAYS(J8,TODAY(),fESTIVOS!$A$2:$A$53), NETWORKDAYS(J8,L8,fESTIVOS!$A$2:$A$53) ) ) -> 0 | P8: 45852 | Q8: 11/07/2025: Dado que ya se crearon las tablas de referencia, se finalizó este proceso el día 10 de julio. Queda pendiente validar el impacto que estas puedan tener en los diferentes módulos y consultas del sistema para que el cliente realice las pruebas. 14/07/2025: El viernes 11 se valida en ambiente de pruebas los ajustes realizados, confirmando funcionamiento correcto en: cargue de cotización y contratación, gestión telefónica desde call center, exportación del informe de Presidencia y descarga de documentos. Quedan pendientes por validar: envío de correos del portafolio de servicios, envío de comprobantes de nómina y validación de consultas.\n Hoy se trabajará en los informes que deben reflejar esta nueva parametrización y se verificará si afecta portafolios o comprobantes de nómina. 15/07/2025: El lunes 14 de julio se finalizó el desarrollo del ajuste, se realizaron las pruebas correspondientes con resultados exitosos y se procedió con el paso a producción. | R8: TRUE | S8: 26/06/2025 Se incluyen requerimientos de acuerdo a sesiones con el cliente. Corresponde a ajustes a plataforma ya en produccion 10/07/2025 ya que crearon las tablas de referencia. pendiente validar el impacto en los diferetnes modulos y consutas. 11/07/2025 Se valida ajustes realizados por mauricio en pruebas posterior a la incluision de nuevo ORIGEN. Para esto se confirma que esta correcto: 1. Cargue cotizacion y contratacion 2. Gestion telefonica call center 3. Exportar informe Presidencia 4. Descarga de documentos con nuevo Origen.) PENDIENTES: 5. Envio correos Portafolio de servicio 6. Envio Comprobantes de nomina 7. Valdacion de consultas. 15/07/2025 Ya se encuenra en produccion
A9: MAURICIO | B9: AJUST_REN_2025_001_2 | C9: INFORME DE PRESIDENCIA (Validación Documental Rentas) | E9: Rentas | F9: FINALIZADO | G9: 100 | H9: =IF(OR(J9="",K9="",K9<J9),0,NETWORKDAYS(J9,K9,fESTIVOS!$A$2:$A$53)) -> 0 | I9: 45834 | J9: 45848 | L9: 45848 | M9: =IF(OR(J9="",AND(L9="",TODAY()<J9),AND(L9<>"",L9<J9)),0, IF(L9="", NETWORKDAYS(J9,TODAY(),fESTIVOS!$A$2:$A$53), NETWORKDAYS(J9,L9,fESTIVOS!$A$2:$A$53) ) ) -> 1 | Q9: 10/07/2025: Se realizaron los ajustes solicitados por el área y estos ya fueron entregados en el ambiente de producción. El cliente efectuó las pruebas correspondientes y confirmó que el ajuste fue aplicado correctamente. | R9: TRUE | S9: 26/06/2025 Se incluyen requerimientos de acuerdo a sesiones con el cliente. Corresponde a ajustes a plataforma ya en produccion 10/07/2025 Se realizan ajustes solicitados por el area. Y ya se entregaron en produccion. El cliente realizo pruebas y confirmo ajuste.
A10: MAURICIO | B10: AJUST_REN_2025_001_3 | C10: CAMBIO DE ESTADO DE IMÁGENES PARA RENTAS NO CONTRATADAS | E10: Rentas | F10: FINALIZADO | G10: 100 | H10: =IF(OR(J10="",K10="",K10<J10),0,NETWORKDAYS(J10,K10,fESTIVOS!$A$2:$A$53)) -> 0 | I10: 45834 | J10: 45854 | L10: 45855 | M10: =IF(OR(J10="",AND(L10="",TODAY()<J10),AND(L10<>"",L10<J10)),0, IF(L10="", NETWORKDAYS(J10,TODAY(),fESTIVOS!$A$2:$A$53), NETWORKDAYS(J10,L10,fESTIVOS!$A$2:$A$53) ) ) -> 2 | P10: 45855 | Q10: 15/07/2025: Se inician ajustes solicitados 18/07/2025 Se culminaron los ajustes requeridos por el área, se realiza paso a produccion el 17 de julio. | R10: TRUE | S10: 15/07/2025 Se inicia ajustes requeridos 17/07/2025 Requerimiento probado y en produccion. Se realizo paso a produccion el dia 17/07/2025
A11: MAURICIO | B11: AJUST_REN_2025_001_4 | C11: VALIDAR INCONSISTENCIA INFORME RENTAS RCMA – DDEP | E11: Rentas | F11: FINALIZADO | G11: 100 | H11: =IF(OR(J11="",K11="",K11<J11),0,NETWORKDAYS(J11,K11,fESTIVOS!$A$2:$A$53)) -> 0 | I11: 45834 | J11: 45848 | L11: 45818 | M11: =IF(OR(J11="",AND(L11="",TODAY()<J11),AND(L11<>"",L11<J11)),0, IF(L11="", NETWORKDAYS(J11,TODAY(),fESTIVOS!$A$2:$A$53), NETWORKDAYS(J11,L11,fESTIVOS!$A$2:$A$53) ) ) -> 0 | P11: 45852 | Q11: 11/07/2025: EL 10 de julio Se realizaron pruebas por parte de Carlos Rodríguez. Actualmente, el cambio se encuentra pendiente de ser implementado en el ambiente de producción. 15/07/2025:Se realizó el paso a producción el día 14 de julio. | R11: TRUE | S11: 26/06/2025 Se incluyen requerimientos de acuerdo a sesiones con el cliente. Corresponde a ajustes a plataforma ya en produccion 10/07/2025 Se realizaron pruebas por parte de Carlos Rodriguez. Pendiente pasar a producicon. 15/07/2025 Ya se encuenra en produccion 15/07/2025 Se solcito por parte del usuario incluir una nueva validacion.
A12: MAURICIO | B12: AJUST_REN_2025_001_5 | C12: INCLUIR VALIDACIÓN ADICIONAL PARA RCMA – DDEP. | E12: Rentas | F12: FINALIZADO | G12: 100 | H12: =IF(OR(J12="",K12="",K12<J12),0,NETWORKDAYS(J12,K12,fESTIVOS!$A$2:$A$53)) -> 0 | I12: 45853 | J12: 45853 | L12: 45854 | M12: =IF(OR(J12="",AND(L12="",TODAY()<J12),AND(L12<>"",L12<J12)),0, IF(L12="", NETWORKDAYS(J12,TODAY(),fESTIVOS!$A$2:$A$53), NETWORKDAYS(J12,L12,fESTIVOS!$A$2:$A$53) ) ) -> 2 | Q12: 16/07/2025: Se finaliza ajuste 15 de julio y se realiza despliegue a produccion el 16 de julio en la mañana. | R12: TRUE
A13: MAURICIO | B13: PRV_2025_011 | C13: ANS - TABLERO DE CONTROL - dashboard | E13: Previsional | F13: FINALIZADO | G13: 100 | H13: =IF(OR(J13="",K13="",K13<J13),0,NETWORKDAYS(J13,K13,fESTIVOS!$A$2:$A$53)) -> 2 | I13: 45855 | J13: 45855 | K13: 45857 | L13: 45862 | M13: =IF(OR(J13="",AND(L13="",TODAY()<J13),AND(L13<>"",L13<J13)),0, IF(L13="", NETWORKDAYS(J13,TODAY(),fESTIVOS!$A$2:$A$53), NETWORKDAYS(J13,L13,fESTIVOS!$A$2:$A$53) ) ) -> 6 | Q13: 18/07/2025: Se completó el query de base. Se trabaja en selección de librería gráfica compatible con Laravel. Se estima un 20% de avance general. 21/07/2025: Se esta trabajando en las graficas de ANS, se estima terminar el 22 de julio para paso a pruebas UAT 24/07/2025: El 22/07/2025 se continua en gestión del tablero de control ANS, sacaba error en los gráficos, se estima terminar el 23/07/2025 por compromiso con el cliente. 23/07/2025: Se terminan los gráficos del tablero de control. 24/07/2025: Se trabaja en el export de la data de las estadisticas 25/07/2025. Se entrega al área tablero de ANS finalizado, programado subir los cambios para paso a producción el 25/07/2025 a las 5:00 pm | R13: TRUE | S13: 17/07/2025 Se solicita realizar desarrollo inicial para lo que ya se encuentra en produccion en cuanto a pagos. Este modulo tambien debe conterner lo correpondiente a Auxilio funerario que actualmente se encuentra pausado
A14: CARLOS | B14: PRV_2025_002 | C14: REPORTE ANEXO 1 (Lentantamiento de requerimiento) | E14: Previsional | F14: FINALIZADO | G14: 100 | H14: =IF(OR(J14="",K14="",K14<J14),0,NETWORKDAYS(J14,K14,fESTIVOS!$A$2:$A$53)) -> 26 | J14: 45859 | K14: 45896 | L14: 45944 | M14: =IF(OR(J14="",AND(L14="",TODAY()<J14),AND(L14<>"",L14<J14)),0, IF(L14="", NETWORKDAYS(J14,TODAY(),fESTIVOS!$A$2:$A$53), NETWORKDAYS(J14,L14,fESTIVOS!$A$2:$A$53) ) ) -> 59 | Q14: 21/07/2025: Carlos esta adelantando el levantamiento del requerimiento, para proyectar entrega 23/07/2025: Se encuentra en definición con el cliente, para establecer algunas prioridades en los requerimientos siguientes 25/08/2025: Se retoma el levantamiento del requerimiento y se proyecta entrega a Mauricio para desarrollo el día de mañana, sin embargo, se estan priorizando informes propios de la operación de Imagine. 03/09/2025: Requerimiento en pausa debido a que Imaginex actualmente no cuenta con permisos para creación de vistas, se encuentra en validación por infraestructura para una solución. 26/09/2025: El 22 de septiembre se termino el levantamiento del requerimiento, en el transcurso de la semana se han estado elaborando vistas, sin embargo, Imagine no tiene acceso y permisos para editar o crear vistas en DLL, AUT ni producción. 03/10/2025: El 02 de octubre se obtienen los permisos y se inicia con la creación de las vistas 14/10/2025: Se proyecta finalizar el levantamiento del requerimiento para pasar a desarrollo | R14: TRUE | S14: 17/07/2025 Se esta culminado el query para generar reporte
A15: MAURICIO | B15: PRV_2025_002-1 | C15: REPORTE ANEXO 1 (desarrollo ) | E15: Previsional | F15: FINALIZADO | G15: 100 | H15: =IF(OR(J15="",K15="",K15<J15),0,NETWORKDAYS(J15,K15,fESTIVOS!$A$2:$A$53)) -> 4 | I15: 45940 | J15: 45940 | K15: 45946 | L15: 45951 | M15: =IF(OR(J15="",AND(L15="",TODAY()<J15),AND(L15<>"",L15<J15)),0, IF(L15="", NETWORKDAYS(J15,TODAY(),fESTIVOS!$A$2:$A$53), NETWORKDAYS(J15,L15,fESTIVOS!$A$2:$A$53) ) ) -> 7 | Q15: 17/10/2025: El 15 de octubre se termino el desarrollo del requerimiento Anexo 1, posteriormente se han realizado validaciones y ajustes que se cruzan con otros requerimientos, con el fin de no presentar incindencias | R15: TRUE
A16: MAURICIO | B16: PRV_2025_001 | C16: Ajuste flujo de pagos | E16: Previsional | F16: FINALIZADO | G16: 100 | H16: =IF(OR(J16="",K16="",K16<J16),0,NETWORKDAYS(J16,K16,fESTIVOS!$A$2:$A$53)) -> 0 | I16: 45855 | J16: 45855 | L16: 45860 | M16: =IF(OR(J16="",AND(L16="",TODAY()<J16),AND(L16<>"",L16<J16)),0, IF(L16="", NETWORKDAYS(J16,TODAY(),fESTIVOS!$A$2:$A$53), NETWORKDAYS(J16,L16,fESTIVOS!$A$2:$A$53) ) ) -> 4 | P16: 45885 | Q16: 21/07/2025: El 17/07/2025 Se envía correo por parte de Carlos a Seguros Alfa, solicitando modificar 2 vistas: a. Sipren: Ajustes V_consolidado_reclamaciones_img b. Plus: AjustesV_consolidado_tramites_plus Pendiente presentarlo a comité para efectuar el cambio correspondiente en las vistas. El 18/07/2025, Mauricio realizó un ajuste en el módulo de flujo de pagos, mediante el cual se asocia a cada estado del flujo una ruta u opción de acceso específica. Anteriormente, independientemente del permiso asignado, los usuarios podían visualizar los estados a los que contaban con permiso. 23/07/2025: El 22 de Julio se entrega al cliente para pruebas, al pendiente de aceptacion para paso a produccion. 24/07/2025: Se solicita a Mauricio subir los cambios de flujo de pagos modificados en las vistas que actualizò Carlos. Validar los cambios y ajustes requeridos por el cliente en requerimientos ya cerrados para paso a producción. 25/07/2025: Se finalizan los ajustes solicitados por el área (un campo llamado parentesco y mostrarlo en el export, en el Excel que exporta el cliente). Programado subir cambios para paso a producción el 25/07/2025 a las 5:00 pm 28/07/2025: El viernes 25 de julio sobre las 6:00 pm hasta las 7:30 pm se realiza el despliegue a producción. El dìa de hoy se encuentra validando que los cambiosy ajustes en el paso a producciòn están funcionando correctamente. Se evidencia que hubo una inconsistencia en los datos que Alfa suministra en el cambio a producción. Se encuentra en validación. 01/08/2025: Se vuelve a validar con Alfa la información reportada en el script, sin embargo, se encuentran a la espera de que el área de producción entregue el DLL que se envió en el despliegue. Por parte de Imagine no hay pendientes. 08/08/2025: El 06 de Agosto a raíz de la reunión con el área Previsionales el día 05 de agosto, surgieron ajustes solicitados por parte del vicepresidente de Alfa. 1. Incluir el cálculo IBL dentro del flujo. Validar primero el nombre de las etiquetas. 2. Convertir en cero al exportar el Excel los valores negativos. Solicitud de Patricia Arteaga 3. Resaltar el nombre de la columna Pago Total para que se ubiquen los usuarios. 4. Validar las etiquetas dentro del editar. Falta información 5. Revisar información que sale en la parte izquierda en el editar, ya que no se sale un valor, según valido Hugo Gómez El día de hoy 08 de agosto, se trabaja en en control de cambios en Flujo de pagos solicitado por el Vicepresidente de Alfa. 20/08/2025: Se pasa a producciòn el 16 de agosto | R16: TRUE
A17: Carlos y Cindy | B17: PRV_2025_003 | C17: AVISO A LA RENTA (Levantamiento del requerimiento) | E17: Previsional | F17: FINALIZADO | G17: 100 | H17: =IF(OR(J17="",K17="",K17<J17),0,NETWORKDAYS(J17,K17,fESTIVOS!$A$2:$A$53)) -> 1 | I17: 45863 | J17: 45863 | K17: 45863 | L17: 45885 | M17: =IF(OR(J17="",AND(L17="",TODAY()<J17),AND(L17<>"",L17<J17)),0, IF(L17="", NETWORKDAYS(J17,TODAY(),fESTIVOS!$A$2:$A$53), NETWORKDAYS(J17,L17,fESTIVOS!$A$2:$A$53) ) ) -> 15 | Q17: 25/07/2025: Carlos y Cindy estan trabajando en el levantamiento del requerimiento para pasar a Mauricio y que inicie con el desarrollo para que quede en el paso a producción programado para el 25/07/2025 a las 5:00 pm 28/07/2025: El viernes 25 de julio se hace socializaciòn del requerimiento con Mauricio y Jairo. 20/08/2025: El sabado 16 se realizo el paso a producciòn | R17: TRUE
A18: MAURICIO | B18: PRV_2025_003-1 | C18: AVISO A LA RENTA (Desarrollo) | E18: Previsional | F18: FINALIZADO | G18: 100 | H18: =IF(OR(J18="",K18="",K18<J18),0,NETWORKDAYS(J18,K18,fESTIVOS!$A$2:$A$53)) -> 2 | I18: 45863 | J18: 45866 | K18: 45867 | L18: 45870 | M18: =IF(OR(J18="",AND(L18="",TODAY()<J18),AND(L18<>"",L18<J18)),0, IF(L18="", NETWORKDAYS(J18,TODAY(),fESTIVOS!$A$2:$A$53), NETWORKDAYS(J18,L18,fESTIVOS!$A$2:$A$53) ) ) -> 5 | P18: 45885 | Q18: 28/07/2025, el viernes 25 de julio, debido a una inconsistencia en el aplicativo ALFASST del área SST con unas ordenes de servicio, se tuvo que dar prioridad y Mauricio no pudo iniciar el desarrollo de Avisos a la renta. El día de hoy, luego de terminar validaciones de paso a producción de otros requerimientos, se inicia desarrollo de este requerimiento. 29/07/2025: Mauricio se enfocarà en terminar el requerimiento completamente. 30/07/2025: Se reporta un avance del 50% en el desarrollo del módulo de avisos de renta. Ya se visualizan los pagos correctamente y quedan pendientes las funcionalidades de notificación, descarga de Excel y eliminación de registros. Se espera finalizar hoy. 01/08/2025: A 31 de julio ya esta por entregar, Mauricio el dìa de hoy mostrara el funcionamiento y el flujo del reporte, para identificar posibles desviaciones y validar si es posible automatizarlo. 04/08/2025: El 01 de agosto quedo funcional el requerimiento, esta proyectado para paso a producción el viernes 08 de agosto 13/08/2025. Se proyecta paso a producción el sabado 16 de agosto. 20/08/2025: Paso a produccion realizado 16 de Agosto. | R18: TRUE
A19: MAURICIO | B19: Img_2025_001 | C19: Validar servidor de contingencia | E19: Imagine | F19: FINALIZADO | G19: 100 | H19: =IF(OR(J19="",K19="",K19<J19),0,NETWORKDAYS(J19,K19,fESTIVOS!$A$2:$A$53)) -> 1 | I19: 45870 | J19: 45870 | K19: 45870 | L19: 45877 | M19: =IF(OR(J19="",AND(L19="",TODAY()<J19),AND(L19<>"",L19<J19)),0, IF(L19="", NETWORKDAYS(J19,TODAY(),fESTIVOS!$A$2:$A$53), NETWORKDAYS(J19,L19,fESTIVOS!$A$2:$A$53) ) ) -> 5 | Q19: 01/08/2025: Se realizarà validación del servidor de contingencia el día de hoy, puesto que en meses pasado se presentaron incidencias y debemos garantizar que toda la información se encuentre sincronizada de forma correcta. 04/08/2025: Se programo sesiòn con Wilson y Mauricio para validaciòn y acompañamiento en la sincronización de la contingencia. 08/08/2025: Validación de error de la sincronización de contingencia, con Alfa y Claro - Onpremise 2. Validación cambio de llaves AWS. 12/08/2025: Se encuentra pendiente ajuste a permisos de carpetas para la sincronización y notificación por correo del error en la sincronización o éxito en la misma. La reunión del viernes para cambio de llaves AWS, se reprogramo para hoy a las 9:00 am hasta las 10:15 am aproximadamente. | R19: TRUE
A20: MAURICIO | B20: PRV_2025_004-1 | C20: Ajustes modulo auxilios funerario | E20: Previsional | F20: FINALIZADO | G20: 100 | H20: =IF(OR(J20="",K20="",K20<J20),0,NETWORKDAYS(J20,K20,fESTIVOS!$A$2:$A$53)) -> 0 | I20: 45874 | J20: 45874 | L20: 45882 | M20: =IF(OR(J20="",AND(L20="",TODAY()<J20),AND(L20<>"",L20<J20)),0, IF(L20="", NETWORKDAYS(J20,TODAY(),fESTIVOS!$A$2:$A$53), NETWORKDAYS(J20,L20,fESTIVOS!$A$2:$A$53) ) ) -> 6 | P20: 45885 | Q20: 08/08/2025: el 05 de Agosto, se realiza acompañamiento en la sesión del área de Previsionales con Blanca Romero, Elizabeth Guerrero y Hugo Gomez, por si surgen dudas u observaciones. Se trabaja en informes de Pagos y Auxilios Funerarios. 11/08/2025: A raíz de la sesión del viernes surgieron ajustes adicionales: 1. Incluir el cálculo del IBL dentro del flujo 2. Convertir en cero al exportar el Excel los valores negativos. Solicitud de Patricia Arteaga 3. Resaltar el nombre de la columna Pago Total para que se ubiquen los usuarios 4. Validar las etiquetas dentro del editar. Falta información 5. Revisar información que sale en la parte izquierda en el editar, ya que no sale un valor, según valido Hugo Gomez. Estos puntos ya quedaron gestionados el día de ayer en un 90%, falta culminar: - Control de cambios en flujo de pagos - Incluir el cálculo del IBL dentro del flujo. Validar nombre de las etiquetas 12/08/2025: El viernes hubo incidencia en el cargue del Excel archivo de formalización de Auxilios Funerarios, sin embargo, este ya quedo solucionado. Se continúa trabajando en los ajustes faltantes requeridos por vicepresidencia de Seguridad Social. 13/08/2025: Reunión con el área de coordinación y desarrollo para instrucciones de entrega de documentación. - Creación de documentos técnicos requeridos por Alfa para paso a comité de cambios el día de hoy 13 de agosto y mañana 14. - Ajustes por pruebas de usuario en error de cargue de archivo y mejora de la consulta. - Se proyecta paso a producción de aviso a la renta y auxilios funerarios el sabado 16 de agosto. 20/08/2025: El dìa sabado 16 se realiza paso a producciòn | R20: TRUE
A21: MAURICIO | B21: PRV_2025_004-2 | C21: Ajustes auxilios funerarios y aviso a la renta | E21: Previsional | F21: FINALIZADO | G21: 100 | H21: =IF(OR(J21="",K21="",K21<J21),0,NETWORKDAYS(J21,K21,fESTIVOS!$A$2:$A$53)) -> 0 | I21: 45883 | J21: 45883 | L21: 45883 | M21: =IF(OR(J21="",AND(L21="",TODAY()<J21),AND(L21<>"",L21<J21)),0, IF(L21="", NETWORKDAYS(J21,TODAY(),fESTIVOS!$A$2:$A$53), NETWORKDAYS(J21,L21,fESTIVOS!$A$2:$A$53) ) ) -> 1 | P21: 45885 | Q21: 14/08/2025: Ajuste a bugs reportados por el cliente para Auxilios Funerarios y Aviso a la Renta (formatos y consultas). Ya el dìa de hoy se certifico por parte del cliente el paso a producciòn, el cual se progrma realizar por parte de Mauricio el sabado 16 de agosto. Se requiriò acompañamiento de Mauricio en las sesiones para solucionar de forma inmediata las inconsistencias, durante las horas de la mañana y tarde. 20/08/2025: EL sabado 16 se realizo paso a producciòn | R21: TRUE
A22: MAURICIO | B22: PRV_2025_004-3 | C22: Genera informes generales pagos y auxilios funerarios | D22: Generar un informe con el detalle de mostrar consulta y la trazabilidad de los casos de los procesos entregados a producciòn en semanas anteriores. | E22: Previsional | F22: FINALIZADO | G22: 100 | H22: =IF(OR(J22="",K22="",K22<J22),0,NETWORKDAYS(J22,K22,fESTIVOS!$A$2:$A$53)) -> 0 | J22: 45895 | L22: 45895 | M22: =IF(OR(J22="",AND(L22="",TODAY()<J22),AND(L22<>"",L22<J22)),0, IF(L22="", NETWORKDAYS(J22,TODAY(),fESTIVOS!$A$2:$A$53), NETWORKDAYS(J22,L22,fESTIVOS!$A$2:$A$53) ) ) -> 1 | Q22: 27/08/2025: El 26 de agosto se trabajo en el desarrollo del informe general de pagos y auxilios funerarios. | R22: TRUE
A23: MAURICIO | B23: Img_2025_002 | C23: Validar servidor de contingencia | D23: Crear .bash para notificar sincronización en base de datos | E23: Imagine | F23: FINALIZADO | G23: 100 | H23: =IF(OR(J23="",K23="",K23<J23),0,NETWORKDAYS(J23,K23,fESTIVOS!$A$2:$A$53)) -> 5 | I23: 45884 | J23: 45884 | K23: 45891 | L23: 45947 | M23: =IF(OR(J23="",AND(L23="",TODAY()<J23),AND(L23<>"",L23<J23)),0, IF(L23="", NETWORKDAYS(J23,TODAY(),fESTIVOS!$A$2:$A$53), NETWORKDAYS(J23,L23,fESTIVOS!$A$2:$A$53) ) ) -> 44 | Q23: 15/08/2025: Se reconfiguraron los permisos y Mauricio estarà validando el tema el día de hoy, sincronizaciòn y funcionamiento 20/08/2025: Al 19 de agosto, se encuentra pendiente reporte por parte de Claro informando las actividades realizadas el dìa viernes de acuerdo al refresh de la llave. Pendiente por parte Mauricio crear .bash para notificar cuando sincronice las bases de datos 25/08/2025: El viernes 22 de agosto se creo el .bash solicitado, sin embargo, se esta presentando una incidencia en la actualización, que no actualiza en la base de datos a diferencia del que corre a las 3 am. Mauricio estará validando otras funcionalidades y en caso de que continue la inconsistencia, se apoyará con Jairo y Jenry 27/08/2025: El 25 de agosto se valido con tecnologìa el tema de crear una conexión SSH, el día de hoy 27 de agosto, dieron respuesta que se puede realizar sin problema. 03/09/2025: Mauricio indica que queda pendiente el sabado 06 de septiembre validar la sincronizaciòn y Carlos Rodriguez debe realizar la documentación de la sincronización para presentar a Alfa. 20/10/2025: El 17 de octubre se realizó sincronización manual de producción a contingencia, debido a que el procesos automático de las 3 am, dejo algunos archivos corruptos | R23: TRUE
A24: MAURICIO | B24: SST_2025_001 | C24: Ajustes en servidores QA y PT de ALFASST AWS | E24: SST | F24: FINALIZADO | G24: 100 | H24: =IF(OR(J24="",K24="",K24<J24),0,NETWORKDAYS(J24,K24,fESTIVOS!$A$2:$A$53)) -> 5 | I24: 45894 | J24: 45894 | K24: 45898 | L24: 45897 | M24: =IF(OR(J24="",AND(L24="",TODAY()<J24),AND(L24<>"",L24<J24)),0, IF(L24="", NETWORKDAYS(J24,TODAY(),fESTIVOS!$A$2:$A$53), NETWORKDAYS(J24,L24,fESTIVOS!$A$2:$A$53) ) ) -> 4 | Q24: 29/08/2025: 25/08/2025: Los desarrollos para esta aplicación se encontraban detenidos desde el año pasado. Por lo cual los ambientes no se encontraban actualizados y/o con data actualizada para pruebas. | R24: TRUE
A25: MAURICIO | B25: SST_2025_002 | C25: Ajustes en servidores QA y PT de ALFASST AWS | E25: SST | F25: FINALIZADO | G25: 100 | H25: =IF(OR(J25="",K25="",K25<J25),0,NETWORKDAYS(J25,K25,fESTIVOS!$A$2:$A$53)) -> 5 | I25: 45894 | J25: 45894 | K25: 45898 | L25: 45897 | M25: =IF(OR(J25="",AND(L25="",TODAY()<J25),AND(L25<>"",L25<J25)),0, IF(L25="", NETWORKDAYS(J25,TODAY(),fESTIVOS!$A$2:$A$53), NETWORKDAYS(J25,L25,fESTIVOS!$A$2:$A$53) ) ) -> 4 | Q25: 29/08/2025: 25/08/2025: Se retomaron las pruebas en los entornos QA y PT para validar nuevos requerimientos y hacer seguimiento al estado de aquellos que aún se encuentran pendientes por ser desplegados en producción. | R25: TRUE
A26: MAURICIO | B26: SST_2025_003 | C26: Ajustes en servidores QA y PT de ALFASST AWS | E26: SST | F26: FINALIZADO | G26: 100 | H26: =IF(OR(J26="",K26="",K26<J26),0,NETWORKDAYS(J26,K26,fESTIVOS!$A$2:$A$53)) -> 5 | I26: 45894 | J26: 45894 | K26: 45898 | L26: 45897 | M26: =IF(OR(J26="",AND(L26="",TODAY()<J26),AND(L26<>"",L26<J26)),0, IF(L26="", NETWORKDAYS(J26,TODAY(),fESTIVOS!$A$2:$A$53), NETWORKDAYS(J26,L26,fESTIVOS!$A$2:$A$53) ) ) -> 4 | Q26: 29/08/2025: 25/08/2025: Durante este proceso, se identificaron algunas incidencias en los servidores, por lo que fue necesario realizar ajustes y correcciones técnicas para garantizar un entorno estable que permitiera continuar con la validación de los cambios. | R26: TRUE
A27: MAURICIO | B27: SST_2025_004 | C27: Ajustes en servidores QA y PT de ALFASST AWS | E27: SST | F27: FINALIZADO | G27: 100 | H27: =IF(OR(J27="",K27="",K27<J27),0,NETWORKDAYS(J27,K27,fESTIVOS!$A$2:$A$53)) -> 5 | I27: 45894 | J27: 45894 | K27: 45898 | L27: 45897 | M27: =IF(OR(J27="",AND(L27="",TODAY()<J27),AND(L27<>"",L27<J27)),0, IF(L27="", NETWORKDAYS(J27,TODAY(),fESTIVOS!$A$2:$A$53), NETWORKDAYS(J27,L27,fESTIVOS!$A$2:$A$53) ) ) -> 4 | Q27: 29/08/2025: 25/08/2025: Se restablecieron los cronogramas del año vigente en los entornos QA y PT para habilitar el nuevo módulo de profesionales y permitir sus respectivas pruebas. | R27: TRUE
A28: MAURICIO | B28: SST_2025_005 | C28: Validar el modulo de profesionales para que el àrea pueda realizar pruebas | E28: SST | F28: FINALIZADO | G28: 100 | H28: =IF(OR(J28="",K28="",K28<J28),0,NETWORKDAYS(J28,K28,fESTIVOS!$A$2:$A$53)) -> 4 | I28: 45894 | J28: 45895 | K28: 45898 | L28: 45897 | M28: =IF(OR(J28="",AND(L28="",TODAY()<J28),AND(L28<>"",L28<J28)),0, IF(L28="", NETWORKDAYS(J28,TODAY(),fESTIVOS!$A$2:$A$53), NETWORKDAYS(J28,L28,fESTIVOS!$A$2:$A$53) ) ) -> 3 | Q28: 29/08/2025: 25/08/2025: Se solucionaron errores en el módulo de profesionales y se realizaron correcciones funcionales. | R28: TRUE
A29: MAURICIO | B29: SST_2025_006 | C29: Accesos y configuración técnica QA ALFASST AWS | E29: SST | F29: FINALIZADO | G29: 100 | H29: =IF(OR(J29="",K29="",K29<J29),0,NETWORKDAYS(J29,K29,fESTIVOS!$A$2:$A$53)) -> 4 | I29: 45894 | J29: 45895 | K29: 45898 | L29: 45897 | M29: =IF(OR(J29="",AND(L29="",TODAY()<J29),AND(L29<>"",L29<J29)),0, IF(L29="", NETWORKDAYS(J29,TODAY(),fESTIVOS!$A$2:$A$53), NETWORKDAYS(J29,L29,fESTIVOS!$A$2:$A$53) ) ) -> 3 | Q29: 29/08/2025: 25/08/2025: Se refrescaron claves y accesos, especialmente en el servidor de pruebas, que presentaba problemas de ingreso. | R29: TRUE
A30: MAURICIO | B30: SST_2025_007 | C30: Accesos y configuración técnica QA ALFASST AWS | E30: SST | F30: FINALIZADO | G30: 100 | H30: =IF(OR(J30="",K30="",K30<J30),0,NETWORKDAYS(J30,K30,fESTIVOS!$A$2:$A$53)) -> 4 | I30: 45894 | J30: 45895 | K30: 45898 | L30: 45897 | M30: =IF(OR(J30="",AND(L30="",TODAY()<J30),AND(L30<>"",L30<J30)),0, IF(L30="", NETWORKDAYS(J30,TODAY(),fESTIVOS!$A$2:$A$53), NETWORKDAYS(J30,L30,fESTIVOS!$A$2:$A$53) ) ) -> 3 | Q30: 29/08/2025: 25/08/2025: Se ajustó la configuración de pgAdmin para garantizar la conexión con las distintas bases de datos de ALFASST. | R30: TRUE
A31: MAURICIO | B31: PRV_2025_006 | C31: Sincronización de estados de casos | E31: Previsional | F31: FINALIZADO | G31: 100 | H31: =IF(OR(J31="",K31="",K31<J31),0,NETWORKDAYS(J31,K31,fESTIVOS!$A$2:$A$53)) -> 4 | I31: 45894 | J31: 45895 | K31: 45898 | L31: 45897 | M31: =IF(OR(J31="",AND(L31="",TODAY()<J31),AND(L31<>"",L31<J31)),0, IF(L31="", NETWORKDAYS(J31,TODAY(),fESTIVOS!$A$2:$A$53), NETWORKDAYS(J31,L31,fESTIVOS!$A$2:$A$53) ) ) -> 3 | Q31: 29/08/2025: 25/08/2025: Se implementó el ajuste para que, al cambiar un caso de estado CORRECCIÓN → REVISADO, se ejecute la sincronización individual del valor, considerando posibles modificaciones. | R31: TRUE
A32: MAURICIO | B32: PRV_2025_0011 | C32: Sincronización de estados de casos | E32: Previsional | F32: FINALIZADO | G32: 100 | H32: =IF(OR(J32="",K32="",K32<J32),0,NETWORKDAYS(J32,K32,fESTIVOS!$A$2:$A$53)) -> 4 | I32: 45894 | J32: 45896 | K32: 45901 | L32: 45930 | M32: =IF(OR(J32="",AND(L32="",TODAY()<J32),AND(L32<>"",L32<J32)),0, IF(L32="", NETWORKDAYS(J32,TODAY(),fESTIVOS!$A$2:$A$53), NETWORKDAYS(J32,L32,fESTIVOS!$A$2:$A$53) ) ) -> 25 | Q32: 29/08/2025: 25/08/2025: Queda pendiente el desarrollo de la sincronización masiva, lo cual implica ajustes en las funciones de sincronización entre bases de datos. 03/09/2025: Requerimiento en pausa debido a que Imaginex actualmente no cuenta con permisos para creación de vistas, se encuentra en validación por infraestructura para una solución. 01/10/2025: El 30 de septiembre se obtienen permisos pendientes, lo cual permitio finalizar el desarrollo del requerimiento | R32: TRUE
A33: MAURICIO | B33: PRV_2025_008 | C33: Flujo de Pagos Control de cambios | E33: Previsional | F33: FINALIZADO | G33: 100 | H33: =IF(OR(J33="",K33="",K33<J33),0,NETWORKDAYS(J33,K33,fESTIVOS!$A$2:$A$53)) -> 0 | I33: 45894 | J33: 45930 | K33: 45901 | L33: 45930 | M33: =IF(OR(J33="",AND(L33="",TODAY()<J33),AND(L33<>"",L33<J33)),0, IF(L33="", NETWORKDAYS(J33,TODAY(),fESTIVOS!$A$2:$A$53), NETWORKDAYS(J33,L33,fESTIVOS!$A$2:$A$53) ) ) -> 1 | Q33: 29/08/2025: 25/08/2025: Permitir la modificación del campo VALOR_PAGO en casos específicos, exclusivamente dentro del primer flujo del proceso. 03/09/2025: Requerimiento en pausa debido a que Imaginex actualmente no cuenta con permisos para creación de vistas, se encuentra en validación por infraestructura para una solución. 01/10/2025: El 30 de septiembre se habilita la ediciòn del campo VALOR_PAGO ya que algunos casos lo requieren, modificaciòn restringida unicamente al primer flujo | R33: TRUE
A34: MAURICIO | B34: PRV_2025_012 | C34: Auxilios Funerarios Control de Cambios | E34: Previsional | F34: FINALIZADO | G34: 100 | H34: =IF(OR(J34="",K34="",K34<J34),0,NETWORKDAYS(J34,K34,fESTIVOS!$A$2:$A$53)) -> 0 | I34: 45894 | J34: 45930 | K34: 45901 | L34: 45930 | M34: =IF(OR(J34="",AND(L34="",TODAY()<J34),AND(L34<>"",L34<J34)),0, IF(L34="", NETWORKDAYS(J34,TODAY(),fESTIVOS!$A$2:$A$53), NETWORKDAYS(J34,L34,fESTIVOS!$A$2:$A$53) ) ) -> 1 | Q34: 29/08/2025: 25/08/2025: Sincronizar y actualizar automáticamente la fecha de siniestro según información proveniente de Porvenir. 03/09/2025: Requerimiento en pausa debido a que Imaginex actualmente no cuenta con permisos para creación de vistas, se encuentra en validación por infraestructura para una solución. 01/10/2025: El 30 de septiembre se creo opciòn para cuando se sincronicen las solicitudes permitan actualizar las fechas de siniestro | R34: TRUE
A35: MAURICIO | B35: PRV_2025_010 | C35: Aviso a la Renta Control de Cambios | E35: Previsional | F35: FINALIZADO | G35: 100 | H35: =IF(OR(J35="",K35="",K35<J35),0,NETWORKDAYS(J35,K35,fESTIVOS!$A$2:$A$53)) -> 0 | I35: 45894 | J35: 45947 | K35: 45901 | L35: 45947 | M35: =IF(OR(J35="",AND(L35="",TODAY()<J35),AND(L35<>"",L35<J35)),0, IF(L35="", NETWORKDAYS(J35,TODAY(),fESTIVOS!$A$2:$A$53), NETWORKDAYS(J35,L35,fESTIVOS!$A$2:$A$53) ) ) -> 1 | Q35: 29/08/2025: 25/08/2025: Incluir en el reporte: * fecha_cierre * número de solicitud * fecha de envío de correo 03/09/2025: Requerimiento en pausa debido a que Imaginex actualmente no cuenta con permisos para creación de vistas, se encuentra en validación por infraestructura para una solución. 20/10/2025: Se incluyen campos solicitados por el área | R35: TRUE
... A38: MAURICIO | B38: PRV_2025_014 | C38: Aviso a la Renta Control de Cambios Reporte | E38: Previsional | F38: FINALIZADO | G38: 100 | H38: =IF(OR(J38="",K38="",K38<J38),0,NETWORKDAYS(J38,K38,fESTIVOS!$A$2:$A$53)) -> 3 | I38: 45894 | J38: 45938 | K38: 45940 | L38: 45947 | M38: =IF(OR(J38="",AND(L38="",TODAY()<J38),AND(L38<>"",L38<J38)),0, IF(L38="", NETWORKDAYS(J38,TODAY(),fESTIVOS!$A$2:$A$53), NETWORKDAYS(J38,L38,fESTIVOS!$A$2:$A$53) ) ) -> 7 | Q38: 29/08/2025: 25/08/2025: Automatizar el envío del informe: Frecuencia: todos los viernes a las 6:00 a.m. En caso de festivo, el informe debe enviarse el día hábil anterior. 03/09/2025: Requerimiento en pausa debido a que Imaginex actualmente no cuenta con permisos para creación de vistas, se encuentra en validación por infraestructura para una solución. 20/10/2025: El viernes 17 de octubre se agrego la funcionalidad para la ejecución del proceso Aviso a la Renta, mediante las tareas programadas. | R38: TRUE
A39: MAURICIO | B39: SST_2025_009 | C39: Ajuste modulo profesionales | D39: Se requiere validar y realizar ajustes de errores e incidencias que se están presentando en el módulo para realizar las pruebas por parte del cliente y sea certificado el paso a producción | E39: SST | F39: FINALIZADO | G39: 100 | H39: =IF(OR(J39="",K39="",K39<J39),0,NETWORKDAYS(J39,K39,fESTIVOS!$A$2:$A$53)) -> 3 | I39: 45901 | J39: 45901 | K39: 45903 | L39: 45919 | M39: =IF(OR(J39="",AND(L39="",TODAY()<J39),AND(L39<>"",L39<J39)),0, IF(L39="", NETWORKDAYS(J39,TODAY(),fESTIVOS!$A$2:$A$53), NETWORKDAYS(J39,L39,fESTIVOS!$A$2:$A$53) ) ) -> 15 | Q39: 01/09/2025: El 30 de agosto Mauricio realizando otras pruebas identifico un error en el modulo de profesionales en el ambiente de pruebas Alfa, por tanto se radica caso el 01 de septiembre para soporte de AWS y se contacta co Oscar Pérez para que nos ayuden con la incidencia reportada. Ya que hasta no sea solucionado no podremos realizar pruebas y el cliente tampoco. La fecha estimada relacionada es solo si nos gestionan en soporte ALFA el día de hoy, de lo contrario se verá afectada y cambiará de acuerdo con la solución del caso radicado. 03/09/2025: El 02 de septiembre queda solucionada la incidencia y queda pendiente realizar pruebas internas antes de entregar a Nohora Carolina de SST para pruebas del área. 05/09/2025: El 04 de septiembre se iniciaron pruebas internas, sin embargo, no fue posible culminarlas debido a una incidencia presentada con el plan de trabajo en el ambiente QA. 08/09/2025: El viernes 05 de septiembre, Mauricio trabajo en el cronograma en ambiente de pruebas, ya se libero presupuesto pero se esta validando porque no carga actividades y programas. 11/09/2025: El 10 de septiembre Mauricio continua validando, ajustando incidencias en el ambiente de QA que no han permitido realizar las pruebas correspondientes. 15/09/2025: El viernes 12 de septiembre Mauricio se enfoco en seguri revisando errores que se estan presentando en el módulo de cronogramas y edición de ordenes de servicios 18/09/2025: Durante los días del 15 al 17 Mauricio detecto errores en el desarrollo y ha trabajado en corregir y mejorar su funcionalidad, adicional de mejorar la apariencia siendo mas intuitivo para el usuario. Se refactorizo el diseño de la gestión de profesionales a acreditar y la gestión de proveedores. 22/09/2025: El viernes 19 de septiembre, Mauricio subió los ajustes de los modulos de profesionales y cronograma de trabajo. | R39: TRUE
A40: MAURICIO | B40: PRV_2025_015 | C40: Creaciòn Vistas en DLL Alfa | D40: Creaciòn de vistas en ambiente DLL Alfa para desarrollo de requerimientos previsionales | E40: Previsional | F40: FINALIZADO | G40: 100 | H40: =IF(OR(J40="",K40="",K40<J40),0,NETWORKDAYS(J40,K40,fESTIVOS!$A$2:$A$53)) -> 4 | I40: 45898 | J40: 45898 | K40: 45903 | L40: 45932 | M40: =IF(OR(J40="",AND(L40="",TODAY()<J40),AND(L40<>"",L40<J40)),0, IF(L40="", NETWORKDAYS(J40,TODAY(),fESTIVOS!$A$2:$A$53), NETWORKDAYS(J40,L40,fESTIVOS!$A$2:$A$53) ) ) -> 25 | Q40: 01/09/2025: El 29 de agosto a Mauricio se le entregaron credenciales por parte de infraestructura Alfa para permisos y creación de vistas en Desarrollo Sipren Plus, sin embargo, permitió coneción preo no la creación de las vistas. 03/09/2025: Requerimiento en pausa debido a que Imaginex actualmente no cuenta con permisos para creación de vistas, se encuentra en validación por infraestructura para una solución. 01/10/2025: Desde el 30 de septiembre se obtuvieron los permisos pendientes y se esta adelantando la creaciòn de vistas de los requerimientos que se han levantado 03/10/2025: el 02 de octubre se asignan nuevas vistas en la función de sincronización | R40: TRUE
A41: MAURICIO | B41: PRV_2025_016 | C41: Actualización Tablero de Estadistica y Cumplimiento | D41: Se incluye en las graficas aux funerarios | E41: Previsional | F41: FINALIZADO | G41: 100 | H41: =IF(OR(J41="",K41="",K41<J41),0,NETWORKDAYS(J41,K41,fESTIVOS!$A$2:$A$53)) -> 3 | I41: 45901 | J41: 45901 | K41: 45903 | L41: 45903 | M41: =IF(OR(J41="",AND(L41="",TODAY()<J41),AND(L41<>"",L41<J41)),0, IF(L41="", NETWORKDAYS(J41,TODAY(),fESTIVOS!$A$2:$A$53), NETWORKDAYS(J41,L41,fESTIVOS!$A$2:$A$53) ) ) -> 3 | Q41: 03/09/2025: 01/09/2025 Mauricio trabaja en la inclusión de la data de Auxilios Funerarios en el tablero de ANS. 02/09/2025: Se trabaja en los graficos de aux funerarios y en la consulta requerida para validar datos de flujo de pagos y aux funerario. Pendientes pruebas internas para antes de entregar para pruebas por parte del área de previsionales 04/09/2025: el 03 de septiembre el desarrollo del gráfico está en fase final, restando únicamente ajustes de personalización en los tooltips. Se programó una reunión con el cliente para la socialización de avances, debido a que no alcanzo el tiempo, se reprogramo sesión para el jueves 4 de septiembre a las 9:00 am El día de hoy 04 de septiembre, se realizan unas pruebas internas antes de entregar al cliente para sus respectivas pruebas y certificaciòn, siendo exitosas. En la sesión al momento de ingresar al aplicativo de pruebas Imagine, el cliente no pudo ya que por politicas de la compañia al parecer les quitaron permisos, se encuentran en validaciòn con el area tecnologica y sin embargo, por parte de Imagine les mostramos el módulo, los graficos, los cambios y los reportes. Se entrega para que apenas tengan acceso puedan validar y confirmar funcionalidad. 11/09/2025: Se confirma funcionalidad por parte del área de Previsionales | R41: TRUE
A42: MAURICIO | B42: Img_2025_004 | C42: Conexiones con Ministerio -SAT | E42: Imagine | F42: FINALIZADO | G42: 100 | H42: =IF(OR(J42="",K42="",K42<J42),0,NETWORKDAYS(J42,K42,fESTIVOS!$A$2:$A$53)) -> 1 | I42: 45902 | J42: 45903 | K42: 45903 | L42: 45903 | M42: =IF(OR(J42="",AND(L42="",TODAY()<J42),AND(L42<>"",L42<J42)),0, IF(L42="", NETWORKDAYS(J42,TODAY(),fESTIVOS!$A$2:$A$53), NETWORKDAYS(J42,L42,fESTIVOS!$A$2:$A$53) ) ) -> 1 | Q42: 04/09/2025: Se identificaron cambios en la configuración, por lo que se programó la reconfiguración de servicios en horas de la tarde. | R42: TRUE
...

Sheet PRUEBAS BOLIVAR
A1: Asignado | B1: Requerimiento | C1: Actividad | D1: ESTADO | E1: F.Asignado | F1: Fecha inicio | G1: F. estimada de entrega | H1: Finalizado | I1: Dias | J1: TEST | K1: PRODUCCION | L1: Observacion
A2: JAIRO NIÑO | B2: MDSB-642019 Cargue archivo tarifas y autorizaciones salud | D2: PRUEBAS BOLIVAR | E2: 45526 | F2: 45526 | L2: ok
A3: JAIRO NIÑO | B3: Gestión aplicativo reembolso salud | C3: Implementación de cartas (Devolución, glosa y pago). | D3: FINALIZADO | E3: 45560 | F3: 45560 | H3: 45567 | I3: =IF(ISBLANK(H3), NETWORKDAYS(F3, TODAY(),fESTIVOS!$A$1:$A$18), NETWORKDAYS(F3, H3, fESTIVOS!$A$1:$A$18)) -> 6 | J3: 45567 | L3: *02/10/2024 ya se encuentra implementado
A4: LUIS BAYONA | B4: MDSB-659398 Ajuste campos archivo Autorizaciones EPS | C4: Ajustar la tabla y el cargue del archivo | D4: CONTROL CAMBIOS PRD | E4: 45581 | F4: 45581 | G4: 45582 | H4: 45590 | I4: =IF(ISBLANK(H4), NETWORKDAYS(F4, TODAY(),fESTIVOS!$A$1:$A$18), NETWORKDAYS(F4, H4, fESTIVOS!$A$1:$A$18)) -> 8 | J4: 45590 | L4: *17/10/2024 Validación del desarrollo. *18/10/2024 Continuara despues de terminar la incidendia de "Caso internet" *21/10/2024 ajustar campos y pruebas *22/10/2024 Subir ajustes a test, se debe solicitar control de cambios en test. *24/10/2024 Se deben ajustar inconsitencias en las fechas del informe. *25/10/2024 Se suben ajustes a test *12/11/2024 se debe subir a produccion (Solicitar control de cambios). *13/11/2024 se escala control de cambios a produccion MDSB-705441.
A5: JAIRO NIÑO | B5: MDSB-683637 REQ Ajustes datos migración EPS-Davinci | C5: Ajustar Glosa por procedimiento | D5: EN TEST | E5: 45572 | F5: 45590 | H5: 45594 | I5: =IF(ISBLANK(H5), NETWORKDAYS(F5, TODAY(),fESTIVOS!$A$1:$A$18), NETWORKDAYS(F5, H5, fESTIVOS!$A$1:$A$18)) -> 3 | J5: 45594 | L5: *29/10/2024 Continua con el desarrollo *30/10/2024 Finalizado
A6: DANILO RAMIREZ | B6: GD772-52 Eliminar envio de correo de notificación de tipologia | C6: Para la tipologia "Creación O Cambio De Usuario Administrador Pagina Web - Ap" se debe eliminar el envio al correo servicioalcliente@segurosbolivar.com cuado se radica en el portal solicitudes ARL. | D6: PRUEBA BOLIVAR | E6: 45602 | F6: 45602 | H6: 45602 | I6: =IF(ISBLANK(H6), NETWORKDAYS(F6, TODAY(),fESTIVOS!$A$1:$A$18), NETWORKDAYS(F6, H6, fESTIVOS!$A$1:$A$18)) -> 1 | K6: 45602 | L6: *07/11/2024 Pendiente pruebas por bolivar en produccion.
A7: JAIRO NIÑO | B7: Gestión aplicativo reembolso salud | C7: Cargue archivo de pago y cambio estado a "Terminado o rechado de pago" e implementación de la carta correspondiente | D7: EN TEST | E7: 45589 | F7: 45589 | H7: 45603 | I7: =IF(ISBLANK(H7), NETWORKDAYS(F7, TODAY(),fESTIVOS!$A$1:$A$18), NETWORKDAYS(F7, H7, fESTIVOS!$A$1:$A$18)) -> 10 | J7: 45603 | L7: *28/10/2024 pendiente definir que estados se deben tomar para llevar el Reembolso a rechazo *01/11/2024 Reinicia Validando la logica de la bandeja. *05/11/2024 aclarar dudas para implementar carta de bancolombia y en pruebas de archivo de pagos *06/11/2024 devolucion por causal. *07/11/2024 devolucion por causal lista para test.
A8: JAIRO NIÑO | B8: MDSB-657409 Modulo para adicionar RG para gestion de respuestas a Glosa EPS | D8: EN TEST | E8: 45603 | F8: 45603 | H8: 45610 | I8: =IF(ISBLANK(H8), NETWORKDAYS(F8, TODAY(),fESTIVOS!$A$1:$A$18), NETWORKDAYS(F8, H8, fESTIVOS!$A$1:$A$18)) -> 5 | J8: 45610 | L8: *12/11/2024 Listo para entrega a Jenry *13/11/2024 pendiente validación con jenry para pasar a dev y test. *14/11/2024 pendiente pasar a test *15/11/2024 Se pasa a test para pruebas bolivar
A9: JESUS PEÑA | B9: GD772-71 Radicación de juntas | C9: Estimar tiempo de desarrollo | D9: EN PRUEBAS BOLIVAR | E9: 45671 | F9: 45673 | G9: 10 Dias | H9: 45680 | I9: =IF(ISBLANK(H9), NETWORKDAYS(F9, TODAY(),fESTIVOS!$A$1:$A$18), NETWORKDAYS(F9, H9, fESTIVOS!$A$1:$A$18)) -> 6 | J9: 45680 | L9: 23/01/2025 Inicio de pruebas para pasar a test 31/01/2025 entregado a prubas Bolivar
A10: JESUS PEÑA | C10: HU 1 Crear en el portal de solicitudes ARL la opción de radicación de JCI - EPS- AFP | D10: EN PRUEBAS BOLIVAR | E10: 45671 | F10: 45673 | H10: 45674 | I10: =IF(ISBLANK(H10), NETWORKDAYS(F10, TODAY(),fESTIVOS!$A$1:$A$18), NETWORKDAYS(F10, H10, fESTIVOS!$A$1:$A$18)) -> 2 | L10: 20/01/2025 pendiente ajustes en yii 31/01/2025 entregado a prubas Bolivar
A11: JESUS PEÑA | C11: HU 2 Creación de formulario para radicación en el portal | D11: EN PRUEBAS BOLIVAR | E11: 45671 | F11: 45673 | H11: 45674 | I11: =IF(ISBLANK(H11), NETWORKDAYS(F11, TODAY(),fESTIVOS!$A$1:$A$18), NETWORKDAYS(F11, H11, fESTIVOS!$A$1:$A$18)) -> 2 | L11: 20/01/2025 pendiente ajustes en yii 31/01/2025 entregado a prubas Bolivar
A12: JESUS PEÑA | C12: HU 3 Parte 2 formulario de radicación Descripción | D12: EN PRUEBAS BOLIVAR | E12: 45671 | F12: 45673 | H12: 45674 | I12: =IF(ISBLANK(H12), NETWORKDAYS(F12, TODAY(),fESTIVOS!$A$1:$A$18), NETWORKDAYS(F12, H12, fESTIVOS!$A$1:$A$18)) -> 2 | L12: 20/01/2025 pendiente ajustes en yii 31/01/2025 entregado a prubas Bolivar
A13: JESUS PEÑA | C13: H4 Opción consulta casos en portal ARL | D13: EN PRUEBAS BOLIVAR | E13: 45671 | F13: 45673 | H13: 45677 | I13: =IF(ISBLANK(H13), NETWORKDAYS(F13, TODAY(),fESTIVOS!$A$1:$A$18), NETWORKDAYS(F13, H13, fESTIVOS!$A$1:$A$18)) -> 3 | L13: 20/01/2025 pendiente ajustes en yii 31/01/2025 entregado a prubas Bolivar
A14: JESUS PEÑA | C14: H5 Radicación individual | D14: EN PRUEBAS BOLIVAR | E14: 45671 | F14: 45678 | H14: 45678 | I14: =IF(ISBLANK(H14), NETWORKDAYS(F14, TODAY(),fESTIVOS!$A$1:$A$18), NETWORKDAYS(F14, H14, fESTIVOS!$A$1:$A$18)) -> 1 | L14: 31/01/2025 entregado a prubas Bolivar
A15: JESUS PEÑA | C15: H6 Adjunto | D15: EN PRUEBAS BOLIVAR | E15: 45671 | F15: 45679 | H15: 45679 | I15: =IF(ISBLANK(H15), NETWORKDAYS(F15, TODAY(),fESTIVOS!$A$1:$A$18), NETWORKDAYS(F15, H15, fESTIVOS!$A$1:$A$18)) -> 1 | L15: 31/01/2025 entregado a prubas Bolivar
A16: JESUS PEÑA | C16: VALIDAR HALLAZGO DE LAS PRUEBAS | D16: EN PRUEBAS BOLIVAR | E16: 45681 | F16: 45684 | H16: 45685 | I16: =IF(ISBLANK(H16), NETWORKDAYS(F16, TODAY(),fESTIVOS!$A$1:$A$18), NETWORKDAYS(F16, H16, fESTIVOS!$A$1:$A$18)) -> 2 | L16: 27/01/2025 pendiente ajustar caso internet en nativo 28/01/2025 ajustes en test para pruebas 28/01/2025 Pendiente ajuste en el campo identificacion en el 2do paso. 31/01/2025 entregado a prubas Bolivar

Sheet FINALIZADOS 2
A1: Asignado a | B1: Jira Caja | C1: Requerimiento | D1: ESTADO | E1: % | F1: dias estimados | G1: F.Asignado | H1: Fecha inicio | I1: F. estimada de entrega | J1: Finalizado | K1: Dias | L1: Jira TEST | M1: TEST | N1: jira PROD | O1: PRODUCCION | P1: OBSERVACIONES | Q1: Seguimiento 28 Abril | R1: Seguimiento 28 Abril 2 | S1: Seguimiento 5 mayo | T1: seguimiento 7 mayo | U1: seguimiento 9 mayo | V1: seguimiento 9 mayo 2 | W1: seguimiento 12 mayo | X1: seguimiento 14 mayo | Y1: seguimiento 15 mayo | Z1: seguimiento 16 mayo | AA1: seguimiento 19 mayo | AB1: seguimiento 21 mayo | AC1: seguimiento 23 mayo | AD1: seguimiento 26 mayo | AE1: seguimiento 28 mayo | AF1: seguimiento 30 mayo | AG1: seguimiento 4 Junio | AH1: seguimiento 6 Junio | AI1: seguimiento 9 Junio | AJ1: seguimiento 11 Junio | AK1: seguimiento 13 Junio | AL1: seguimiento 16 Junio | AM1: Column 4 | AN1: Column 5
A2: DANILO RAMIREZ | B2: GD772-94 | C2: tablero de analisis de la operación de reembolsos | D2: FINALIZADO | G2: 45751 | H2: 45756 | I2: 45760 | J2: 45759 | K2: =IF(ISBLANK(J2), NETWORKDAYS(H2, TODAY(),fESTIVOS!$A$1:$A$18), NETWORKDAYS(H2, J2, fESTIVOS!$A$1:$A$18)) -> 3 | P2: 07/04/2025:Iniciara tan pronto finalice las vulnerabilidades pendientes. 09/04/2025: Ayer Danilo no avanzó por vulnerabilidades; hoy inicia la implementación, coordinará con Jairo (extrae datos del informe); estiman 3-4 días (hasta el jueves o viernes) 10/04/2025: No avanzó ayer por otras prioridades; hoy dedicará tiempo y coordinará con Jairo para el contexto; estiman 3-4 días. 11/04/2025: Ayer ajustó el API del informe de digitación (puerto 888 en producción); hoy termina ajustes finales y avanza en la implementación en Yii, coordinado con Jairo para evitar duplicidad; Se solicita control de cambios MDSB-795762 en test, quedo ejecutado con exito y se escala control de cambios a produccion MDSB-796132. 14/04/2025: Se encentra terminando los ajustes necesarios para pasar el req a test para pruebas. 22/04/2025: Se realiza paso a producción.
A3: DANILO RAMIREZ | C3: vulnerabilidades claudia | D3: FINALIZADO | E3: 90 | G3: 45749 | H3: 45754 | I3: 45772 | J3: 45783 | K3: =IF(ISBLANK(J3), NETWORKDAYS(H3, TODAY(),fESTIVOS!$A$1:$A$18), NETWORKDAYS(H3, J3, fESTIVOS!$A$1:$A$18)) -> 22 | M3: 45755 | P3: 07/04/2025: Pendiente de revisar; implica cambiar librerías como JavaScript o Bootstrap, lo que evaluará hoy para determinar viabilidad,Iniciara tan pronto finalice implementación de la Vulnerabilidad- Web Application Information Disclosure. 08/04/2025: Inicio 09/04/2025:Ayer finalizó y resolvió esta vulnerabilidad; todas las vulnerabilidades están cerradas por ahora. | Q3: Se trabajaran alternando espacios con que permita la IA | R3: Pendiente cipres | S3: Paso a produccion 5 mayo | T3: finalizado 6 mayo
A4: DANILO RAMIREZ | C4: Vulnerabilidades Retest | D4: FINALIZADO | E4: 60 | G4: 45749 | H4: 45749 | I4: 45779 | J4: 45783 | K4: =IF(ISBLANK(J4), NETWORKDAYS(H4, TODAY(),fESTIVOS!$A$1:$A$18), NETWORKDAYS(H4, J4, fESTIVOS!$A$1:$A$18)) -> 25 | M4: 45754 | P4: 02/04/2025: Inicia con la implementación 03/04/2025: Ayer comenzó esta vulnerabilidad, avanzó poco por otras tareas; hoy continuará trabajando en ella. 04/04/2025: Unque avanzó bastante, la tarea aún no está finalizada. Hoy se continuará con ese objetivo. 07/04/2025 Finalizada en test 07/04/2025: haciendo un cambio en Application error messages y subira a test 08/04/2025: Finalizo implementación en test | Q4: Se trabajaran alternando espacios con que permita la IA | R4: pendiente 2 vulnerabilidades se entrega hoy | S4: Paso a produccion 5 mayo | T4: finaliado 6 mayo
