Workbook

Sheet EN PROCESO (Bolivar)
A1: Asignado a | B1: Jira Caja | C1: Requerimiento | D1: Descripcion req | E1: Actividad | F1: ESTADO | G1: % Avance | H1: Dias estimados desarrollo | I1: F.Asignado | J1: Fecha inicio | K1: Fecha estimada de entrega | L1: Finalizado | M1: Dias total desarrollo | N1: Fecha compromiso cliente | O1: TEST | P1: PRODUCCION | Q1: OBSERVACIONES | R1: VISIBLE | S1: Prioridad | T1: Jira TEST | U1: jira PROD | V1: Rama | W1: Seguimiento 5 mayo | X1: seguimiento 7 mayo | Y1: seguimiento 9 mayo | Z1: seguimiento 9 mayo 2 | AA1: seguimiento 12 mayo | AB1: seguimiento 14 mayo | AC1: seguimiento 15 mayo | AD1: seguimiento 16 mayo | AE1: seguimiento 19 mayo | AF1: seguimiento 21 mayo | AG1: seguimiento 23 mayo | AH1: seguimiento 26 mayo | AI1: seguimiento 28 mayo | AJ1: seguimiento 30 mayo | AK1: seguimiento 4 Junio | AL1: seguimiento 6 Junio | AM1: seguimiento 9 Junio | AN1: seguimiento 11 Junio | AO1: seguimiento 13 Junio | AP1: seguimiento 16 Junio | AQ1: seguimiento 18 Junio | AR1: seguimiento 20 Junio | AS1: seguimiento 25 Junio | AT1: seguimiento 26 Junio | AU1: seguimiento 27 Junio | AV1: seguimiento 01 de Julio | AW1: seguimiento 02 de Julio | AX1: seguimiento 04 de Julio | AY1: seguimiento 07 de Julio | AZ1: seguimiento 08 de Julio | BA1: seguimiento 09 de Julio | BB1: seguimiento 10 de Julio | BC1: seguimiento 11 de Julio | BD1: seguimiento 14 de Julio | BE1: seguimiento 15 de Julio | BF1: seguimiento 16 de Julio | BG1: seguimiento 17 de Julio | BH1: seguimiento 18 de Julio | BI1: seguimiento 21 de Julio | BJ1: seguimiento 23 de Julio | BK1: seguimiento 23 de Julio 2 | BL1: Column 61 | BM1: Column 62 | BN1: Column 63 | BO1: Column 64
A2: DANILO | B2: INTERNO-D001 | C2: Radicación Express con IA ( SALUD ) | F2: PRUEBAS CLIENTE | G2: 90 | H2: =IF(OR(J2="",K2="",K2<J2),0,NETWORKDAYS(J2,K2,fESTIVOS!$A$2:$A$53)) -> 40 | I2: 45715 | J2: 45715 | K2: 45775 | L2: 45734 | M2: =IF(OR(J2="",AND(L2="",TODAY()<J2),AND(L2<>"",L2<J2)),0, IF(L2="", NETWORKDAYS(J2,TODAY(),fESTIVOS!$A$2:$A$53), NETWORKDAYS(J2,L2,fESTIVOS!$A$2:$A$53) ) ) -> 14 | O2: 45734 | Q2: 28/02/2025: modificó el script para entrenar con lenguaje natural; el modelo propio (basado en Verner) reconoce respuestas rápidas (ej. segunda opinión médica) tras retirar el destilado. Es ligero y responde rápido. Planea ajustar, subir a dev/test y usar una base preentrenada para optimizar. 03/03/2025: El viernes 28 se subieron las modificaciones a un repositorio, pero aún falta un cambio que planea terminar y desplegar hoy, tras ajustes adicionales que retrasaron el despliegue inicial a dev y test. 04/03/2025: Ajustó el algoritmo del modelo (impresión y entrenamiento) el día anterior, subiendo los cambios al repositorio, pero falta un ajuste en el API para desplegarlo, ya que se alojará en un servidor distinto al de Oficina Virtual por limitaciones de capacidad; espera terminarlo pronto. 05/03/2025: No ha avanzado más en Radicación Express por priorizar el API de Recobros; habló con Jenry sobre cambios adicionales y planea retomarlo tras finalizar el API esta semana. 06/03/2025: Trabajó en una modificación para Radicación Express, pero no la finalizó por requerir más cambios; no dio más detalles ni avances significativos. 07/03/2025: Se detiene ya que se dedicara al API de recobros. 10/03/2025: Detenido ya que se encuentra trabajando en la Lectura de incapacidadaes por Python 12/03/2025 : Si es posible y se da el espacio en la sesion de presentación del API de recobros se realizara presentación de este requerimiento. 14/03/2025: Ayer se presentó el avance del proyecto al cliente y Se realizó un ajuste en la implementación, cambiando el modelo de multi-language a una versión en español para mejorar el rendimiento. Este cambio impactó parcialmente el entrenamiento, pero se espera recuperar la estabilidad durante la semana. 17/03/2025: El viernes avanzó en Radicación Express, resolviendo problemas menores, y ajustó la lógica para llevar al usuario al segundo o tercer paso tras confirmar; hoy sigue dedicado a esto, ajustando los datos enviados al formulario para finalizar esa parte. 18/03/2025: Terminó la integración del formulario de Radicación Express con autorizaciones médicas, autocompletando datos (ciudad, IPS, médico) si están completos o dejando en el primer paso si no; hoy subirá los cambios tras reunirse con Jenry para validar o ajustar. 19/03/2025: Desplegó Radicación Express en test, pero enfrentó problemas de capacidad en el servidor para entrenar el modelo (100 registros fallaron); ajustó el entrenamiento a un registro cada 15 minutos, logrando 3-4 ejemplos ayer, y hoy seguirá entrenando y ajustando. 20/03/2025:Verificó el modelo ayer, ajustó un fallo donde Python mataba el proceso a la mitad, y continuó el entrenamiento (pocos ciclos aún); hoy planea alcanzar 100 ciclos con registros diferentes. 21/03/2025: Revisó el entrenamiento del modelo, que ya superó 100 ejemplos sin problemas ayer; hoy seguirá monitoreando y avanzando en el entrenamiento 27/03/2025: El modelo ya se entrenó con los casos previos y reconoce información; hoy buscará tiempo para añadir 200 registros más para entrenar entre hoy y mañana. 28/03/2025: Ayer no adiocno 28/03/2025: No revisada ayer por falta de tiempo; hoy planea agregar 500 registros para entrenar y retomar el avance. 31/03/2025: El viernes agregó 173 ejemplos más (total 473 casos); el modelo entrena bien, reconoce 4 de 5 casos con léxico colombiano; hoy o mañana terminará esta tanda y planea sumar 500 registros más. 01/04/2025: Ayer insertó nuevos registros para entrenar el modelo esta semana. 09/04/2025: Entrenado con 800 casos, listo en test para pruebas por Santiago o usuarios; hoy se entregará oficialmente para pruebas por el cliente, con entrenamiento continuo; estiman 8 días para producción si se prioriza. 03/09/2025: Se corrigieron errores recientes y se entregó una nueva versión a Santiago. Se encuentra en proceso de validación, 27/02/2026: Hasta la fecha no se ha obtenido respuesta del cliente. | R2: False | V2: Se entrega para TEST | AU2: 1
A3: DANILO | B3: INTERNO-D002 | C3: Lectura de incapacidades por Python | F3: FINALIZADO | G3: 100 | H3: =IF(OR(J3="",K3="",K3<J3),0,NETWORKDAYS(J3,K3,fESTIVOS!$A$2:$A$53)) -> 64 | I3: 45702 | J3: 45702 | K3: 45797 | L3: 45713 | M3: =IF(OR(J3="",AND(L3="",TODAY()<J3),AND(L3<>"",L3<J3)),0, IF(L3="", NETWORKDAYS(J3,TODAY(),fESTIVOS!$A$2:$A$53), NETWORKDAYS(J3,L3,fESTIVOS!$A$2:$A$53) ) ) -> 8 | Q3: 14/02/2025 Se encuentra ajustando cambio de OCR para minimizar el tiempo de lectura realizando entrenamiento. 17/02/2025 Se realizo cambio de OCR, y pruebas 18/02/2025 ajustar un modelo diferente a ollama para mejorar la lectura del OCR. 19/02/2025 Continuara con los ajustes 20/02/2025 Realizar ajustes para hacer una entrega parcial hoy 21/02/2025 En pruebas de entrenamiento al nuevo modelo. 24/02/2025 Organizar datos y consultas e implementarlos en el entrenamiento del modelo para posteriormente pasar a produccion. 25/02/2025 Se adelanta las consultas par la construccion del dataset para entrenar el modelo (Bert), despues de terminar la construccion serla a los ambientes y comenzar con el entrenamiento. 26/02/2025 Se re ealiza despliegue a produccion el 25 de febrero, se realizara una modificacion en el dataset desplegarla a produccion para que se encuentre lista para usar, realizar pruebas e iniciar entrenamiento en las noche. 26/02/2025: Se suben a produccion las modificaciones y al iniciar el entrenamiento del modelo se presentaron varios inconveniestes encuanto a nombres de facientes y fechas con la data de produccion para lo cual se debio ajustar el dataset. 27/02/2025:se le daran tres ciclos de incapacidades y a medio dia validar cual fue el nivle de aprendizaje. 28/02/2025:Culminó una etapa del modelo, entrenándolo con 2 ciclos (20 registros cada uno), logrando identificar nombre del paciente, fechas y número de incapacidades. Planea entrenar con un dataset más grande en la noche (por uso de RAM) y mejorar la clasificación con datos existentes 04/03/2025: Ayer ajusto los scripts de entrenamiento para que esta semana se pueda entrenar más rápido el modelo. 05/03/2025: Las últimas modificaciones se subieron el viernes 28 de febrero, el modelo se entrena en la noche y los fines de semana cada 6 horas con dataset construido dos horas antes; revisará resultados la próxima semana para evaluar el entrenamiento. 10/03/2025; Se encuentra realizando validaciones a los resutados del entrenamiento de la semana anterior y mejorando el regex mientras el modelo mejora su entrenamiento. 11/03/2025: Está trabajando en un tab para el portal de incapacidades que muestre la información leída por el modelo de IA; planea avanzar lo más posible hoy o terminarlo, sin bloqueos ni dudas reportadas. 12/03/2025: Ya se encuentra ajustado el algorimo de la lectura y se guarda la información en una tabla para mostrar la información extraida en el aplicativo de incapacidades, hoy se ajustara la vista para mostrar la información en la consulta de incapacidades. 13/03/2025: Ayer finalizó una vista para mostrar la información procesada por el modelo de IA, con ajustes adicionales completados; hoy espera definir prioridades tras una reunión de las 9 a.m. 14/03/2025: Se presentó el avance del proyecto a un grupo de personas, generando gran interés Se resolvieron dudas sobre la tecnología y se trabajará en una versión más completa. 18/03/2025: No está trabajando activamente en esto; el modelo se entrena en la noche con un dataset de imágenes, pero con pocos casos aún para mejorar efectividad, y planea revisar pronto el porcentaje de precisión. 28/03/2025: No le dedicó tiempo ayer; hoy buscará agregar más registros para entrenar el modelo. 01/04/2025: Revisó el modelo ayer; avanza poco, pero ajustó el entrenamiento para que sea más rápido sin afectar el servidor; entrena cada 6 horas los fines de semana para aprovechar recursos. 09/04/2025: Entrenado lentamente por recursos limitados (pocos ciclos para no afectar el servidor); lleva 15-20 días así, hoy revisarán su efectividad para decidir si ajustar o buscar alternativas. | R3: TRUE | AB3: Se correra un comando para revisar el estado de lectura de incapacidades, medir el avance del entrenamiento y validar los resultados obtenidos. | AE3: No se pudo validar completamente el avance debido a una caída del servidor ocasionada por falta de direcciones IP, un problema que no había ocurrido anteriormente, validara hoy el avance | AF3: El 19 de mayo,Se modifico el OCR para mejorar la lectura y confirma que ha alcanzado una efectividad del 85% | AI3: Falta un detalle menor para terminar la integración de la información extraída sobre incapacidades. Planea cerrarlo hoy. | AJ3: El 28 de mayo Se implementó la ejecución automática de solicitudes de incapacidades a partir de la lectura con IA. Se visualiza en una pestaña separada para mostrar resultados al cliente. Se discutió que, aunque Bolívar no usa actualmente los datos extraídos, la información será útil para validaciones futuras. | AN3: Los porcentajes de efectividad no superan el 50 % en pruebas recientes. En casos revisados, los valores más comunes rondan el 37 %, incluso en incapacidades actuales. Se recomienda revisar la calidad de los documentos fuente y optimizar la lógica de extracción | AO3: No se ha podido validar el rendimiento del modelo | AR3: entrenamiento fines semana | AU3: 27/06/2025:Pendiente validacion de efectividad en la lectura y ajuste del OCR para disminuir el consumos de recusos.
A4: DANILO | B4: GD772-103 | C4: Paso de documentos de fs a s3 | D4: Fecha de entrega al clente: 10/11/2025 | F4: CANCELADO | G4: 95 | H4: =IF(OR(J4="",K4="",K4<J4),0,NETWORKDAYS(J4,K4,fESTIVOS!$A$2:$A$53)) -> 3 | I4: 45701 | J4: 45762 | K4: 45768 | L4: 45799 | M4: =IF(OR(J4="",AND(L4="",TODAY()<J4),AND(L4<>"",L4<J4)),0, IF(L4="", NETWORKDAYS(J4,TODAY(),fESTIVOS!$A$2:$A$53), NETWORKDAYS(J4,L4,fESTIVOS!$A$2:$A$53) ) ) -> 25 | O4: 45939 | Q4: 19/02/2025 se tuvo sesion Con Juan Angel para validar como hacer la copia de los documentos y se definio un orden para hacer las trasferencias, se programara la tarea para el 20 de Febrero y se validara el 21 de febrero el resultado 21/02/2025 La tarea programada para la trasferencia de las imagenes se ejecuto ayer 20 de febrero y hoy se realizara la validación de resultados. 24/02/2025 Se realizó la validación, pero no se evidenciaron resultados. Se consultará con la persona encargada para determinar la razón por la cual la transferencia no fue exitosa 26/02/2025 Se radica ticket MDSB-770619 solicitando apoyo para ejecutar la transferencia de archivos desde el disco FS hacia el bucket S3. 27/02/2025 El Ticket MDSB-770619 escalado a bolivar solicitando apoyo para ejecutar la transferencia de archivos desde el disco FS hacia el bucket S3 se en cuentra en estado en proceso. 28/02/2025 El Ticket MDSB-770619 escalado a bolivar solicitando apoyo para ejecutar la transferencia de archivos desde el disco FS hacia el bucket S3 se en cuentra en estado en proceso. 04/03/2025 No hay avances ni respuestas al ticket MDSB-770619 sobre el paso de documentos; 11/03/2025: Se comenta el ticket MDSB-770619 solicitando avances en la solicitud o si se requiere alguna información adicional o algún ajuste de nuestra parte para avanzar con la sincronización. 13/03/2025: A un no se obtiene avances del progreso del ticket MDSB-770619. 28/03/2025: Depende de Bolívar para transferir archivos; no hay avances locales por ahora. 02/04/2025: Ayer Infraestructura de Bolivar realizo la sincronizacion del primer directorio Sincronización de /opt/storage/img04/arp, e indican que seguiran migrando los directorios en las noches ya que generan afectacion en el servidor. 03/04/2025: Hoy infraestructura informa la fecha tentativa de finalizacion es el 4 de abril. el dia de hoy estan terminando la carpeta IMG02 04/04/2025: el 3 de abril en la noche se detuvo la transferencia de documentos debido a que ocaciono la caida del servidor a 10:52 pm. 07/04/2025: Confirman finalizacion del paso de documentos, Se solverificar que el tamaño del disco S3 corresponda al mismo del FS. 09/04/2025: De acuerdo a la sesion con infraestructura de bolivar se Construira plan de paso Fs a S3, hoy se pasa el faltante y se expone el s3 a producción. 10/04/2025 se confirma paso de toda la informacion MDSB-770619 01/10/2025: Se tiene previsto iniciar el trabajo de migración alrededor del 15 de octubre. Actualmente infraestructura ya realizó una transferencia hacia un repositorio intermedio (“grandote”), pero es necesario garantizar que la información también se replique en nuestro entorno para validar la integridad de los datos. Se sugiere solicitar a infraestructura un avance formal del estado de la migración, dado que el proceso lleva aproximadamente un mes en ejecución. El equipo considera importante iniciar desde ya la planeación de las pruebas de validación para asegurar que la transferencia se haya completado de manera correcta y sin pérdida de información. 06/10/2025: Se estima un tiempo de implementación de aproximadamente una semana, considerando revisión de sincronizaciones y definición del punto de partida 08/10/2025: Entre el 6 y 7 de octubre se avanzó en el mapeo de campos relacionados con las rutas de almacenamiento (campo BAT) y en la normalización de URLs para garantizar la correcta transferencia de archivos. Se detectaron registros fuera de estándar que serán reportados. Se implementa la lógica para transferencias diarias y eliminación de archivos con más de 90 días, con trazabilidad mediante logs. Se acordó definir una variable de entorno para el almacenamiento híbrido (local y S3), asegurando compatibilidad en los visores y consultas de archivos. 09/10/2025: Se escala control de cambios a test MDSB-907732 para la creación del esquema auditoria y de la tabla auditoria.verificacion_efs_s3. Control de cambios ejecutado con exito. 09/10/2025: Se escala control de cambios a Producción MDSB-907823 para la creación del esquema auditoria y de la tabla auditoria.verificacion_efs_s3. 10/10/2025: Durante los días anteriores se avanzó en múltiples tareas asociadas al requerimiento. Se implementó y probó con éxito la lógica de sincronización diaria de los archivos del día anterior, con un tiempo promedio de ejecución de 6 minutos. Se desarrolló e implementó la lógica para eliminación automática de archivos del disco FS con más de 90 días de antigüedad, validada en el entorno PRUN mediante pruebas exitosas. Se ajustó la lógica de consulta de archivos desde las aplicaciones, la cual ya se encuentra funcional. Se creó un control de certificación de migración, que valida la existencia de los archivos en S3 15/10/2025: El proceso de migración se encuentra finalizado en un 95 %. Falta aprobación del control de cambios para ejecutar las pruebas en producción y completar la verificación de registros. El script de validación está implementado y funcional. 17/10/2025: A la espera de la aprobación de control de cambios para ejecutar los scripts en producción y validar la integridad de la información migrada. 20/10/2025: En espera de aprobación del control de cambios por parte del QA (Ricardo) para poder continuar con la sincronización de archivos 24/10/2025: El control de cambios se ejecutó correctamente en el ambiente de producción; sin embargo, se evidenció que faltan los permisos necesarios para acceder a la tabla. 27/10/2025: Se escala control de cambios MDSB-918655 para los permisos requeridos. 29/10/2025: Control de cambios MDSB-918655 ya obtuvo las aprovaciones necesarias para avanzar, se estima sea incluido en el comité de cambios digitales de hoy, una vez ejecutado se continuará con la verificación y validación de las imágenes transferidas. 05/11/2025: Control de cambios MDSB-918655 ejwcutado con exito el 29 de octubre, a hoy no se 11/11/2025: Requerimiento cancelado según instrucción de la gerencia de Imagine. | R4: FALSE | S4: 0 | T4: MDSB-907732 | U4: MDSB-907823 / MDSB-918655 | AB4: verificar la transferencia de archivos, ya que se completó la transferencia de los documentos faltantes | AD4: Validara la cantidad de documentos tranferidos y dara respuesta al correo | AE4: se revisó la transferencia de archivos, donde se detectaron diferencias que fueron comentadas en el jira. | AF4: Implementara logica para el conteo de imagenes y se prepara para realizar el cambio del disco el jueves 22 de mayo a las 6pm | AG4: El 21 de mayo se implementó una lógica para el conteo de archivos transferidos, como parte de la preparación para el paso a producción programado para el lunes 26 de mayo. Las pruebas realizadas el 22 de mayo permitieron validar el montaje del FS en una unidad alternativa, lo cual ofrece flexibilidad para intervenir manualmente en caso de archivos faltantes o fallidos. Infraestructura será responsable de la transferencia de los registros faltantes durante el fin de semana, con posibilidad de apoyo nuestro si es necesario. | AH4: Se avanzó en los conteos correspondientes a img04. Se espera consolidar los resultados en el transcurso del día para dar respuesta formal con evidencias a los correos correspondientes. | AI4: El conteo de datos para FS y S3 sigue pendiente. se planea terminar hoy el conteo y compartir evidencias para análisis, el paso a produccion sigue pendiente. | AJ4: El 28 de mayo se termina el conteo y se envian evidencias, pendiente confirmación de Bolivar | AO4: Se ajustaron fechas para realizar un nuevo reconteo de archivos transferidos | AR4: Para el viernes 20 de junio se programo Ventana de mantenimiento a las 5 pm para realizar paso a producción. | AS4: 25/06/2025: El viernes 20 de junio se intentó realizar el paso a producción, pero no fue exitoso, ya que al momento de cargar archivos el sistema no lo permitía debido a temas de permisos que no pudieron resolverse en ese momento,Por esta razón, fue necesario reversar la implementación.Se estima realizar nuevamente el paso a producción el día jueves 26 de junio. | AT4: 26/06/2025: Se programa paso a producción el día miércoles 2 de julio de 10:00 a 11:00 pm. | AW4: 02/07/2025: Para hoy esta programado el paso a producción a las 10 Pm. | AX4: 04/07/2025: El paso programado para el 2 de julio no fue exitoso debido aque se presentaron dificultades al levantar el servicio, Bolivar propone clonar la máquina actual para probar configuraciones antes hacer el paso a producción. Se acordó que la máquina estaría lista para pruebas el lunes 7 de julio, con la realización de estas programadas para el martes 8 de julio. | BA4: 09/07/2025:Ayer 8 de junio se recibió el ambiente con S3 para pruebas de parte del cliente, se confirmó que la copia es fiel a producción realizando pruebas básicas de navegación. Se planea probar el montaje completo con S3 y revisar si el problema de bloqueo persiste al montar EBS. | BB4: 10/07/2025:Se escala solicitud MDSB-844713 para habilitar el acceso a la instancia de pruebas_s3 para validar localmente la implementación de los discos, antes del paso a producción. | BC4: 11/07/2025: Pendiente respuesta del ticketMDSB-844713 ya que el bloqueo impide validar completamente las aplicaciones. Mientras tanto, se ha avanzado con otras tareas técnicas en ese entorno. | BD4: 14/07/2025: El viernes 11 de julio se supero el bloqueo de red que impedía comunicación con el puerto 80, lo cual permitió avanzar en el montaje del EC3. Se identificó un problema con el RECAPTCHA debido a que este está configurado para un dominio específico, y en el ambiente actual se está usando una IP directa, Se continuará en lo posible de solucionar y comenzar a realizar pruebas. | BF4: 16/07/2025: Se continúa con las pruebas y estabilización del S3 y el EBS. Ayer se intentó actualizar Apache, lo que obligó a reinstalar el sistema operativo por incompatibilidad de librerías. Se realizó la restauración del sistema para continuar con las pruebas hoy. Se está evaluando si el EBS es viable dado que su integración obliga a actualizar todo el sistema operativo. | BG4: 17/07/2025: Se aplican las actualizaciones necesarias para corregir el problema con el disco EBS pero la actualización no concluyó como se esperaba, nuevamente los discos en el ambiente de pruebas, manteniendo una estructura lógica diferente a la anterior | BH4: 18/07/2025: El 17 de julio se realizaron pruebas satisfactorias en el ambiente de pruebas S3. Se planea continuar con pruebas de rendimiento simulando entre 40 y 80 sesiones activas para validar el comportamiento similar al entorno productivo. Se espera finalizar hoy para liberar el ambiente y continuar con otras tareas como la actualización de Apache. | BI4: 21/07/2025: El viernes 18 de julio se realizaron pruebas de carga y funcionales, corrigiendo errores detectados. Se entregó informe y el ambiente quedó listo para el paso a producción. Se identificó mejora en la latencia desde FPM. Se requiere confirmación del cliente para la fecha de paso a producción. | BJ4: 23/07/2025: Se realizara paso a produccion 23 de julio a las 10 pm | BK4: 25/07/2025: El día miércoles 23 de julio se realizó un despliegue exitoso al entorno S3. Sin embargo, el 24 de julio fue necesario revertir los cambios debido a fallos de rendimiento detectados tras la implementación. Se requiere evaluar la capacidad actual del servidor y documentar lo ocurrido, con el fin de identificar las causas del problema y definir acciones correctivas que garanticen la estabilidad del sistema en futuros despliegues. | BM4: 30/07/2025:El proceso se encuentra en pausa hasta que se defina el método para el traspaso de imágenes
A5: DANILO | B5: GD772-64 | C5: Api de recobros | F5: DETENIDO CLIENTE | H5: =IF(OR(J5="",K5="",K5<J5),0,NETWORKDAYS(J5,K5,fESTIVOS!$A$2:$A$53)) -> 0 | I5: 45712 | J5: 45715 | L5: 45723 | M5: =IF(OR(J5="",AND(L5="",TODAY()<J5),AND(L5<>"",L5<J5)),0, IF(L5="", NETWORKDAYS(J5,TODAY(),fESTIVOS!$A$2:$A$53), NETWORKDAYS(J5,L5,fESTIVOS!$A$2:$A$53) ) ) -> 7 | Q5: 24/02/2025 Retomara esta tarea que estaba asignada a Jhoan. 26/02/2025 se encuentra pendiente hasta terminnar el desarrollo de la lectura de incapacidadaes por Python 27/02/2025: Se intentara leer las URLs prefirmadas en T3. y revisar si lo que Joan desarrollo sirve o si se necesita crear una implementación distinta para que funcione bien. 28/02/2025: Avanzó en pruebas; las URL prefirmadas funcionan, pero faltan credenciales completas (Access Key ID y Secret Access Key) para permisos. Dejó un comentario al respecto en el ticket MDSB-766368. 03/03/2025: El viernes se recibe respuesta a un ticket relacionado con credenciales de usuario y una URL prefirmada. Validó que las credenciales funcionaran y logró resolver el tema del usuario quedando pendiente Implementar la URL prefirmada (o listado de URLs) en la consulta exitosa. 04/03/2025: Avanzó configurando el ambiente en su máquina y revisando la lógica del API; hoy planea implementar el consumo de URLs prefirmadas y dejarlo listo si es posible. 05/03/2025 ajustó la recepción de parámetros y consultas del API, corrigiendo errores como la confusión entre siniestro y cédula, y añadió claves "not found" para identificar imágenes no disponibles en S3; falta terminar la consulta de facturas y revisar un PATH en tipologías, planeando compartir resultados de incapacidades hoy a las 10 y avanzar en facturas. 05/03/2025: No permite conectar al ambiente de desarrollo por el Administrador de Sesiones de AWS se radica ticket MDSB-774334 06/03/2025: Ayer por la mañana tuvo problemas de acceso al ambiente por un agente, pero en la tarde probó los cambios en incapacidades, generando URLs prefirmadas con claves "found" y "not found" (código 200), indicando imágenes no disponibles en S3; hoy planea avanzar en facturas, revisar tipologías y un posible Paht. 07/03/2025: Estandarizó consultas corrigiendo errores de sintaxis y añadió una validación para mostrar un mensaje genérico en errores 500 (con logs internos detallados); ya funciona la búsqueda de facturas, y hoy ajustará y compartirá la búsqueda de tipologías que usa la tabla Nexos para URLs prefirmadas. 10/03/2025: El viernes 7 de marzo finalizo el requerimiento y reslizo entrega al cliente para pruebas. 12/03/2025 : Se escala solicitud MDSB-778771 implementar un control de acceso al dominio de imaginex-dev-recobros.segurosbolivar.com.para que únicamente se permita la comunicación desde los siguientes orígenes: API Gateway de AWS Seguros Bolívar Refactoring ARL: SegurosBolivar-Bienestar-ARL-DEV SegurosBolivar-Bienestar-ARL-STG SegurosBolivar-Bienestar-ARL-PROD 13/03/2025: La solicitud MDSB-778771 escalada a infraestructura se en cuentra en estado en proceso. 18/03/2025: ayer infroman que los ajustes fueron realizados. 20/03/2025: Dedicó tiempo ayer a privatizar el dominio tras un ticket previo; DEV ya funciona con reglas, y hoy solicitará el dominio de test para avanzar. 20/03/2025: Solicita dominio en el ticket MDSB-783892 21/03/2025: Ayer radicó el ticket MDSB-783892 para solicitar el dominio de test, ya que DEV funciona bien sin errores reportados, Realizara paso a test tan pronto se reciba una respuesta positiva de la solicitud. 26/03/2025: En el ticket MDSB-783892 solictan diligenciamiento de información, Danilo envia formato solicitado, confirman la generación del registro. 27/03/2025: Si todo sale bien con Autorizaciones Médicas esta mañana, por la tarde iniciará la implementación del host virtual en test. 28/03/2025: Ayer implementó el host virtual para test y validó reglas con el ticket MDSB-787645, restringiendo acceso al dominio; está avanzado, pendiente de pruebas finales. 01/04/2025:Ticket MDSB-787645 ejecutado con exito, y se escala Ticket MDSB-789767 solicitando la creación del subdominio imaginex-recobros.segurosbolivar.com. (Produccion). 03/04/2025: Bolívar detuvo el requerimiento hasta aprobar fase 2; sigue avanzando el ticket MDSB-789767 para el DNS, falta completar el formato solicitado con el dato "value" (buscará apoyo de Edgar hoy). 04/04/2025: Se resolvió el ticket MDSB-789767 pendiente para la creación del DNS en producción, aunque la funcionalidad aún no está habilitada, Esto se hizo para evitar retrasos cuando se autorice el paso a producción. | R5: FALSE
A6: DANILO | B6: INTERNO-D003 | C6: Comprimir información del body de la tabla cola_correos | F6: DETENIDO CLIENTE | H6: =IF(OR(J6="",K6="",K6<J6),0,NETWORKDAYS(J6,K6,fESTIVOS!$A$2:$A$53)) -> 0 | I6: 45747 | J6: 45747 | M6: =IF(OR(J6="",AND(L6="",TODAY()<J6),AND(L6<>"",L6<J6)),0, IF(L6="", NETWORKDAYS(J6,TODAY(),fESTIVOS!$A$2:$A$53), NETWORKDAYS(J6,L6,fESTIVOS!$A$2:$A$53) ) ) -> 295 | Q6: 01/04/2025: Ayer trabajó en comprimir el body de la tabla cola_correos; una extensión externa logró un 25-26% de compresión (32 GB en producción), pero no tiene soporte para Postgres 15.5; propuso un script en Python que reduce hasta 50%, aunque se evita depender de scripts por ser implementación adicional; sigue en evaluación. 02/04/2025: Se define que antes de implementar cualquier cambio, se debe consultar con el cliente (Bolívar). Se discutirán los resultados obtenidos y se determinará si la solución es aceptable. Se sugiere la alternativa de utilizar un trigger en la base de datos, lo que permitiría comprimir y descomprimir automáticamente los datos sin necesidad de modificaciones en el código de la aplicación. Esto simplificaría la implementación y reduciría la carga de desarrollo. 03/04/2025: De acuerdo a la sesion con Bolivar, quedó pendiente enviar la especificación técnica a Leidy para escalarla a tecnología y aprobar la solución propuesta por imagine (compresión del 25-26% o script al 50%); redactará el correo hoy con Jenry. 09/04/2025: Pendiente de confirmación de Bolívar sobre la solución propuesta; Jenny sugirió pasarlo a producción, pero requiere una implementación (1 semana estimada) | R6: FALSE
A7: JAIRO | B7: MDSB-707440/GD772-74 | C7: Portal reembolsos ARL (FLUJO YII) | F7: FINALIZADO | G7: 100 | H7: =IF(OR(J7="",K7="",K7<J7),0,NETWORKDAYS(J7,K7,fESTIVOS!$A$2:$A$53)) -> 11 | I7: 45719 | J7: 45779 | K7: 45793 | L7: 45791 | M7: =IF(OR(J7="",AND(L7="",TODAY()<J7),AND(L7<>"",L7<J7)),0, IF(L7="", NETWORKDAYS(J7,TODAY(),fESTIVOS!$A$2:$A$53), NETWORKDAYS(J7,L7,fESTIVOS!$A$2:$A$53) ) ) -> 9 | P7: 45883 | Q7: 03/03/2025: Iniciara despues de finalizar el req GD772-83 Boton Glosa parcial del total de la factura 10/03/2025; Inicia con el desarrollo. 11/03/2025 : Inicio bajando el sitio, pero no avanzó mucho debido a que Jenry le asignó otro requerimiento (Captura de datos e informe). 21/03/2025:Se iniciara con el desarrollo despues de cerrar el req GD772-72 Requerimiento Captura de datos e informe (Reembolsos). 27/03/2025: Continuará con este requerimiento tras subir GD772-72 a test; no reportó avances ayer. 28/03/2025: Iniciará hoy tras subir GD772-72 a test; no avanzó ayer. 02/04/2025: Espera reiniciar despues del medio dia con el req. 10/04/2025: Se realizaron cambios menores previos a la activación. Se planea iniciar la activación hoy del req. 11/04/2025: tiene el ambiente listo pero no ha iniciado código; espera mostrar avances esta tarde. 14/04/2025: tiene el ambiente listo pero no ha iniciado código,Informa que a un no ha reactivado el req. 11/08/2025: Aprueban control de cambios en comite de cambios digitales y se ejecutara hoy 11 de agosto a las 4:20pm 20/08/2025: El requerimiento ya fue implementado y migrado a producción el jueves 14 de agosto. Se estabilizó el viernes y quedó consolidado en la rama máster. | R7: TRUE | T7: MDSB-814902 | U7: MDSB-856139 | V7: Se retoma luego del 104 | W7: Se inicia requerimiento el 5 de mayo , en 2 semanas se entrega | X7: seguimos en el proceso | Z7: Se pausa y se da inicio a analiticia fila 56 | AA7: Se está analizando el tema de asignación por valores y explorando cómo incorporar el componente de servicios. | AB7: En el proceso de reembolsos se ha llegado a la etapa de asignación y radicación en "sí salud" | AD7: pasar pacial, solicitara cambios en test, se escala control de cambios a test MDSB-814902 | AE7: Control de cambios MDSB-814902 ejecutado el viernes 16 de mayo, está desarrollando actividades relacionadas con la radicación en salud. Se espera pasar un avance parcial pronto a tets para que Jenry pueda comenzar las pruebas de digitación | AF7: Se realiza paso a test 20 de mayo un parcial y continuara trabajando en el restante del requerimiento | AG7: Se realizaron ajustes en inconsistencias, permisos y roles. Se pasó un parcial para pruebas, y se está a la espera de validaciones para continuar con los ajustes finales. | AI7: Se está trabajando en unificar los informes de ARL con los de Reembolso Salud en una misma pestaña, Las pruebas dependen de un servicio de Bolívar que aún no está disponible | AJ7: Se creó el primer informe específico para ARL basado en los ya existentes para Reembolso Salud. Está en proceso de pruebas, | AK7: El API presenta fallas en ambiente de pruebas; según tecnología, se propondrá apuntar el sitio de test a produccion para poder llevar acabo las pruebas y autoricen el paso a produccion. Se debe considerar personalizar plantillas de respuesta para ARL. | AL7: Desarrollo ya se encuentra en test, a la espera de confirmación si el rachivo de pagos en igual al de salud. | AM7: El viernes 6 de junio se informa a Bolívar que pueden iniciar las pruebas con la implementación de la simulación del sistema SISalud, con el fin de validar el flujo completo de radicación en ausencia del entorno funcional | AN7: A la espera de habilitación del ambiente de pruebas para que Bolivar continue con las pruebas, Bolivar debe gestionar la activación para continuar. | AO7: El requerimiento sigue en ambiente de pruebas. No hay confirmación de validaciones de parte de Bolivar. | AQ7: Sigue en pruebas por Bolivar. | AU7: 27/06/2025: Se estima tiempo de entrega del resultado de las pruebas el 1 de julio por parte de bolivar | BF7: 16/07/2025: El 15 de julio el portal fue entregado al cliente para pruebas, se entregaron tanto las cartas como la funcionalidad del flujo completo. | BJ7: Cambio en las cartas | BK7: Pendiente confirmar que modificaciòn se requiere | BM7: 30/07/2025: El cliente ha dado visto bueno para realizar el paso a producción. Se procede a escalar el control de cambios MDSB-856139
A8: JESUS | B8: MDSB-780227 | C8: Duplicación de actividades en Nativo | E8: 1. comando quitar duplicados 2. Revisar la funcio´n de reasignar. 3. Revisar flujos (en nativo) | F8: FINALIZADO | G8: 100 | H8: =IF(OR(J8="",K8="",K8<J8),0,NETWORKDAYS(J8,K8,fESTIVOS!$A$2:$A$53)) -> 0 | I8: 45730 | J8: 45733 | L8: 45824 | M8: =IF(OR(J8="",AND(L8="",TODAY()<J8),AND(L8<>"",L8<J8)),0, IF(L8="", NETWORKDAYS(J8,TODAY(),fESTIVOS!$A$2:$A$53), NETWORKDAYS(J8,L8,fESTIVOS!$A$2:$A$53) ) ) -> 61 | Q8: 18/03/2025: No alcanzo a revisar la duplicación de casos; hoy analizará los radicados por buzón (flujo correcto pero con actividades duplicadas), y podría crear un comando si no encuentra la causa. 19/03/2025: Revisó ayer por la mañana la duplicación de actividades en Nativo sin encontrar errores en el código; hoy continuará investigando la causa. 20/03/2025: Se detiene para darle pioridad al req GD772-92 - Malla CUPS en Nativo. 03/04/2025: Continua detenida ya que se debe dar prioridad al Req GD772-84 Comunicaciones gestión de aportes sin afiliacion (masivos). | R8: TRUE | AP8: Retomara validación de la incidencia. | AU8: se implemento check para colocar flujo en administracion. Se identificó que el error se debía a que algunas tipologías no tenían definido el tipo de asignación como "flujo", lo que permitía la apertura de múltiples actividades para un mismo caso. Se actualizó la configuración de dichas tipologías,
A9: JESUS | B9: GD772-87 | C9: Implementar en laravel la autenticación con QR | F9: DETENIDO CLIENTE | G9: 97 | H9: =IF(OR(J9="",K9="",K9<J9),0,NETWORKDAYS(J9,K9,fESTIVOS!$A$2:$A$53)) -> 2 | I9: 45691 | J9: 45688 | K9: 45691 | L9: 45700 | M9: =IF(OR(J9="",AND(L9="",TODAY()<J9),AND(L9<>"",L9<J9)),0, IF(L9="", NETWORKDAYS(J9,TODAY(),fESTIVOS!$A$2:$A$53), NETWORKDAYS(J9,L9,fESTIVOS!$A$2:$A$53) ) ) -> 9 | O9: 45723 | Q9: 03/02/2025 Generacion de la Vista del codigo de 2 pasos en login de Bolivar 05/02/2025 Se mostraran avances para el 7 de Febrero 07/02/2025 Inicia encriptación de datos, sesion a 4pm hoy para mostrar avances en dev 10/02/2025 Quitar la autorecuperación del QR. 12/02/2025 Se sube a dev el login de laravel 21/02/2025: se debe incluir a donde se envia el correo de recuperación. 24/02/2025: se escaló el control de cambios a test con el ticket MDSB-768688. 25/02/2025: Se encuentra pendiente creacion de req caja para asociarlo al control de cambios y se de la aprobacion de QA. 28/02/2025: Pendiente creacion de requerimiento caja de parte de Bolivar, Imagine reaizara el envio del manual de usuario. 03/03/2025 : El dia viernes 28 de febrero Bolivar crea el requerimiento caja GD772-87 para adjuntarlo al control de cambios MDSB-768688 en test y continuar con el proceso. 04/03/2025: Control de cambios MDSB-768688 se encuentra en estado aprobacion QA de Bolivar. 05/03/2025: Control aprobado por QA, Control de cambios ejecutado con éxito 06/03/2025: Subió el doble factor a test ayer, pero no compara bien el código del Authenticator; sospecha confusión por claves en Develop o un fallo en la librería, y lo revisará hoy. 07/03/2025: El doble factor no valida bien el código; ayer descartó conflictos en Develop borrando registros, y hoy investigará si es la librería o el dominio compartido. 10/03/2025. El viernes 7 de marzo identifico que la hora del servidor de tets esta adelantada respecto a la hora del celular, quedo ajustado. 21/03/2025: Pendiente resultado de pruebas de Bolivar y el visto bueno para realizar paso a produccion. 26/03/2025: Bolivar informa que el resultado de las pruebas las enviaran la semana del 31 de marzo y confirman la implementación en los 2 aplicativos (Nativo y Yii) 03/04/2025:Bolivar tiene programadas para el 3 y 4 de abril con diferentes perfiles de usuario, de acuerdo al resultado solicitaran paso a producción la próxima semana. 10/04/2025: Bolívar autorizó ayer iniciarlo en test para los ambientes de Yii y nativo 25/09/2025: Deacuerdo a nuevo mentodo de autenticación propuesto por el cliente seda por cancelado este requerimiento y se iniciara el GD772-146 | R9: FALSE | T9: MDSB-768688 | U9: MDSB-849084 | AO9: Esta pendiente resultados de las pruebas de Bolivar | AR9: El 18 de Junio Bolivar informa que realizan las pruebas en test y aun realizando la exclusión de usuario (Listas blancas) se está solicitando doble factor de autenticación Se identificó que la funcionalidad de Listas Blancas no está operando correctamente desde el navegador debido al score del CAPTCHA. Como propuesta, se sugiere implementar una validación directa por cédula, eliminando la dependencia del CAPTCHA. | AS9: 24/06/2025: Jesus entrega el viernes 20 de junio ajuste de Listas blancas, el usuario activo en listas blancas se le debe omitir la solicitud del codigo de verificación. 24/06/2025: Se aplica ajuste, se confirma funcionalidad y se le notifica al cliente para su validación. | BE9: 15/07/2025: El cliente confirma la aprobación para el paso a producción; sin embargo, la ejecución queda pendiente de definir la fecha, ya que se requiere realizar previamente la divulgación al equipo de trabajo, y por parte de Imagine se debe solicitar control de cambios en produccion. | BF9: solicitar control de cambios
A10: JESUS | B10: GD772-87 | C10: Implementar en Yii y Nativo la autenticación con QR | F10: DETENIDO CLIENTE | G10: 97 | H10: =IF(OR(J10="",K10="",K10<J10),0,NETWORKDAYS(J10,K10,fESTIVOS!$A$2:$A$53)) -> 0 | I10: 45761 | J10: 45761 | L10: 45771 | M10: =IF(OR(J10="",AND(L10="",TODAY()<J10),AND(L10<>"",L10<J10)),0, IF(L10="", NETWORKDAYS(J10,TODAY(),fESTIVOS!$A$2:$A$53), NETWORKDAYS(J10,L10,fESTIVOS!$A$2:$A$53) ) ) -> 7 | O10: 45771 | Q10: 14/04/2025: Se estima iniciar con la implementación tras terminar con los ajustes del req GD772-84. 05/09/2025: En pruebas con nuevos usuarios se identificó un error: el mismo código no funciona en las tres plataformas, obligando a generar múltiples claves. Este comportamiento no se presentó en fases de prueba inicial. Se solicitó revisión técnica. 17/09/2025:El cliente informa que se requiere adicionar un segundo método de autenticación, similar al utilizado para la recuperación de clave 25/09/2025: Deacuerdo a nuevo mentodo de autenticación propuesto por el cliente seda por cancelado este requerimiento y se iniciara el GD772-146 | R10: FALSE | T10: MDSB-768688 | U10: MDSB-849084 | AB10: Bolivar reporta 2 halazgo en la pruebas. | AF10: El 20 de mayo se realiza ajuste en la recuperación de codigo y queda pendiente la inclusion de lsitas blancas tan pronto se ajuste el modulo en yii. | AG10: continúa ajustando la lógica para excluir la validación de listas blancas en el doble factor. | AH10: Se finalizó e implementó exitosamente en TES la funcionalidad pendiente de lista blanca relacionada con el doble factor. Este entregable ya está en ambiente de pruebas, se Realizaran pruebas de funcionamiento | AI10: El 26 de mayo Se finalizan los ajustes indiecados por Bolivar y se infroma para que realicen las pruebas. | AO10: Esta pendiente resultados de las pruebas de Bolivar | AR10: El 18 de Junio Bolivar informa que realizan las pruebas en test y aun realizando la exclusión de usuario (Listas blancas) se está solicitando doble factor de autenticación Se identificó que la funcionalidad de Listas Blancas no está operando correctamente desde el navegador debido al score del CAPTCHA. Como propuesta, se sugiere implementar una validación directa por cédula, eliminando la dependencia del CAPTCHA. | AS10: 24/06/2025: Jesus entrega el viernes 20 de junio ajuste de Listas blancas, el usuario activo en listas blancas se le debe omitir la solicitud del codigo de verificación. 24/06/2025: Se aplica ajuste, se confirma funcionalidad y se le notifica al cliente para su validación. | BE10: 15/07/2025: El cliente confirma la aprobación para el paso a producción; sin embargo, la ejecución queda pendiente de definir la fecha, ya que se requiere realizar previamente la divulgación al equipo de trabajo, y por parte de Imagine se debe solicitar control de cambios en produccion.
A11: JESUS | B11: GD772-116 | C11: Requerimiento gestión Medicamentos fase 2 - Sprint 2 | F11: FINALIZADO | G11: 100 | H11: =IF(OR(J11="",K11="",K11<J11),0,NETWORKDAYS(J11,K11,fESTIVOS!$A$2:$A$53)) -> 11 | I11: 45814 | J11: 45826 | K11: 45842 | L11: 45849 | M11: =IF(OR(J11="",AND(L11="",TODAY()<J11),AND(L11<>"",L11<J11)),0, IF(L11="", NETWORKDAYS(J11,TODAY(),fESTIVOS!$A$2:$A$53), NETWORKDAYS(J11,L11,fESTIVOS!$A$2:$A$53) ) ) -> 16 | O11: 45849 | P11: 45924 | Q11: 09/06/2025: Estimación inicial de desarrollo 9 dias 16/06/2025: Se acordó iniciar el desarrollo el 18 de junio, una vez se finalicen tareas pendientes de giras 20/06/2025:El 19 de junio finalizó el punto 2,continuara con el punto 3. 25/06/2025:El desarrollo avanza en el punto 4 de la fase 2 (creación de tipología y actividades). Se ha completado aproximadamente el 40% del requerimiento 27/06/2025: 27/06/2025: Se reporta un avance del 60%. 02/07/2025:Se avanza en un 75% del desarrollo de la Fase 2 de Medicamentos. Ya se encuentra funcional la creación individual de casos con su trazabilidad completa cuando un proveedor indica no entrega. Se han realizado pruebas exitosas en flujo y visualización. Actualmente se trabaja en la gestión masiva desde Excel para validar múltiples casos simultáneamente y asegurar la correcta apertura e identificación de cada uno. Pendiente finalizar el manejo masivo y ajustes en bandejas administrativas. 04/07/2025: El desarrollo alcanza un 85% de avance. Ya se construyó la generación de carta para proveedor nuevo. Queda pendiente recibir el modelo de carta de cancelación y completar dos botones adicionales. La validación masiva vía Excel fue pospuesta para el final 07/07/2025: Avance parcial durante el viernes 4 de julio en una nueva funcionalidad vinculada a botones de acción. Se priorizó el análisis de flujos con doble actividad y se atenderá el requerimiento de medicamentos durante la jornada de hoy, se estima entrega de desarrollo 8 de julio. 09/07/2025: El desarrollo se encuentra en su fase final, aunque ha experimentado algunos retrasos debido a revisiones relacionadas con otros temas. Actualmente, hay una duda funcional pendiente sobre el comportamiento del botón “Copiar y Reabrir Caso”, la cual está en revisión.Se solicitará el respectivo control de cambios para realizar las pruebas en el ambiente de test. 09/07/2025: Se escala control de cambios en test bajo el jira MDSB-844308. 10/07/2025: Control de cambios MDSB-844308 ejecutado con éxito. 11/07/2025: : El desarrollo fue completado y subido a TES. Se agregó retroalimentación para la carga masiva de Excel. Está pendiente desarrollar la pestaña de trazabilidad y adjuntos, que fue solicitada en reunión con el cliente. Las plantillas de correo fueron entregadas y se está integrando para las pruebas. 16/07/2025: Avanza la estabilización con enfoque en mejoras de experiencia de usuario. Faltan validaciones en gestión y pequeñas correcciones funcionales. Plantillas ya están disponibles. 18/07/2025: Se completó el flujo y ajustes hallados en las pruebas de medicamentos. 23/07/2025: Se realizaron los ajustes solicitados, los cuales incluyen la separación de vistas en pestañas para mejorar la organización de la información, así como la inclusión de botones para la gestión de casos relacionados. 30/07/2025: El día 28 de julio se realizó la entrega del desarrollo al cliente, quien iniciará el proceso de pruebas. 14/08/2025: El cliente ha dado su visto bueno para realizar el paso a producción del requerimiento. 15/08/2025: Se solicita al cliente proporcionar un listado similar al que habitualmente cargan los proveedores, preferiblemente con un volumen considerable, con el fin de realizar pruebas de carga en el aplicativo. 20/08/2025: Cliente envia Archivo solicitado. 25/08/2025: Se identificó riesgo de saturación del sistema si se procesa en línea. Se propuso implementar un proceso en segundo plano con validaciones y notificación por correo al finalizar. 29/08/2025: Se finalizan ajustes y pruebas 15/09/2025: Se escala control de cambios MDSB-890762 para producción. 22/09/2025: Control de cambios ejecutado con exito en 20 de septiembre, código revisado y listo para desplegar en producción hoy a las 5 p.m. 24/09/2025: se corrigió la URL de despliegue, pasando de consulta salud a consulta ARL. El desarrollo quedó listo para pruebas en ambiente de test y posterior despliegue a producción. 25/09/2025: Se realizo despiegue a producción el 24 de septiembre y se encuentra en estabilización... 26/09/2025: En la estabilizacion se corrigió error en producción relacionado con variables y trazabilidad de actividades. Queda pendiente definir ejecución de colas sin duplicación entre servidores para proceso de encolado de cargue masivo en la consulta de autorizaciones. 29/09/2025: Se inicia incluision de nuevas columnas al informe de de tiempos | R11: TRUE | T11: MDSB-844308 | U11: MDSB-890762 | AM11: Estimación inicial de desarrollo 9 dias | AP11: Se acordó iniciar el desarrollo el 18 de junio, una vez se finalicen tareas pendientes de giras | AQ11: Inicia desarrollo | AR11: 20/06/2025:El 19 de junio finalizó el punto 2,continuara con el punto 3. | AS11: 25/06/2025:El desarrollo avanza en el punto 4 de la fase 2 (creación de tipología y actividades). Se ha completado aproximadamente el 40% del requerimiento | AU11: 27/06/2025: Se reporta un avance del 60% | AW11: 02/07/2025: Se avanza en un 75% del desarrollo de la Fase 2 de Medicamentos. Ya se encuentra funcional la creación individual de casos con su trazabilidad completa cuando un proveedor indica no entrega. Se han realizado pruebas exitosas en flujo y visualización. Actualmente se trabaja en la gestión masiva desde Excel para validar múltiples casos simultáneamente y asegurar la correcta apertura e identificación de cada uno. Pendiente finalizar el manejo masivo y ajustes en bandejas administrativas. | AX11: 04/07/2025: El desarrollo alcanza un 85% de avance. Ya se construyó la generación de carta para proveedor nuevo. Queda pendiente recibir el modelo de carta de cancelación y completar dos botones adicionales. La validación masiva vía Excel fue pospuesta para el final | AY11: 07/07/2025: Avance parcial durante el viernes 4 de julio en una nueva funcionalidad vinculada a botones de acción. Se priorizó el análisis de flujos con doble actividad y se atenderá el requerimiento de medicamentos durante la jornada, se estima entrega de desarrollo 8 de julio. | BA11: 09/07/2025: El desarrollo se encuentra en su fase final, aunque ha experimentado algunos retrasos debido a revisiones relacionadas con otros temas. Actualmente, hay una duda funcional pendiente sobre el comportamiento del botón “Copiar y Reabrir Caso”, la cual está en revisión. Se solicitará el respectivo control de cambios para realizar las pruebas en el ambiente de test. 09/07/2025: Se escala control de cambios en test bajo el jira MDSB-844308 | BB11: 10/07/2025: Control de cambios MDSB-844308 ajecutado con exito. | BC11: 10/07/2025:El desarrollo fue completado y subido a TES. Se agregó retroalimentación para la carga masiva de Excel. Está pendiente desarrollar la pestaña de trazabilidad y adjuntos, que fue solicitada en reunión con el cliente. Las plantillas de correo fueron entregadas y se está integrando para las pruebas. | BD11: 14/07/2025: El desarrollo fue montado en TES con todas las actividades, tipologías y configuración básica. Se encuentra en etapa de estabilización y pruebas conjuntas. | BF11: 16/07/2025: Avanza la estabilización con enfoque en mejoras de experiencia de usuario. Faltan validaciones en gestión y pequeñas correcciones funcionales. Plantillas ya están disponibles. | BH11: 18/07/2025: Se completo el flujo y ajustes hallados en las prubas de medicamentos. | BJ11: 23/07/2025: Se realizaron los ajustes solicitados, los cuales incluyen la separación de vistas en pestañas para mejorar la organización de la información, así como la inclusión de botones para la gestión de casos relacionados. | BM11: 30/07/2025:El día 28 de julio se realizó la entrega del desarrollo al cliente, quien iniciará el proceso de pruebas.
A12: JESUS | B12: MDSB-1045072 | C12: Extracción histórica de Casos existentes en Nativo de los años de 2001 a 2016 | D12: Se solicita por favor una base de datos con la relación de caso, fecha de radicación, tipologia y área; de los casos correspondientes a los años de 2001 a 2016, por favor entregar la información en excel un archivo por año (la información con todos los estados, anulados, cerrados, pendientes, todo) Ejemplo de estructura esperada: CASO , FECHA DE RADICACIÓN, ÁREA DE CIERRE, TIPOLOGIA DE CIERRE (1234566) , (1/01/2001), (Administrativo), (Novedades) Por favor me confirman si se requiere crear un Jira por cada año o si en este mismo se pueden realizar entrega parciales. | F12: FINALIZADO | G12: 100 | H12: =IF(OR(J12="",K12="",K12<J12),0,NETWORKDAYS(J12,K12,fESTIVOS!$A$2:$A$53)) -> 0 | I12: 46170 | J12: 46170 | L12: 46171 | M12: =IF(OR(J12="",AND(L12="",TODAY()<J12),AND(L12<>"",L12<J12)),0, IF(L12="", NETWORKDAYS(J12,TODAY(),fESTIVOS!$A$2:$A$53), NETWORKDAYS(J12,L12,fESTIVOS!$A$2:$A$53) ) ) -> 2 | Q12: 28/05/2026: Se identificó que antes de 2016 el sistema manejaba una estructura distinta sin flujos ni tipologías para lo cual se deben ubicar casos históricos de referencia e identificar tablas relacionadas.. 02/06/2026: Los informes correspondientes a este jira ya se encuentran disponibles y a la espera de la confirmación de Jenry para hacer la entrega al cliente. 10/06/2026: Se realiza entrega a cliente de la información solicitada | R12: True
A13: JESUS | B13: INTERNO-JE050 | C13: Análisis y control de eliminación de registros y soportes de incapacidades en Imagine | D13: Se requiere identificar el origen de la eliminación de registros asociados a incapacidades y sus documentos soporte en Imagine, debido a que se han presentado casos donde la información deja de estar disponible para consulta. El objetivo es determinar qué procesos o componentes están realizando dichas eliminaciones, fortalecer los mecanismos de trazabilidad y auditoría, e implementar controles que permitan conservar la información de soportes y conocer el origen de cualquier eliminación realizada sobre los registros. | F13: FINALIZADO | G13: 100 | H13: =IF(OR(J13="",K13="",K13<J13),0,NETWORKDAYS(J13,K13,fESTIVOS!$A$2:$A$53)) -> 0 | I13: 46171 | J13: 46171 | L13: 46175 | M13: =IF(OR(J13="",AND(L13="",TODAY()<J13),AND(L13<>"",L13<J13)),0, IF(L13="", NETWORKDAYS(J13,TODAY(),fESTIVOS!$A$2:$A$53), NETWORKDAYS(J13,L13,fESTIVOS!$A$2:$A$53) ) ) -> 3 | Q13: 29/05/2026: Se realizó la validación del caso 31149409, identificando que el registro de la incapacidad había sido eliminado y posteriormente fue restaurado 02/06/2026: Durante el análisis se evidenció que el documento PDF asociado no pudo ser recuperado, debido a que la trazabilidad actual únicamente conserva información de la tabla de incapacidades y no de la tabla de soportes. Como siguiente actividad, se iniciará un barrido y análisis de las aplicaciones relacionadas con el proceso de incapacidades para identificar el origen de las eliminaciones y determinar si existen más registros afectados por esta situación. 04/06/2026: El 2 de junio se identificó una falla en el flujo antiguo de incapacidades que permitía a los usuarios eliminar registros y adjuntos ya radicados al regresar a pasos anteriores del proceso. El análisis determinó que la causa estaba asociada a la navegación posterior a la radicación y no a errores adicionales del código. Debido a la migración del proceso hacia un nuevo flujo basado en OCR y API, el módulo afectado dejó de utilizarse. | R13: True
A14: JESUS | B14: MDSB-1045076 | C14: Consolidado Cantidad de Imagenes del 2001 la 2025 | D14: Se solicita un consolidado general con la siguiente información: Teniendo en cuenta desde el 2001 hasta el 2025 y todos los productos. | F14: EN PROCESO | G14: 40 | H14: =IF(OR(J14="",K14="",K14<J14),0,NETWORKDAYS(J14,K14,fESTIVOS!$A$2:$A$53)) -> 0 | I14: 46175 | J14: 46175 | M14: =IF(OR(J14="",AND(L14="",TODAY()<J14),AND(L14<>"",L14<J14)),0, IF(L14="", NETWORKDAYS(J14,TODAY(),fESTIVOS!$A$2:$A$53), NETWORKDAYS(J14,L14,fESTIVOS!$A$2:$A$53) ) ) -> 9 | N14: 46199 | Q14: 04/06/2026: Se desarrolló un script para verificar la existencia física de archivos históricos registrados en las diferentes tablas de almacenamiento documental de Nativo. El objetivo es validar aproximadamente 25 años de información almacenada. Durante las pruebas se evidenció que consultar simultáneamente los diferentes repositorios de almacenamiento generaba tiempos de respuesta muy altos, por lo que el proceso fue optimizado para ejecutarse por períodos y consultar inicialmente únicamente el almacenamiento histórico. El resultado se genera progresivamente en archivos CSV para evitar problemas de memoria. Se verificara si el proceso actualmente en ejecución finalizó correctamente, revisar los resultados generados y continuar con la validación masiva del histórico documental. 05/06/2026: Se ajusta lalogica para la descarga del informe para que permita relacionar el numero del caso, Se programan la generaciòn de reportes, desde el 2001 al 2025. 09/06/2026: Se desarrolló un proceso para generar un inventario histórico de imágenes asociadas a casos de los últimos 25 años. El proceso consulta aproximadamente 10 u 11 tablas documentales de Nativo y genera archivos consolidados. Tras ejecutarse masivamente durante el fin de semana, se detectó una posible afectación al rendimiento del servidor, motivo por el cual la tarea fue cancelada y los resultados eliminados. Se espera realizar una reevaluaciòn de como ejecutar el proceso de extraccón para no afcectar el redimiento del servidor. 11/06/2026: Se estima entrega al cliente el 26 de junio | R14: True
A15: JESUS | B15: INTERNO-JE051 | C15: Optimización y monitoreo de colas Default PM2 | D15: Se reportó una acumulación cercana a 700 procesos pendientes en la cola principal del sistema, afectando funcionalidades críticas como el envío de correos, replicación de casos y otros procesos automáticos. La situación fue mitigada mediante el reinicio de los servicios, restableciendo el procesamiento normal. Se requiere implementar un mecanismo de monitoreo y notificación automática que alerte al equipo de soporte y desarrollo cuando la cantidad de elementos en cola supere los umbrales definidos, permitiendo actuar de manera preventiva antes de que el cliente perciba la afectación o reporte la incidencia. | F15: EN PROCESO | G15: 30 | H15: =IF(OR(J15="",K15="",K15<J15),0,NETWORKDAYS(J15,K15,fESTIVOS!$A$2:$A$53)) -> 0 | I15: 46184 | J15: 46185 | M15: =IF(OR(J15="",AND(L15="",TODAY()<J15),AND(L15<>"",L15<J15)),0, IF(L15="", NETWORKDAYS(J15,TODAY(),fESTIVOS!$A$2:$A$53), NETWORKDAYS(J15,L15,fESTIVOS!$A$2:$A$53) ) ) -> 2 | Q15: 16/06/2026: El 12 de Junio se realizó una investigación técnica sobre los problemas presentados en la cola Default. Durante el análisis se identificó que existen configuraciones nativas del Ecosystem de PM2 que permiten ejecutar múltiples procesos para una misma cola, configurar redundancia ante fallos y mejorar la resiliencia del procesamiento sin necesidad de realizar desarrollos adicionales. El objetivo es evitar bloqueos que afecten el envío de correos y otros procesos críticos. Hoy se continura con la implementarción y pruebas de configuraciones avanzadas de PM2, validar el comportamiento bajo carga, definir mecanismos de recuperación automática y complementar el monitoreo para detectar oportunamente problemas en las colas de procesamiento. | R15: True
A16: JESUS | B16: INTERNO-JE069 | C16: Validación de usuario 1065580157 no visible en tablero de efectividad de cuidado al trabajador /Drummond | D16: El cliente reporta un caso donde el usuario 1065580157 no aparece reflejado en un tablero de efectividad de cuidado al trabajador /Drummond. Se verificaron controles básicos, estados de nómina y configuraciones visibles, sin encontrar inconsistencias evidentes. | F16: FINALIZADO | G16: 100 | H16: =IF(OR(J16="",K16="",K16<J16),0,NETWORKDAYS(J16,K16,fESTIVOS!$A$2:$A$53)) -> 0 | I16: 46185 | J16: 46189 | L16: 46189 | M16: =IF(OR(J16="",AND(L16="",TODAY()<J16),AND(L16<>"",L16<J16)),0, IF(L16="", NETWORKDAYS(J16,TODAY(),fESTIVOS!$A$2:$A$53), NETWORKDAYS(J16,L16,fESTIVOS!$A$2:$A$53) ) ) -> 1 | Q16: 16/06/2026: Se identifico faltaba insertar la cedula en la tabla wf_efec_funcionarios | R16: True
