Workbook

Sheet EN PROCESO (Colpatria)
A1: Asignado a | B1: ID REQ | C1: Requerimiento | D1: Descripcion req | E1: Actividad | F1: ESTADO | G1: % AVANCE | H1: Dias estimados de desarrollo | I1: F.Asignado | J1: Fecha inicio | K1: F. estimada de entrega | L1: Fecha Finalizado | M1: Dias total desarrollo | N1: Fecha compromiso cliente | O1: FECHA PASO A TEST | P1: FECHA PASO A PRODUCCION | Q1: DESCRIPCION DEL AVANCE | R1: visible
A2: Faver Lopez | B2: COLP25-0001 | C2: Clasificacion de Documentos | D2: Se requiere crear un clasificador de documentos para el proceso de afiliaciones | F2: PAUSADO | G2: 30 | H2: =IF(OR(J2="",K2="",K2<J2),0,NETWORKDAYS(J2,K2,Hoja2!$A$2:$A$53)) -> 17 | I2: 45931 | J2: 45931 | K2: 45954 | M2: =IF(OR(J2="",AND(L2="",TODAY()<J2),AND(L2<>"",L2<J2)),0, IF(L2="", NETWORKDAYS(J2,TODAY(),Hoja2!$A$2:$A$53), NETWORKDAYS(J2,L2,Hoja2!$A$2:$A$53) ) ) -> 175 | Q2: Se tiene ya construida la base del entranamiento 15/10/2025: Se Pausa este requerimiento mientras se avanza en otras automatizaciones del proceso de afiliaciones | R2: True
A3: Faver Lopez | B3: COLP25-0002 | C3: Mejoras Modulo Gestor Lote | D3: Se solicita hacer ajustes en el modulo de gestor lotes tramites: - Ajustar resolución de Imagenes - Ajustar el proceso diario de preparación de archivos - Ajustar visualización de imagenes posterior a generar lotes - Ajustar para que se mantengan los filtros del gestor lote - Permitir carga de otros tipos de archivos (xlsx, correos, word) - Los excel NR, no salen completos, ajustar el pantallazo al tamaño de la tabla | F3: FINALIZADO | G3: 100 | H3: =IF(OR(J3="",K3="",K3<J3),0,NETWORKDAYS(J3,K3,Hoja2!$A$2:$A$53)) -> 12 | J3: 45931 | K3: 45947 | L3: 45945 | M3: =IF(OR(J3="",AND(L3="",TODAY()<J3),AND(L3<>"",L3<J3)),0, IF(L3="", NETWORKDAYS(J3,TODAY(),Hoja2!$A$2:$A$53), NETWORKDAYS(J3,L3,Hoja2!$A$2:$A$53) ) ) -> 10 | Q3: 12/09/2025: Se ajusta la resolucion de imagenes 19/09/2025: Se ajusta el proceso automatico de preparación de tramites para loteo. 19/09/2025: Ajusta la visualización de imagenes luego de generar el lote 19/09/2025: Agrega nuevos tipos de archivos permitidos para el cargue 15/10/2025: Se ajusta que al tomar el screenshot este quede ajustado al tamaño de la tabla | R3: True
A4: Faver Lopez | B4: COLP25-0003 | C4: Automatizar Informe Usuarios Imagine | D4: El informe de usuarios de Imagine se envia de forma mensual, en los primeros 5 dias del mes, este proceso realiza de forma manual y se requiere habilitar un proceso automatico para que lo envie | F4: PASO A PRODUCCION | G4: 80 | H4: =IF(OR(J4="",K4="",K4<J4),0,NETWORKDAYS(J4,K4,Hoja2!$A$2:$A$53)) -> 20 | J4: 45901 | K4: 45926 | M4: =IF(OR(J4="",AND(L4="",TODAY()<J4),AND(L4<>"",L4<J4)),0, IF(L4="", NETWORKDAYS(J4,TODAY(),Hoja2!$A$2:$A$53), NETWORKDAYS(J4,L4,Hoja2!$A$2:$A$53) ) ) -> 197 | Q4: 03/10/2025: Se revisa el proceso de la generación del informe con John 03/10/2025: Se realizaron ajustes en el reporte, se corregen inconsistencias que se ajustan de forma manual actualmente | R4: True
A5: Faver Lopez | B5: COLP25-0004 | C5: Proceso Archivo Nomina Pendiente | D5: Se requiere una opcion que permite agilizar el proceso de alistamiento del archivo de nomina, ya que es algo que quita mucho tiempo por cada archivo | F5: FINALIZADO | G5: 100 | H5: =IF(OR(J5="",K5="",K5<J5),0,NETWORKDAYS(J5,K5,Hoja2!$A$2:$A$53)) -> 8 | J5: 45931 | K5: 45940 | L5: 45954 | M5: =IF(OR(J5="",AND(L5="",TODAY()<J5),AND(L5<>"",L5<J5)),0, IF(L5="", NETWORKDAYS(J5,TODAY(),Hoja2!$A$2:$A$53), NETWORKDAYS(J5,L5,Hoja2!$A$2:$A$53) ) ) -> 17 | O5: 45909 | P5: 45919 | Q5: 22/08/2025: Se crea la estructura y la lectura del archivo, se mapean algunos campos del excel 09/09/2025: Se trabajo en las validacions de devolución y en las transformaciones de las columnas 09/09/2025: Se pasara al ambiente de QA los cambios iniciales 19/09/2025: Se tiene mapeado un 95% de los valores y las reglas a aplicar 03/10/2025: Se completo el mapeo de las columnas del arhcivo de nomina y sus reglas. 03/10/2025: Se han agregado mejoras y procesamiento de diferentes columnas 31/10/2025: Se realizan ajuste en columnas y se modifica el encabezado para que cargue sin errores 07/11/2025: Se da finalizado el proceso y se manejaran como mejoras separadas los cambios que se realicen. | R5: True
A6: Faver Lopez | B6: COLP25-0005 | C6: Automatizaciones Imagine - Desarrollar Modulo Transformación de Archivo Masivo Voluntarios | D6: Este desarrollo es para reducir la manuallidad de procesar archivos de excel de forma manual, este permitir realizar las trasnformaciones de los valores de las columnas y validar la información | F6: FINALIZADO | G6: 100 | H6: =IF(OR(J6="",K6="",K6<J6),0,NETWORKDAYS(J6,K6,Hoja2!$A$2:$A$53)) -> 5 | J6: 45870 | K6: 45877 | L6: 45954 | M6: =IF(OR(J6="",AND(L6="",TODAY()<J6),AND(L6<>"",L6<J6)),0, IF(L6="", NETWORKDAYS(J6,TODAY(),Hoja2!$A$2:$A$53), NETWORKDAYS(J6,L6,Hoja2!$A$2:$A$53) ) ) -> 58 | O6: 45891 | P6: 45954 | Q6: 22/08/2025: Se han agregado mejoras y optimizaciones al proceso de transformación del archivo masivo 12/09/2025: Actualmente este modulo esta en ambiente QA, y se usa para el proceso de transformación de las afiliaciones de voluntarios (por oficio), pero en las ultimas 2 cargues se han estado trabajando como afiliaciones independientes asociados a una afiliacion de Axa para su cargue. 12/09/2025: Se debe definir si va a contiuar asi, ya que entonces se entregaria el archivo en la estructura esperada para su cargue a Access 12/09/2025: Actualmente este modulo esta en ambiente QA, y se usa para el proceso de transformación de las afiliaciones de voluntarios (por oficio), pero en las ultimas 2 cargues se han estado trabajando como afiliaciones independientes asociados a una afiliacion de Axa para su cargue, se ha definido si va a contiuar asi, ya que entonces se entregaria el archivo ya en la estructura esperada para su cargue a Access 24/10/2025: Se deja en producción funcional, se tienen mejoras que realizar pero se tomaran por separado cada mejora | R6: True
A7: Faver Lopez | B7: COLP25-0006 | C7: Creación Modulo de Administración | D7: Se requiere la creación de un modulo de administración para el manejo de usuarios, roles y permisos | F7: FINALIZADO | G7: 100 | H7: =IF(OR(J7="",K7="",K7<J7),0,NETWORKDAYS(J7,K7,Hoja2!$A$2:$A$53)) -> 19 | J7: 45870 | K7: 45898 | L7: 45954 | M7: =IF(OR(J7="",AND(L7="",TODAY()<J7),AND(L7<>"",L7<J7)),0, IF(L7="", NETWORKDAYS(J7,TODAY(),Hoja2!$A$2:$A$53), NETWORKDAYS(J7,L7,Hoja2!$A$2:$A$53) ) ) -> 58 | O7: 45873 | P7: 45957 | Q7: 22/07/2025: Va en 90% faltan detalles de filtros y temas de busquedas, perfiles. 04/08/2025: Pendientes por pruebas 15/08/2025: Se realizaron ajustes a las paginaciones, ya se pueden asignar los roles a los usuarios. 15/08/2025: Falta agregar filtros para buscar usuarios y quedar listo la funcionalidad 19/09/2025: Se realizaron ajustes en el manejo de permisos del frontend y se agrega opcion en el modulo de adminsitración par ala signación de los permisos 03/10/2025: Se mejora la administracion de usuarios, se agregan filtros para la busqueda de usuarios 03/10/2025: Se esta realizando un ajuste en la administración de los permisos y roles 24/10/2025: Se agrego la funcionalidad para modificar los datos de los usuarios | R7: True
A8: Faver Lopez | B8: COLP25-0007 | C8: Migrar el motor de base de datos de postgresql de 9,6 a la versión 17,5 | D8: Se solicita antes de migrar el sistema operativo del servidor de base de datos de producción, realizar la migración versión superior o igual a postgreSql 12 , esto con el fin de atender una alerta de vulneSrabilidad | F8: FINALIZADO | G8: 100 | H8: =IF(OR(J8="",K8="",K8<J8),0,NETWORKDAYS(J8,K8,Hoja2!$A$2:$A$53)) -> 72 | J8: 45870 | K8: 45975 | L8: 46001 | M8: =IF(OR(J8="",AND(L8="",TODAY()<J8),AND(L8<>"",L8<J8)),0, IF(L8="", NETWORKDAYS(J8,TODAY(),Hoja2!$A$2:$A$53), NETWORKDAYS(J8,L8,Hoja2!$A$2:$A$53) ) ) -> 88 | P8: 46001 | Q8: 15/07/2025: En sesion con Natalia , Ana para pruebas ambiente QA que se programo el dia 18 de julio a las 10:00 de la mañana. 15/07/2025: Se envidencia algunos ajuste para realizar por parte de Faver se agenda sesion nuevamente para el dia lunes 21 de julio en horas de la tarde 22/07/2025: Esta programada para el 25 de julio el proceso de migración. Se envío correo para solicitar instalación de odbc para la nueva versión. 22/07/2025: Nota - Se cambio para el lunes 28 de julio 22/07/2025: Nota - Se define y autoriza por operaciones para el 4 de agosto para no afectar operaciones en cierre de mes 08/08/2025: Ya se instalo la version de postgres 17.5, se hizo el upgrade. 08/08/2025: Fallo al restaurar bases de datos debido a una funcion no soportada y el plan para evitar cambiar todas las tablas no funciono como se esperaba. 08/08/2025: Pendiente de reprogramar el proceso de restaurar la base de datos en el nuevo motor. 14/10/2025: Se envio plan actaulizado para el proceso de migración de la base de datos. 07/11/2025: Se recibe aprobación del cliente (Operaciones) para que se realice a mitad de mes, queda pendiente de programar con el area de seguridad y DBA. 28/11/2025: Se espera programar para el 5 de diciembre el paso a producción 04/12/2025: Se reprograma para el 9 de Diciembre el paso a producción 10/12/2025: Se realiza migración de la base de datos a la version solicitada de forma correcta. | R8: True
A9: Faver Lopez | B9: COLP25-0008 | C9: Excluir Personas del Correo: TRASLADOS CON PRIMERA NOMINA PENDIENTE POR CARGAR | D9: Se recibe correo solicitando excluir algunos correos del las notificación que se envia sobre tramites con traslados con primera nomina pendiente por cargar. | F9: PENDIENTE CLIENTE | G9: 50 | H9: =IF(OR(J9="",K9="",K9<J9),0,NETWORKDAYS(J9,K9,Hoja2!$A$2:$A$53)) -> 63 | I9: 45870 | J9: 45870 | K9: 45961 | M9: =IF(OR(J9="",AND(L9="",TODAY()<J9),AND(L9<>"",L9<J9)),0, IF(L9="", NETWORKDAYS(J9,TODAY(),Hoja2!$A$2:$A$53), NETWORKDAYS(J9,L9,Hoja2!$A$2:$A$53) ) ) -> 216 | Q9: 03/10/2025: No se ha realizado debido a restricciones de acceso al mabiente de desarrollo de Imagine 04/10/2025: Se realiza revisión del proceso, se quito el envio a algunos usuarios pero se requiere validar como se aplicara esta regla con Axa, ya que es una regla de negocio y debe la aprobación y definición del cambio. | R9: True
A10: Faver Lopez | B10: COLP25-0009 | C10: Notificaciones Radicador Masivos | D10: Se requiere notificar los cambios de estado de los radicados masivos | F10: FINALIZADO | G10: 100 | H10: =IF(OR(J10="",K10="",K10<J10),0,NETWORKDAYS(J10,K10,Hoja2!$A$2:$A$53)) -> 14 | J10: 45936 | K10: 45954 | L10: 45954 | M10: =IF(OR(J10="",AND(L10="",TODAY()<J10),AND(L10<>"",L10<J10)),0, IF(L10="", NETWORKDAYS(J10,TODAY(),Hoja2!$A$2:$A$53), NETWORKDAYS(J10,L10,Hoja2!$A$2:$A$53) ) ) -> 14 | Q10: 24/10/2025: Se agrega notificaciones para las diferentes acciones del radicador de masivos | R10: True
A11: Faver Lopez | B11: COLP25-0010 | C11: Mejoras Radicados Masivos | D11: Se requiere que al momento de realizar una accción sobre un radicado masivo se pida una confirmación por parte del usuario para evitar errores al dar gestion | F11: FINALIZADO | G11: 100 | H11: =IF(OR(J11="",K11="",K11<J11),0,NETWORKDAYS(J11,K11,Hoja2!$A$2:$A$53)) -> 14 | J11: 45936 | K11: 45954 | L11: 45954 | M11: =IF(OR(J11="",AND(L11="",TODAY()<J11),AND(L11<>"",L11<J11)),0, IF(L11="", NETWORKDAYS(J11,TODAY(),Hoja2!$A$2:$A$53), NETWORKDAYS(J11,L11,Hoja2!$A$2:$A$53) ) ) -> 14 | Q11: 24/10/2025: Se agrega confirmaciones para los cambios de estado de los radicados | R11: True
A12: Faver Lopez | B12: COLP25-0011 | C12: Inactivar los procesos del gestor de lotes (php) | D12: Se requiere inactivar funcionalidades del gestor de lotes del aplicativo de Imaginex ya que estas se estan trabaajndo en el nuevo aplicatvio, esto con el fin de evitar duplicar procesos | F12: FINALIZADO | G12: 100 | H12: =IF(OR(J12="",K12="",K12<J12),0,NETWORKDAYS(J12,K12,Hoja2!$A$2:$A$53)) -> 4 | J12: 45951 | K12: 45954 | L12: 45954 | M12: =IF(OR(J12="",AND(L12="",TODAY()<J12),AND(L12<>"",L12<J12)),0, IF(L12="", NETWORKDAYS(J12,TODAY(),Hoja2!$A$2:$A$53), NETWORKDAYS(J12,L12,Hoja2!$A$2:$A$53) ) ) -> 4 | Q12: 24/10/2025: Se inactivan las opciones del gestor antiguo para que no sean usadas y evitar conflicto en el proceso de loteo | R12: True
A13: Faver Lopez | B13: COLP25-0012 | C13: Optimizacion de Consulta Tramites | D13: Se requiere optimizar una consulta para el proceso de calidad de entrega de los planos adicionales, esta consulta actulmente se trada unos 15 seg en mostrar resutlados, afectando el rendiemiento de la aplicación y generando demoras en el proceso de generación de planos adicionales | F13: FINALIZADO | G13: 100 | H13: =IF(OR(J13="",K13="",K13<J13),0,NETWORKDAYS(J13,K13,Hoja2!$A$2:$A$53)) -> 5 | J13: 45950 | K13: 45954 | L13: 45954 | M13: =IF(OR(J13="",AND(L13="",TODAY()<J13),AND(L13<>"",L13<J13)),0, IF(L13="", NETWORKDAYS(J13,TODAY(),Hoja2!$A$2:$A$53), NETWORKDAYS(J13,L13,Hoja2!$A$2:$A$53) ) ) -> 5 | Q13: 24/10/2025: Se optimiza la consulta paa los procesos de calidad en la generacion de planos adicionales | R13: True
A14: Faver Lopez | B14: COLP25-0013 | C14: Agregar Tipologia FX al Gestor de Lotes | D14: Se requiere agregar la tipologia FX para la familia de novedades en el gestor de lotes | F14: FINALIZADO | G14: 100 | H14: =IF(OR(J14="",K14="",K14<J14),0,NETWORKDAYS(J14,K14,Hoja2!$A$2:$A$53)) -> 3 | J14: 45952 | K14: 45954 | L14: 45954 | M14: =IF(OR(J14="",AND(L14="",TODAY()<J14),AND(L14<>"",L14<J14)),0, IF(L14="", NETWORKDAYS(J14,TODAY(),Hoja2!$A$2:$A$53), NETWORKDAYS(J14,L14,Hoja2!$A$2:$A$53) ) ) -> 3 | Q14: 24/10/2025: Se agrego tipologia FX a la familia de novedades en el gestor de lotes | R14: True
A15: Faver Lopez | B15: COLP25-0014 | C15: Ajustes Proceso Nomina Dependientes | D15: Se requieren los situientes ajustes en la nomina de dependientes: - Limpieza de tildes en los campos (centro trabajo, ciudad) - duplicar la columan ciudad y numero de contacto | F15: FINALIZADO | G15: 100 | H15: =IF(OR(J15="",K15="",K15<J15),0,NETWORKDAYS(J15,K15,Hoja2!$A$2:$A$53)) -> 5 | J15: 45950 | K15: 45954 | L15: 45954 | M15: =IF(OR(J15="",AND(L15="",TODAY()<J15),AND(L15<>"",L15<J15)),0, IF(L15="", NETWORKDAYS(J15,TODAY(),Hoja2!$A$2:$A$53), NETWORKDAYS(J15,L15,Hoja2!$A$2:$A$53) ) ) -> 5 | Q15: 24/10/2025: Se realizan los ajustes en el plano de nominas dependientes | R15: True
A16: Faver Lopez | B16: COLP25-0015 | C16: Depuracion de almacenamiento del servidor productivo | D16: Se presenta alertamiento por espacio en el almacenamiento del servidor productivo, se requiere hacer un proceso de depuración de información para liberar espacio | F16: FINALIZADO | G16: 100 | H16: =IF(OR(J16="",K16="",K16<J16),0,NETWORKDAYS(J16,K16,Hoja2!$A$2:$A$53)) -> 1 | J16: 45954 | K16: 45954 | L16: 45954 | M16: =IF(OR(J16="",AND(L16="",TODAY()<J16),AND(L16<>"",L16<J16)),0, IF(L16="", NETWORKDAYS(J16,TODAY(),Hoja2!$A$2:$A$53), NETWORKDAYS(J16,L16,Hoja2!$A$2:$A$53) ) ) -> 1 | O16: 45954 | P16: 45954 | Q16: 24/10/2025: Se realiza el proceso de depuración con el are operativa de inforamción en el volumen de almacenamiento y se corrige el alertamiento | R16: True
A17: Faver Lopez | B17: COLP25-0016 | C17: Mejorar Plan Migración Base de Datos | D17: Se requiere revisar el plan que se tiene para el proceso de migración de la base de datos de produción de postgres 9,6 a 17,5 | F17: FINALIZADO | G17: 100 | H17: =IF(OR(J17="",K17="",K17<J17),0,NETWORKDAYS(J17,K17,Hoja2!$A$2:$A$53)) -> 5 | J17: 45957 | K17: 45961 | L17: 45961 | M17: =IF(OR(J17="",AND(L17="",TODAY()<J17),AND(L17<>"",L17<J17)),0, IF(L17="", NETWORKDAYS(J17,TODAY(),Hoja2!$A$2:$A$53), NETWORKDAYS(J17,L17,Hoja2!$A$2:$A$53) ) ) -> 5 | O17: 45961 | P17: 45964 | Q17: 31/10/2025: Se revisa el plan de trabajo y se establecen mejoras para realizar el proceso mas rapido, ejecutando backups y restauración aprovechando el multiproceso | R17: True
A18: Faver Lopez | B18: COLP25-0017 | C18: Depuración de aplicativo Imagine (PHP) | D18: Se requiere realizar depuración del aplicativo de Imaginex, esto se requiere ya que se esta realizando el proceso de extracción del aplicativo a Github, actualmente el aplicativo contiene carpetas que no son necesarias para los procesos de desaroollo actuales | F18: PAUSADO | G18: 85 | H18: =IF(OR(J18="",K18="",K18<J18),0,NETWORKDAYS(J18,K18,Hoja2!$A$2:$A$53)) -> 5 | J18: 45957 | K18: 45961 | M18: =IF(OR(J18="",AND(L18="",TODAY()<J18),AND(L18<>"",L18<J18)),0, IF(L18="", NETWORKDAYS(J18,TODAY(),Hoja2!$A$2:$A$53), NETWORKDAYS(J18,L18,Hoja2!$A$2:$A$53) ) ) -> 158 | Q18: 31/10/2025: Se esta realizando el proceso de depuracion de la carpetas del repositorio del aplicativo Imaginex, se generaron backup de codigo que no se usa actualmente. 07/11/2025: Se realiza depuración del codigo se eliminan carpetas no requeridas (se generaron backups) queda listo para subir al repositorio. 15/12/2025: Se ha estado trabajando en la revisión y codigo para su cargue en el repositorio de Imagine. 18/12/2025: Se agregan librerias necesarias para ajuste en visor de tiff 02/03/2026: Estos ajustes se pondran en pausa debido a que se estan migrando funcionalidades al nuevo aplicativo, por lo cual la revisión y depuración del aplicativo no se ha podido avanzar, no es posible terminarlo y enviar todo al repositorio debido a información que puede ser sensible por cual se requiere la revision manual del codigo antes de realizar cargue en repositorios. | R18: True
A19: Faver Lopez | B19: COLP25-0018 | C19: Restringir Funcionalidades Gestor Lotes en Tramites Loteados | D19: Se requiere agregar una restringir para eliminacion y reordenar los archivos e imagenes luego de generar lote | F19: FINALIZADO | G19: 100 | H19: =IF(OR(J19="",K19="",K19<J19),0,NETWORKDAYS(J19,K19,Hoja2!$A$2:$A$53)) -> 5 | J19: 45957 | K19: 45961 | L19: 45961 | M19: =IF(OR(J19="",AND(L19="",TODAY()<J19),AND(L19<>"",L19<J19)),0, IF(L19="", NETWORKDAYS(J19,TODAY(),Hoja2!$A$2:$A$53), NETWORKDAYS(J19,L19,Hoja2!$A$2:$A$53) ) ) -> 5 | O19: 45961 | P19: 45964 | Q19: 31/10/2025: Se agregan validaciones para restringir acciones sobre los archivos e imagenes de tramites loteados en el gestor de lotes | R19: True
A20: Faver Lopez | B20: COLP25-0019 | C20: Mejoras Gestor Lotes - Manejo estado Radicados | D20: Se requiere agregar una validación para revisar si un tramite esta en estado (anulado, cancelado o eliminado), al gestionar | F20: FINALIZADO | G20: 100 | H20: =IF(OR(J20="",K20="",K20<J20),0,NETWORKDAYS(J20,K20,Hoja2!$A$2:$A$53)) -> 5 | J20: 45957 | K20: 45961 | L20: 45961 | M20: =IF(OR(J20="",AND(L20="",TODAY()<J20),AND(L20<>"",L20<J20)),0, IF(L20="", NETWORKDAYS(J20,TODAY(),Hoja2!$A$2:$A$53), NETWORKDAYS(J20,L20,Hoja2!$A$2:$A$53) ) ) -> 5 | O20: 45961 | P20: 45964 | Q20: 31/10/2025: Se agrega un resoltado de las filas de tramites que tienen estan en estado no gestionable (anulado, cancelado o eliminar) | R20: True
A21: Faver Lopez | B21: COLP25-0020 | C21: Mejora Proceso Login Usuarios | D21: Se requiere contar los ingresos y actualizar fecha ultimo ingreso | F21: FINALIZADO | G21: 100 | H21: =IF(OR(J21="",K21="",K21<J21),0,NETWORKDAYS(J21,K21,Hoja2!$A$2:$A$53)) -> 5 | J21: 45957 | K21: 45961 | L21: 45961 | M21: =IF(OR(J21="",AND(L21="",TODAY()<J21),AND(L21<>"",L21<J21)),0, IF(L21="", NETWORKDAYS(J21,TODAY(),Hoja2!$A$2:$A$53), NETWORKDAYS(J21,L21,Hoja2!$A$2:$A$53) ) ) -> 5 | O21: 45961 | P21: 45964 | Q21: 31/10/2025: Se ajusta el flujo de autenticacion para actualizar la fecha de ultimo ingreso y la cantidad de ingresos | R21: True
A22: Faver Lopez | B22: COLP25-0021 | C22: Registrar datos del usuario con el primer login | D22: Se requiere que el nuevo aplicativo registre en base de datos, los usuarios que son nuevos y cargue los datos que son retornados por el DA | F22: FINALIZADO | G22: 100 | H22: =IF(OR(J22="",K22="",K22<J22),0,NETWORKDAYS(J22,K22,Hoja2!$A$2:$A$53)) -> 5 | J22: 45957 | K22: 45961 | L22: 45961 | M22: =IF(OR(J22="",AND(L22="",TODAY()<J22),AND(L22<>"",L22<J22)),0, IF(L22="", NETWORKDAYS(J22,TODAY(),Hoja2!$A$2:$A$53), NETWORKDAYS(J22,L22,Hoja2!$A$2:$A$53) ) ) -> 5 | O22: 45961 | P22: 45964 | Q22: 31/10/2025: Se modifica el flujo de autenticacion para guardar o actualizar los datos del usuario. | R22: True
A23: Faver Lopez | B23: COLP25-0022 | C23: Mejoras El Filtrado del Gestor Lote | D23: Se requiere al ingresar a un tramite y regresar al grid de tramites se mantengan los filtros de busqueda | F23: PAUSADO | G23: 50 | H23: =IF(OR(J23="",K23="",K23<J23),0,NETWORKDAYS(J23,K23,Hoja2!$A$2:$A$53)) -> 23 | I23: 45957 | J23: 45957 | K23: 45989 | M23: =IF(OR(J23="",AND(L23="",TODAY()<J23),AND(L23<>"",L23<J23)),0, IF(L23="", NETWORKDAYS(J23,TODAY(),Hoja2!$A$2:$A$53), NETWORKDAYS(J23,L23,Hoja2!$A$2:$A$53) ) ) -> 158 | Q23: 02/03/2026: Se ha trabajado en mejoras del grid de gestor de lotes, se han realizado ajustes e acuerdo a las necesidades que se han venido presentando por el área de operaciones, aun falta una implementación para mantener filtros entre navegaciones. Actualmente no se ha avanzado en esta tarea ya que se esta dando gestión a otras funcionalidades del gestor. | R23: True
A24: Faver Lopez | B24: COLP25-0023 | C24: Hardening Servidro Producción | D24: Se viene adelantando un proceso de hardeninzación por parte de seguridad de la información | F24: FINALIZADO | G24: 100 | H24: =IF(OR(J24="",K24="",K24<J24),0,NETWORKDAYS(J24,K24,Hoja2!$A$2:$A$53)) -> 2 | J24: 45966 | K24: 45967 | L24: 45967 | M24: =IF(OR(J24="",AND(L24="",TODAY()<J24),AND(L24<>"",L24<J24)),0, IF(L24="", NETWORKDAYS(J24,TODAY(),Hoja2!$A$2:$A$53), NETWORKDAYS(J24,L24,Hoja2!$A$2:$A$53) ) ) -> 2 | P24: 45966 | Q24: 06/11/2025: Se realiza el acompañamiento al equipo de Axa en el proceso de hardenización del servidor de producción. | R24: True
A25: Faver Lopez | B25: COLP25-0024 | C25: Ajuste sincronizacion datos usuarios | D25: Se requiere realizar ajustes en el proceso de sincronización de datos de los usuarios que entrega el servicio de SOAP del DA | F25: FINALIZADO | G25: 100 | H25: =IF(OR(J25="",K25="",K25<J25),0,NETWORKDAYS(J25,K25,Hoja2!$A$2:$A$53)) -> 2 | J25: 45965 | K25: 45966 | L25: 45966 | M25: =IF(OR(J25="",AND(L25="",TODAY()<J25),AND(L25<>"",L25<J25)),0, IF(L25="", NETWORKDAYS(J25,TODAY(),Hoja2!$A$2:$A$53), NETWORKDAYS(J25,L25,Hoja2!$A$2:$A$53) ) ) -> 2 | O25: 45966 | P25: 45966 | Q25: 05/11/2025: Se realiza ajuste en el proceso de actualización de los datos obtenidos del servicio SOAP de Directorio Activo | R25: True
A26: Faver Lopez | B26: COLP25-0025 | C26: Migrar conversores tiff | D26: Se requiere migrar las funcionalidades de conversion de archivos a tiff debido a que el ajuste realizado en el hardening afecta la libreria que se estaba usando para el proceso | F26: FINALIZADO | G26: 100 | H26: =IF(OR(J26="",K26="",K26<J26),0,NETWORKDAYS(J26,K26,Hoja2!$A$2:$A$53)) -> 2 | J26: 45967 | K26: 45968 | L26: 45968 | M26: =IF(OR(J26="",AND(L26="",TODAY()<J26),AND(L26<>"",L26<J26)),0, IF(L26="", NETWORKDAYS(J26,TODAY(),Hoja2!$A$2:$A$53), NETWORKDAYS(J26,L26,Hoja2!$A$2:$A$53) ) ) -> 2 | O26: 45968 | P26: 45968 | Q26: 07/11/2025: Se migran las funcionalidades de conversión a la nueva aplicación, de esta forma se deja de depender de librerias como graphicsmagick y Ghostscript. | R26: True
A27: Faver Lopez | B27: COLP25-0026 | C27: Agregar Areas y Novedades Masivas | D27: El cliente solicita agregar nuevas novedades para radicar masivos del Area de SALUD y HYC | F27: FINALIZADO | G27: 100 | H27: =IF(OR(J27="",K27="",K27<J27),0,NETWORKDAYS(J27,K27,Hoja2!$A$2:$A$53)) -> 1 | J27: 45875 | K27: 45876 | L27: 45876 | M27: =IF(OR(J27="",AND(L27="",TODAY()<J27),AND(L27<>"",L27<J27)),0, IF(L27="", NETWORKDAYS(J27,TODAY(),Hoja2!$A$2:$A$53), NETWORKDAYS(J27,L27,Hoja2!$A$2:$A$53) ) ) -> 1 | O27: 45875 | P27: 45876 | Q27: 07/11/2025: Se agrega areas y novedades solicitadas para el proceso de radicación de masivos. | R27: True
A28: Faver Lopez | B28: COLP25-0027 | C28: Actualizar dependencias API Automatizacion | D28: Se requiere actualizar dependencias del api para procesos de automatización | F28: FINALIZADO | G28: 100 | H28: =IF(OR(J28="",K28="",K28<J28),0,NETWORKDAYS(J28,K28,Hoja2!$A$2:$A$53)) -> 1 | J28: 45989 | K28: 45989 | L28: 45989 | M28: =IF(OR(J28="",AND(L28="",TODAY()<J28),AND(L28<>"",L28<J28)),0, IF(L28="", NETWORKDAYS(J28,TODAY(),Hoja2!$A$2:$A$53), NETWORKDAYS(J28,L28,Hoja2!$A$2:$A$53) ) ) -> 1 | O28: 45989 | P28: 45989 | Q28: 28/11/2025: Se realiza proceso de actualización de las dependencias del API a las ultimas versiones, se actualiza tambien la versión del navegador requerido para navegación automatica en Rues. | R28: True
A29: Faver Lopez | B29: COLP25-0028 | C29: Revision de Vulnerabilidades en Dependencias | D29: Se requiere realizar un proceso de revisión de vulnerabilidades de dependencias de los aplicativos de Imagine (nodejs y python) | F29: FINALIZADO | G29: 100 | H29: =IF(OR(J29="",K29="",K29<J29),0,NETWORKDAYS(J29,K29,Hoja2!$A$2:$A$53)) -> 1 | J29: 45989 | K29: 45989 | L29: 45989 | M29: =IF(OR(J29="",AND(L29="",TODAY()<J29),AND(L29<>"",L29<J29)),0, IF(L29="", NETWORKDAYS(J29,TODAY(),Hoja2!$A$2:$A$53), NETWORKDAYS(J29,L29,Hoja2!$A$2:$A$53) ) ) -> 1 | O29: 45989 | P29: 46000 | Q29: 28/11/2025: Se realiza la revisión de vulnerabilidades y actualización de dependencias de los aplicativos de Imagine. | R29: True
A30: Faver Lopez | B30: COLP25-0029 | C30: Migrar Ant Desing | D30: Se requiere migrar la libreria de componentes del FrontEnd Imagine a la versión 6 de Ant Desing, este cambio requiere de ajustes en algunos componentes, mejora la compatibilidad con React 19 por defecto. | F30: FINALIZADO | G30: 100 | H30: =IF(OR(J30="",K30="",K30<J30),0,NETWORKDAYS(J30,K30,Hoja2!$A$2:$A$53)) -> 1 | J30: 45989 | K30: 45989 | L30: 45989 | M30: =IF(OR(J30="",AND(L30="",TODAY()<J30),AND(L30<>"",L30<J30)),0, IF(L30="", NETWORKDAYS(J30,TODAY(),Hoja2!$A$2:$A$53), NETWORKDAYS(J30,L30,Hoja2!$A$2:$A$53) ) ) -> 1 | O30: 45989 | P30: 46052 | Q30: 28/11/2025: Se actualiza Ant Desing a v6, se realiza ajustes necesarios los ajustes necesarios para la compatibilidad con la nueva versión. 30/01/2026: Se realiza el paso a produccion de la migración de la libreria de componentes. 13/02/2026: Se han actualizado todos los componentes y realizado ajustes de propiedades deprecadas. | R30: True
A31: Faver Lopez | B31: COLP25-0030 | C31: Actualizacion Dependencias - API Automatizaciones | D31: Se requiere actualizar dependencias del api para procesos de automatización, esto es necesario para aplicar los ultimos parches de seguridad. | F31: FINALIZADO | G31: 100 | H31: =IF(OR(J31="",K31="",K31<J31),0,NETWORKDAYS(J31,K31,Hoja2!$A$2:$A$53)) -> 1 | J31: 45995 | K31: 45995 | L31: 45995 | M31: =IF(OR(J31="",AND(L31="",TODAY()<J31),AND(L31<>"",L31<J31)),0, IF(L31="", NETWORKDAYS(J31,TODAY(),Hoja2!$A$2:$A$53), NETWORKDAYS(J31,L31,Hoja2!$A$2:$A$53) ) ) -> 1 | O31: 45995 | P31: 45995 | Q31: 04/12/2025: Se realiza la actualización de dependencias para aplicar parches de seguridad | R31: True
A32: Faver Lopez | B32: COLP25-0036 | C32: Mitigación de Vulnerabilidades | D32: Se requiere actualizar dependencias con vulnerabilidades reportadas que afectan el aplicativo de Imagine Solicitudes | F32: FINALIZADO | G32: 100 | H32: =IF(OR(J32="",K32="",K32<J32),0,NETWORKDAYS(J32,K32,Hoja2!$A$2:$A$53)) -> 1 | J32: 46002 | K32: 46002 | L32: 46002 | M32: =IF(OR(J32="",AND(L32="",TODAY()<J32),AND(L32<>"",L32<J32)),0, IF(L32="", NETWORKDAYS(J32,TODAY(),Hoja2!$A$2:$A$53), NETWORKDAYS(J32,L32,Hoja2!$A$2:$A$53) ) ) -> 1 | O32: 46002 | P32: 46002 | Q32: 11/12/2025: Se realiza actaulización de las dependencias con vulnerabiidades a versiones corregidas. | R32: True
A33: Faver Lopez | B33: COLP25-0031 | C33: Ajuste Visor Imagenes - Imaginex | D33: En el modulo antiguo de consulta de Imagenes en Nativo, se requiere ajusta el visor de Imagines que soporta imagenes .tif, debido a que esta fallando al momento de cargar algunas imagenes | F33: FINALIZADO | G33: 100 | H33: =IF(OR(J33="",K33="",K33<J33),0,NETWORKDAYS(J33,K33,Hoja2!$A$2:$A$53)) -> 1 | J33: 46009 | K33: 46009 | L33: 46009 | M33: =IF(OR(J33="",AND(L33="",TODAY()<J33),AND(L33<>"",L33<J33)),0, IF(L33="", NETWORKDAYS(J33,TODAY(),Hoja2!$A$2:$A$53), NETWORKDAYS(J33,L33,Hoja2!$A$2:$A$53) ) ) -> 1 | O33: 46009 | P33: 46009 | Q33: 18/12/2025: Se realiza ajuste del visor de imagenes .tif, se requirio de cambios en las librerias javascript para corregir unos errores de descompresión de los archivos multi páginas. | R33: True
A34: Faver Lopez | B34: COLP25-0032 | C34: Pruebas Servidor DB QA | D34: Se requiere realizar pruebas de acceso y funcionalidad de la base de datos de QA, debido a procesos de Hardenización ejecutados por el cliente. | F34: FINALIZADO | G34: 100 | H34: =IF(OR(J34="",K34="",K34<J34),0,NETWORKDAYS(J34,K34,Hoja2!$A$2:$A$53)) -> 1 | J34: 46008 | K34: 46008 | L34: 46008 | M34: =IF(OR(J34="",AND(L34="",TODAY()<J34),AND(L34<>"",L34<J34)),0, IF(L34="", NETWORKDAYS(J34,TODAY(),Hoja2!$A$2:$A$53), NETWORKDAYS(J34,L34,Hoja2!$A$2:$A$53) ) ) -> 1 | O34: 46008 | P34: 46008 | Q34: 17/12/2025: Se realizan las pruebas de acceso y funcionalidad de las bases de datos del ambiente QA, no se presentan novedades. | R34: True
A35: Faver Lopez | B35: COLP25-0033 | C35: AUTOMATIZACIONES IMAGINE - Generar Planos Novedades Masivas | D35: Se requiere que el procesamiento y generación de planos de la novedades radicadas por el modulo de masivos se puede realizar de forma automatica | F35: FINALIZADO | G35: 100 | H35: =IF(OR(J35="",K35="",K35<J35),0,NETWORKDAYS(J35,K35,Hoja2!$A$2:$A$53)) -> 0 | J35: 45962 | M35: =IF(OR(J35="",AND(L35="",TODAY()<J35),AND(L35<>"",L35<J35)),0, IF(L35="", NETWORKDAYS(J35,TODAY(),Hoja2!$A$2:$A$53), NETWORKDAYS(J35,L35,Hoja2!$A$2:$A$53) ) ) -> 153 | P35: 46052 | Q35: 18/12/2025: Se creo el proceso para lotear, guardar y generar planos de las novedades masivas 01/02/2026: Se completa el proceso y se habilita de forma automatica todo el proceso de generación de planos en el radicador de masivos. | R35: True
A36: Faver Lopez | B36: COLP25-0034 | C36: Cargue de Festivos 2026 | D36: Se requiere agregar los festivos en las bases de datos para el año 2026 | F36: FINALIZADO | G36: 100 | H36: =IF(OR(J36="",K36="",K36<J36),0,NETWORKDAYS(J36,K36,Hoja2!$A$2:$A$53)) -> 1 | J36: 46022 | K36: 46022 | L36: 46022 | M36: =IF(OR(J36="",AND(L36="",TODAY()<J36),AND(L36<>"",L36<J36)),0, IF(L36="", NETWORKDAYS(J36,TODAY(),Hoja2!$A$2:$A$53), NETWORKDAYS(J36,L36,Hoja2!$A$2:$A$53) ) ) -> 1 | P36: 46022 | Q36: 31/12/2025: Se crean las query y se realiza el cargue en las tablas de las diferentes base de datos de Imagine | R36: True
A37: Faver Lopez | B37: COLP25-0035 | C37: Crear un Informe para radicador masivos | D37: Se solicito en la reunion de seguimiento mensual con el cliente que se agregue un informe para descargar el detalle de los radicados masivos. | F37: FINALIZADO | G37: 100 | H37: =IF(OR(J37="",K37="",K37<J37),0,NETWORKDAYS(J37,K37,Hoja2!$A$2:$A$53)) -> 5 | J37: 46027 | K37: 46031 | L37: 46031 | M37: =IF(OR(J37="",AND(L37="",TODAY()<J37),AND(L37<>"",L37<J37)),0, IF(L37="", NETWORKDAYS(J37,TODAY(),Hoja2!$A$2:$A$53), NETWORKDAYS(J37,L37,Hoja2!$A$2:$A$53) ) ) -> 5 | O37: 46031 | P37: 46052 | Q37: 31/12/2025: Se pase el desarrollo al mabiente de QA para pruebas correspondientes 30/01/2026: Se habilito el modulo para genearar reportes de los radicados masivos | R37: True
A38: Faver Lopez | B38: COLP26-0001 | C38: Revisión Modulo Sarlaft | D38: Se esta evidenciando que al momento de cambiar de estado los registros de sarlaft estos pierden referencia al archivo con la información de la composición accionaria | F38: FINALIZADO | G38: 100 | H38: =IF(OR(J38="",K38="",K38<J38),0,NETWORKDAYS(J38,K38,Hoja2!$A$2:$A$53)) -> 1 | J38: 46043 | K38: 46043 | L38: 46043 | M38: =IF(OR(J38="",AND(L38="",TODAY()<J38),AND(L38<>"",L38<J38)),0, IF(L38="", NETWORKDAYS(J38,TODAY(),Hoja2!$A$2:$A$53), NETWORKDAYS(J38,L38,Hoja2!$A$2:$A$53) ) ) -> 1 | O38: 46043 | P38: 46043 | Q38: 31/12/2025: Se realiza ajustes para evitar perdida de la ruta del archivo del sarlaft | R38: True
A39: Faver Lopez | B39: COLP26-0002 | C39: Ajuste Devoluciones Radicador | D39: Solicitan modificar el proceso de notificacion de devoluciones de radicados, se requiere que estas devoluciones se realicen directamente al usuario radicador | F39: FINALIZADO | G39: 100 | H39: =IF(OR(J39="",K39="",K39<J39),0,NETWORKDAYS(J39,K39,Hoja2!$A$2:$A$53)) -> 0 | I39: 46083 | J39: 46167 | L39: 46170 | M39: =IF(OR(J39="",AND(L39="",TODAY()<J39),AND(L39<>"",L39<J39)),0, IF(L39="", NETWORKDAYS(J39,TODAY(),Hoja2!$A$2:$A$53), NETWORKDAYS(J39,L39,Hoja2!$A$2:$A$53) ) ) -> 4 | O39: 46169 | P39: 46170 | Q39: 02/03/2026: Este requerimiento aun no se esta trabajando ya que aun falta realizar definiciones de como se modificara el flujo de radicación de tramites. 29/06/2026: Se realizan los ajustes para notificar al usuario cuando se realiza una devolución. | R39: True
A40: Faver Lopez | B40: COLP26-0003 | C40: Ajuste Reporte General 2 | D40: Solicitan revisión y ajuste del reporte general 2 ya que este no esta siendo consistente en los datos, lo que dificulta interpretar el estado de los radicados. | F40: PAUSADO | G40: 80 | H40: =IF(OR(J40="",K40="",K40<J40),0,NETWORKDAYS(J40,K40,Hoja2!$A$2:$A$53)) -> 0 | M40: =IF(OR(J40="",AND(L40="",TODAY()<J40),AND(L40<>"",L40<J40)),0, IF(L40="", NETWORKDAYS(J40,TODAY(),Hoja2!$A$2:$A$53), NETWORKDAYS(J40,L40,Hoja2!$A$2:$A$53) ) ) -> 0 | Q40: 02/03/2026: Se ha realizado ajustes en el reporte para incluir las nuevas fechas de vigencia y determinar el cumplimiento de ANS. Los informes estan pausados por solicitud de Don Hernan esto no se avanzara por ahora | R40: True
...

Sheet Hoja2
A1: 45292 | B1: Año Nuevo
A2: 45299 | B2: Día de los Reyes Magos
A3: 45376 | B3: Día de San José
A4: 45379 | B4: Jueves Santo (Semana Santa)
A5: 45380 | B5: Viernes Santo (Semana Santa)
A6: 45413 | B6: Día del Trabajo
A7: 45425 | B7: Día de la Ascensión
A8: 45446 | B8: Corpus Christi
A9: 45453 | B9: Sagrado Corazón
A10: 45474 | B10: San Pedro y San Pablo
A11: 45493 | B11: Día de la Independencia
A12: 45511 | B12: Batalla de Boyacá
... A53: 46381 | B53: Navidad

Sheet ASISTENCIA
A1: ASISTENCIA DAYLI
A3: INTEGRANTE | B3: 45596 | C3: 45597 | D3: 45601 | E3: 45602 | F3: 45603 | G3: 45604 | H3: 45608 | I3: 45609 | J3: 45610 | K3: 45611 | L3: 45614 | M3: 45615 | N3: 45616 | O3: 45617 | P3: 45618 | Q3: 45621 | R3: 45622 | S3: 45623 | T3: 45624 | U3: 45625 | V3: 45628 | W3: 45629 | X3: 45630 | Y3: 45631 | Z3: 45632 | AA3: 45635 | AB3: 45636 | AC3: 45637 | AD3: 45638 | AE3: 45639 | AF3: 45642 | AG3: 45643 | AH3: 45644 | AI3: 45645 | AJ3: 45646 | AK3: 45649 | AL3: 45650 | AM3: 45652 | AN3: 45653 | AO3: 45656 | AP3: 45656 | AQ3: 45664 | AR3: 45665 | AS3: 45666 | AT3: 45667 | AU3: 45670 | AV3: 45671 | AW3: 45672 | AX3: 45673 | AY3: 45674 | AZ3: 45677 | BA3: 45678 | BB3: 45679 | BC3: 45680 | BD3: 45681 | BE3: 45684 | BF3: 45685 | BG3: 45686 | BH3: 45687 | BI3: 45688 | BJ3: 45691 | BK3: 45692 | BL3: 45693 | BM3: 45694 | BN3: 45695 | BO3: 45698 | BP3: 45699 | BQ3: 45700 | BR3: 45701 | BS3: 45702 | BT3: 45705 | BU3: 45706 | BV3: 45707 | BW3: 45708 | BX3: 45709 | BY3: 45712 | BZ3: 45713 | CA3: 45714 | CB3: 45715 | CC3: 45716 | CD3: 45719 | CE3: 45720 | CF3: 45721 | CG3: 45722 | CH3: 45723 | CI3: 45726 | CJ3: 45727 | CK3: 45728 | CL3: 45729 | CM3: 45730 | CN3: 45733 | CO3: 45734 | CP3: 45735 | CQ3: 45736 | CR3: 45737 | CS3: 45741
A4: DANILO RAMIREZ | B4: SI | C4: no (Dia de la familia) | D4: SI | E4: SI | F4: SI | G4: SI | H4: SI | I4: SI | J4: SI | K4: SI | L4: SI | M4: SI | N4: SI | O4: No hubo sesion | P4: SI | Q4: SI | R4: SI | S4: SI | T4: SI | U4: NO | V4: SI | W4: SI | X4: SI | Y4: SI | Z4: SI | AA4: SI | AB4: SI | AC4: SI | AD4: SI | AE4: No hubo sesión | AF4: SI | AG4: SI | AH4: SI | AI4: SI | AJ4: SI | AK4: SI | AL4: NO HUBO SESION | AM4: NO | AN4: NO | AO4: SI | AP4: NO HAY SESION | AQ4: SI | AR4: SI | AS4: NO HAY SESION | AT4: SI | AU4: SI | AV4: SI | AW4: SI | AX4: SI | AY4: NO HAY SESION | AZ4: SI | BA4: SI | BB4: SI | BC4: SI | BD4: SI | BE4: SI | BF4: SI | BG4: SI | BH4: SI | BI4: SI | BJ4: NO HAY SESION | BK4: Vacaciones | BL4: Vacaciones | BM4: Vacaciones | BN4: Vacaciones | BO4: Vacaciones | BP4: Vacaciones | BQ4: Vacaciones | BR4: SI | BS4: SI | BT4: SI | BU4: SI | BV4: SI | BW4: SI | BX4: SI | BY4: SI | BZ4: SI | CA4: SI | CB4: SI | CC4: SI | CD4: SI | CE4: SI | CF4: SI | CI4: No hobo sesion por caida de los sitios. | CS4: SI
A5: JAIRO NIÑO | B5: SI | C5: SI | D5: SI | E5: SI | F5: SI | G5: SI | H5: SI | I5: SI | J5: SI | K5: SI | L5: Vacaciones | M5: Vacaciones | N5: Vacaciones | O5: Vacaciones | P5: Vacaciones | Q5: SI | R5: SI | S5: SI | T5: SI | U5: SI | V5: SI | W5: SI | X5: SI | Y5: SI | Z5: SI | AA5: SI | AB5: SI | AC5: SI | AD5: SI | AF5: SI | AG5: SI | AH5: SI | AI5: SI | AJ5: SI | AK5: SI | AM5: SI | AN5: SI | AO5: SI | AQ5: Vacaciones | AR5: Vacaciones | AT5: Vacaciones | AU5: Vacaciones | AV5: Vacaciones | AW5: Vacaciones | AX5: Vacaciones | AZ5: Vacaciones | BA5: SI | BB5: SI | BC5: SI | BD5: SI | BE5: SI | BF5: SI | BG5: SI | BH5: SI | BI5: SI | BK5: SI | BL5: SI | BM5: SI | BN5: SI | BO5: SI | BP5: SI | BQ5: SI | BR5: SI | BS5: SI | BT5: SI | BU5: SI | BV5: SI | BW5: SI | BX5: SI | BY5: SI | BZ5: SI | CA5: SI | CB5: SI | CC5: SI | CD5: SI | CE5: SI | CF5: SI | CS5: SI
A6: JESUS PEÑA | B6: SI | C6: SI | D6: SI | E6: SI | F6: SI | G6: SI | H6: SI | I6: SI | J6: SI | K6: Dia de la familia | L6: SI | M6: SI | N6: SI | O6: No hubo sesion | P6: SI | Q6: SI | R6: SI | S6: SI | T6: SI | U6: SI | V6: SI | W6: SI | X6: SI | Y6: SI | Z6: SI | AA6: SI | AB6: SI | AC6: SI | AD6: SI | AF6: SI | AG6: SI | AH6: SI | AI6: SI | AJ6: SI | AK6: SI | AM6: SI | AN6: SI | AO6: SI | AQ6: SI | AR6: SI | AT6: SI | AU6: SI | AV6: SI | AW6: SI | AX6: SI | AZ6: SI | BA6: SI | BB6: SI | BC6: SI | BD6: SI | BE6: SI | BF6: SI | BG6: SI | BH6: SI | BI6: SI | BK6: SI | BL6: SI | BM6: Falla electrica | BN6: SI | BO6: SI | BP6: SI | BQ6: SI | BR6: SI | BS6: SI | BT6: SI | BU6: SI | BV6: SI | BW6: SI | BX6: SI | BY6: SI | BZ6: SI | CA6: SI | CB6: SI | CC6: SI | CD6: SI | CE6: SI | CF6: SI | CS6: SI
A7: LUIS BEDOYA | B7: SI | C7: SI | D7: SI | E7: SI | F7: SI | G7: SI | H7: SI | I7: SI | J7: SI | K7: SI | L7: Dia de la familia | M7: SI | N7: SI | O7: No hubo sesion | P7: SI | Q7: SI | R7: SI | S7: SI | T7: SI | U7: SIN INTERNET | V7: SI | W7: SI | X7: SI | Y7: SI | Z7: NO | AA7: SI | AB7: SI | AC7: SI | AD7: SI | AF7: SI | AG7: SI | AH7: SI | AI7: SI | AJ7: SI | AK7: SI | AM7: SI | AN7: SI | AO7: SI | AQ7: SI | AR7: SI | AT7: SI | AU7: NO | AV7: SI | AW7: SI | AX7: SI | AZ7: SI | BA7: SI | BB7: SI | BC7: SI | BD7: SI | BE7: SI | BF7: SI | BG7: SI | BH7: SI | BI7: SI | BK7: SI | BL7: SI | BM7: SI | BN7: SI | BO7: NO | BU7: SI | BV7: SI | BW7: SI | BX7: SI
A8: JOHAN QUICENO | B8: SI | C8: SI | D8: SI | E8: SI | F8: SI | G8: SI | H8: SI | I8: SI | J8: SI | K8: SI | L8: NO | M8: SI | N8: SI | O8: No hubo sesion | P8: SI | Q8: SI | R8: SI | S8: SI | T8: SI | U8: SI | V8: SI | W8: Permiso | X8: SI | Y8: SI | Z8: SI | AA8: SI | AB8: NO | AC8: SI | AD8: SI | AF8: SI | AG8: SI | AH8: SI | AI8: SI | AJ8: SI | AK8: SI | AM8: SI | AN8: NO | AO8: SI | AQ8: SI | AR8: SI | AT8: SI | AU8: SI | AV8: SI | AW8: SI | AX8: SI | AZ8: SI | BA8: SI | BB8: SI | BC8: SI | BD8: SI | BE8: SI | BF8: SI | BG8: sin internet | BH8: SI | BI8: SI | BK8: SI | BL8: SI | BM8: SI | BN8: SI | BO8: SI | BP8: SI | BQ8: SI | BR8: SI | BS8: SI | BT8: SI | BU8: SI | BV8: SI | BW8: SI | BX8: TRABAJO HASTA HOY
A9: FABIO FORERO | B9: SI | C9: SI | D9: SI | E9: SI | F9: SI | G9: SI | H9: SI | I9: SI | J9: SI | K9: SI | L9: SI | M9: SI | N9: SI | O9: Dia de la familia | P9: SI | Q9: SI | R9: SI | S9: SI | T9: SI | U9: SI | V9: SI | W9: SI | X9: SI | Y9: SI | Z9: SI | AA9: SI | AB9: SI | AC9: SI | AD9: SI | AF9: SI | AG9: SI | AH9: SI | AI9: SI | AJ9: SI | AK9: SI | AM9: SI | AN9: SI | AO9: SI | AQ9: SI | AR9: SI | AT9: SI | AU9: SI | AV9: SI | AW9: SI | AX9: SI | AZ9: SI | BA9: SI | BB9: SI | BC9: SI | BD9: SI | BE9: SI | BF9: SI | BG9: SI | BH9: SI | BI9: SI | BK9: SI | BL9: SI | BM9: SI | BN9: SI | BO9: SI | BP9: SI | BQ9: SI | BR9: SI | BS9: SI | BT9: SI | BU9: SI | BV9: SI | BW9: SI | BX9: SI | BY9: SI | BZ9: SI | CA9: SI | CB9: SI | CC9: SI | CD9: SI | CE9: SI | CF9: SI | CS9: SI
A10: JENRY HENAO | B10: SI | C10: SI | D10: SI | E10: SI | F10: SI | G10: SI | H10: SI | I10: NO | J10: SI | K10: NO | L10: SI | M10: SI | N10: NO | O10: No hubo sesion | P10: NO | Q10: NO | R10: SI | S10: SI | T10: SI | U10: NO | V10: SI | W10: SI | X10: SI | Y10: SI | Z10: SI | AA10: SI | AB10: SI | AC10: SI | AD10: SI | AF10: SI | AG10: SI | AH10: SI | AI10: SI | AJ10: SI | AK10: NO | AM10: NO | AN10: SI | AO10: SI | AQ10: SI | AR10: SI | AT10: SI | AU10: SI | AV10: SI | AW10: SI | AX10: SI | AZ10: SI | BA10: NO | BB10: NO | BC10: NO | BD10: NO | BE10: NO | BF10: SI | BG10: SI | BH10: SI | BI10: SI | BK10: SI | BL10: SI | BM10: SI | BN10: SI | BO10: SI | BP10: SI | BQ10: SI | BR10: SI | BS10: SI | BT10: SI | BU10: SI | BV10: SI | BW10: NO | BX10: SI | BY10: SI | BZ10: SI | CA10: SI | CB10: SI | CC10: SI | CD10: SI | CE10: SI | CF10: SI | CS10: SI
A11: LIYIBET PEREZ | B11: SI | C11: SI | D11: SI | E11: SI | F11: SI | G11: SI | H11: SI | I11: SI | J11: nomina | K11: NO | L11: SI | M11: NO | N11: SI | O11: No hubo sesion | P11: SI | Q11: SI | R11: SI | S11: NO | T11: NO | U11: NO | V11: SI | W11: SI | X11: SI | Y11: SI | Z11: SI | AA11: SI | AB11: SI | AC11: SI | AD11: NO | AF11: SI | AG11: SI | AH11: SI | AI11: SI | AJ11: SI | AK11: SI | AM11: SI | AN11: SI | AO11: SI | AQ11: SI | AR11: SI | AT11: SI | AU11: NO | AV11: NO | AW11: SI | AX11: SI | AZ11: NO | BA11: SI | BB11: SI | BC11: SI | BD11: SI | BE11: NO | BF11: NO | BG11: NO | BH11: SI | BI11: SI | BK11: SI | BL11: SI | BM11: SI | BN11: SI | BO11: NO | BP11: SI | BQ11: SI | BR11: NOMINA | BS11: SI | BT11: SI | BU11: SI | BV11: SI | BW11: SI | BX11: SI | BY11: SI | BZ11: SI | CA11: SI | CB11: NO | CC11: NO | CD11: SI | CE11: SI | CF11: SI | CS11: SI
A12: WILSON APONTE | B12: SI | C12: NO | D12: SI | E12: SI | F12: NO | G12: NO | H12: SI | I12: NO | J12: SI | K12: NO | L12: SI | M12: NO | N12: NO | O12: No hubo sesion | P12: SI | Q12: NO | R12: NO | S12: NO | T12: NO | U12: NO | V12: NO | W12: SI | X12: NO | Y12: NO | Z12: SI | AA12: NO | AB12: NO | AC12: SI | AD12: NO | AF12: NO | AG12: NO | AH12: NO | AI12: NO | AJ12: SI | AK12: SI | AM12: NO | AN12: NO | AO12: NO | AQ12: NO | AR12: NO | AT12: NO | AU12: NO | AV12: SI | AW12: SI | AX12: NO | AZ12: NO | BA12: NO | BB12: NO | BC12: SI | BD12: NO | BE12: SI | BF12: NO | BG12: NO | BH12: SI | BI12: NO | BK12: NO | BL12: NO | BM12: SI | BN12: NO | BO12: NO | BP12: NO | BQ12: NO | BR12: SI | BS12: NO | BT12: NO | BU12: SI | BV12: SI | BW12: NO | BX12: NO | BY12: SI | BZ12: NO | CA12: NO | CB12: SI | CC12: NO | CD12: NO | CE12: SI | CF12: NO | CS12: NO
A13: JOHN ROLON | B13: SI | C13: NO | D13: NO | E13: NO | F13: NO | G13: NO | H13: NO | I13: NO | J13: SI | K13: NO | L13: NO | M13: SI | N13: NO | O13: No hubo sesion | P13: NO | Q13: NO | R13: NO | S13: NO | T13: NO | U13: NO | V13: SI | W13: NO | X13: NO | Y13: NO | Z13: NO | AA13: NO | AB13: NO | AC13: SI | AD13: NO | AF13: NO | AG13: NO | AH13: NO | AI13: SI | AJ13: NO | AK13: NO | AM13: NO | AN13: NO | AO13: NO | AQ13: NO | AR13: NO | AT13: NO | AU13: NO | AV13: NO | AW13: NO | AX13: NO | AZ13: NO | BA13: NO | BB13: NO | BC13: NO | BD13: NO | BE13: NO | BF13: NO | BG13: NO | BH13: NO | BI13: NO | BK13: NO | BL13: NO | BM13: NO | BN13: NO | BO13: NO | BP13: NO | BQ13: NO | BR13: NOMINA | BS13: NO | BT13: NO | BU13: NO | BV13: NO | BW13: NO | BX13: NO | BY13: NO | BZ13: NO | CA13: NO | CB13: NO | CC13: NO | CD13: SI | CE13: SI | CF13: SI | CS13: NO

Sheet pruebas i
A1: Asignado | B1: Requerimiento | C1: Actividad | D1: ESTADO | E1: F.Asignado | F1: Fecha inicio | G1: F. estimada de entrega | H1: Finalizado | I1: Dias | J1: TEST | K1: PRODUCCION | L1: Observacion
A2: LUIS BAYONA | B2: Encolar informe de efectividad de salud | D2: FINALIZADO | E2: 45567 | F2: 45567 | G2: 45568 | H2: 45569 | I2: =IF(ISBLANK(H2), NETWORKDAYS(F2, TODAY(),Hoja2!$A$1:$A$18), NETWORKDAYS(F2, H2, Hoja2!$A$1:$A$18)) -> 3 | J2: 45572 | L2: *02/10/2024 inicia gestion. *03/10/2024 Finalizar la consulta y realizar pruebas * 07/10/2024 desarrollo en test para pruebas
A3: FABIO FORERO | B3: VULNERABILIDADES BAJAS | C3: Web Server Allows Password Auto-Completion | D3: PENDIENTE | E3: 45575 | H3: 0 | I3: =IF(ISBLANK(H3), NETWORKDAYS(F3, TODAY(),Hoja2!$A$1:$A$18), NETWORKDAYS(F3, H3, Hoja2!$A$1:$A$18)) -> 0 | J3: 45569 | L3: *04/10/2024 pruebas * 07/10/2024 se entrega a Danilo para pruebas y posterior despliegue a producción * 09/10/2024 Confirmar entrega de rama a Danilo * 10/10/2024 Etregadas a Danilo 9 de octubre,
A4: FABIO FORERO | C4: Autocomplete Enabled (15 Y 18) | D4: PENDIENTE | E4: 45575 | H4: 0 | I4: =IF(ISBLANK(H4), NETWORKDAYS(F4, TODAY(),Hoja2!$A$1:$A$18), NETWORKDAYS(F4, H4, Hoja2!$A$1:$A$18)) -> 0 | J4: 45569 | L4: *04/10/2024 pruebas * 07/10/2024 se entrega a Danilo para pruebas y posterior despliegue a producción * 09/10/2024 Confirmar entrega de rama a Danilo * 10/10/2024 Etregadas a Danilo 9 de octubre
A5: FABIO FORERO | B5: VULNERABILIDADES MEDIAS | C5: Internal Server Error | D5: PENDIENTE | E5: 45575 | H5: 0 | I5: =IF(ISBLANK(H5), NETWORKDAYS(F5, TODAY(),Hoja2!$A$1:$A$18), NETWORKDAYS(F5, H5, Hoja2!$A$1:$A$18)) -> 0 | J5: 45569 | L5: *04/10/2024 pruebas * 07/10/2024 se entrega a Danilo para pruebas y posterior despliegue a producción * 09/10/2024 Confirmar entrega de rama a Danilo * 10/10/2024 Etregadas a Danilo 9 de octubre
