Workbook

Sheet EN PROCESO (Proteccíon)
A1: Asignado a | B1: ID REQ | C1: Requerimiento | D1: Descripcion req | E1: Actividad | F1: ESTADO | G1: % AVANCE | H1: Dias estimados de desarrollo | I1: F.Asignado | J1: Fecha inicio | K1: F. estimada de entrega | L1: Finalizado | M1: Dias total desarrollo | N1: Fecha compromiso cliente | O1: FECHA PASO A TEST | P1: FECHA PASO A PRODUCCION | Q1: OBSERVACIONES | R1: Visible
A2: Alejandro | B2: REQ-1-1 | C2: Tratamiento especial al radicar trámites de vejez (Revision de flujo y código) | D2: Se está a la espera de la solicitud formal por parte del cliente | F2: FINALIZADO | G2: 100 | H2: =IF(OR(J2="",K2="",K2<J2),0,NETWORKDAYS(J2,K2,Hoja2!$A$2:$A$53)) -> 1 | I2: 45826 | J2: 45827 | K2: 45827 | L2: 45827 | M2: =IF(OR(J2="",AND(L2="",TODAY()<J2),AND(L2<>"",L2<J2)),0, IF(L2="", NETWORKDAYS(J2,TODAY(),Hoja2!$A$2:$A$53), NETWORKDAYS(J2,L2,Hoja2!$A$2:$A$53) ) ) -> 1 | Q2: 19/06/2025 Se identifico el código a intervenir y con el que trabajar en el requerimiento | R2: true
A3: Alejandro | B3: REQ-1-2 | C3: Tratamiento especial al radicar trámites de vejez (Reunión con las partes interesadas para identificar los inputs de trabajo) | D3: Se está a la espera de la solicitud formal por parte del cliente | F3: FINALIZADO | G3: 100 | H3: =IF(OR(J3="",K3="",K3<J3),0,NETWORKDAYS(J3,K3,Hoja2!$A$2:$A$53)) -> 1 | I3: 45827 | J3: 45832 | K3: 45832 | L3: 45832 | M3: =IF(OR(J3="",AND(L3="",TODAY()<J3),AND(L3<>"",L3<J3)),0, IF(L3="", NETWORKDAYS(J3,TODAY(),Hoja2!$A$2:$A$53), NETWORKDAYS(J3,L3,Hoja2!$A$2:$A$53) ) ) -> 1 | Q3: 24/06/2025: Se reune con las partes interesadas, se identifican los requisitos, necesidades y material de trabajo, pero se suspende el requerimiento hasta nuevo aviso | R3: true
A4: Alejandro | B4: REQ-2-1 | C4: Creación de reporte de AUF para identificación de pagos, creación de opción de cargue masivo para cambio de bandejas y creación de opción de consulta de pagos (Creación de script para generar reporte de pagos de auxilios funerarios y la vista para su consumo) | D4: Creación de Herramientas adicionales para el tratamiento de información y flujo en el módulo de auxilios funerarios | F4: FINALIZADO | G4: 100 | H4: =IF(OR(J4="",K4="",K4<J4),0,NETWORKDAYS(J4,K4,Hoja2!$A$2:$A$53)) -> 0 | I4: 45832 | J4: 45839 | K4: 45833 | L4: 45839 | M4: =IF(OR(J4="",AND(L4="",TODAY()<J4),AND(L4<>"",L4<J4)),0, IF(L4="", NETWORKDAYS(J4,TODAY(),Hoja2!$A$2:$A$53), NETWORKDAYS(J4,L4,Hoja2!$A$2:$A$53) ) ) -> 1 | O4: 45839 | P4: 45853 | Q4: 24/06/2025: Se realiza reunión para la identificación de nuevos requisitos 01/07/2025: Se realiza vista para el consumo y parte de la lóigica para la creación del reporte 01/07/2025: Se está a la espera de validar la información del reporte debido a que se nos envía 2 reportes con estructuras distintas 09/07/2025: Se realiza reunión con las partes interesadas y se acuerda en agregar información obtenida de distintas fuentes al formulario 15/07/2025: Se realizaron aún más cambios propuestos por el usuario y correcciones de fallas en el funcionamiento 15/07/2025: Se pasa a producción | R4: true
A5: Alejandro | B5: REQ-2-2 | C5: Creación de reporte de AUF para identificación de pagos, creación de opción de cargue masivo para cambio de bandejas y creación de opción de consulta de pagos (Creación de script para generar opción de consulta de pagos) | D5: Creación de Herramientas adicionales para el tratamiento de información y flujo en el módulo de auxilios funerarios | F5: FINALIZADO | G5: 100 | H5: =IF(OR(J5="",K5="",K5<J5),0,NETWORKDAYS(J5,K5,Hoja2!$A$2:$A$53)) -> 2 | I5: 45839 | J5: 45839 | K5: 45840 | L5: 45848 | M5: =IF(OR(J5="",AND(L5="",TODAY()<J5),AND(L5<>"",L5<J5)),0, IF(L5="", NETWORKDAYS(J5,TODAY(),Hoja2!$A$2:$A$53), NETWORKDAYS(J5,L5,Hoja2!$A$2:$A$53) ) ) -> 8 | O5: 45848 | P5: 45853 | Q5: 09/07/2025: Se Había pospuesto la creación del código y se retoma el día 8 10/07/2025: Se termina el desarrollo y las pruebas e 10 con las modificaciones indicadas en la reunión 15/07/2025: Se realizaron aún más cambios propuestos por el usuario y correcciones de fallas en el funcionamiento 15/07/2025: Se pasa a producción | R5: true
A6: Alejandro | B6: REQ-2-3 | C6: Creación de reporte de AUF para identificación de pagos, creación de opción de cargue masivo para cambio de bandejas y creación de opción de consulta de pagos (Creación de script para generar opción en el de cargue y procesado de datos ) | D6: Creación de Herramientas adicionales para el tratamiento de información y flujo en el módulo de auxilios funerarios | F6: FINALIZADO | G6: 100 | H6: =IF(OR(J6="",K6="",K6<J6),0,NETWORKDAYS(J6,K6,Hoja2!$A$2:$A$53)) -> 1 | I6: 45839 | J6: 45840 | K6: 45840 | L6: 45840 | M6: =IF(OR(J6="",AND(L6="",TODAY()<J6),AND(L6<>"",L6<J6)),0, IF(L6="", NETWORKDAYS(J6,TODAY(),Hoja2!$A$2:$A$53), NETWORKDAYS(J6,L6,Hoja2!$A$2:$A$53) ) ) -> 1 | O6: 45840 | P6: 45853 | Q6: 01/07/2025: Se realiza reunión para la identificación de nuevos requisitos 02/07/2025: Se Crea vista y lógica para el cargue de documentos y procesamiento de datos 02/07/2025: Se realizan pruebas de funcionamiento y se esta a la espera de que el cliente realice pruebas 15/07/2025: Se realizaron aún más cambios propuestos por el usuario y correcciones de fallas en el funcionamiento 15/07/2025: Se pasa a producción | R6: true
A7: Alejandro | B7: REQ-2-4 | C7: Creación de reporte de AUF para identificación de pagos, creación de opción de cargue masivo para cambio de bandejas y creación de opción de consulta de pagos (Modificación de script para generar reporte de pagos de auxilios funerarios agregando distinta información y lógica para su construcción) | D7: Creación de Herramientas adicionales para el tratamiento de información y flujo en el módulo de auxilios funerarios | F7: FINALIZADO | G7: 100 | H7: =IF(OR(J7="",K7="",K7<J7),0,NETWORKDAYS(J7,K7,Hoja2!$A$2:$A$53)) -> 2 | I7: 45847 | J7: 45847 | K7: 45848 | L7: 45848 | M7: =IF(OR(J7="",AND(L7="",TODAY()<J7),AND(L7<>"",L7<J7)),0, IF(L7="", NETWORKDAYS(J7,TODAY(),Hoja2!$A$2:$A$53), NETWORKDAYS(J7,L7,Hoja2!$A$2:$A$53) ) ) -> 2 | O7: 45848 | P7: 45853 | Q7: 10/07/2025: Se termina el desarrollo y las pruebas. Se está en espera del visto bueno para pasar a producción 14/07/2025: Se identifican a través de las pruebas de usuarios modificaciones y añadidos por hacer. Se realizan los debidos cambios y se entrega al cliente resultados para su validación 15/07/2025: Se realizaron aún más cambios propuestos por el usuario y correcciones de fallas en el funcionamiento 15/07/2025: Se pasa a producción | R7: true
A8: Alejandro | B8: REQ-3-1 | C8: Cambios técnicos en aplicativo imagine para proceso de mesa de control documental solicitud de pensión (Reunión con las partes interesadas para identificación de requerimientos) | D8: desarrollo de la mesa de validación documental con inteligencia artificial en Filenet que implica las siguientees actividades: Se debe retirar la bandeja de imagine Validación Mesa de Control Unificada ya que la validación de documentos se realizará a través de filenet. Dado que se requiere conservar otras funciones adicionales a la bandeja de validación en el software de imagine que depende de la validación documental, se les notificara a través del siguiente web service cada vez que una solicitud documental (Paquete de documentos relacionado a los diferentes riesgos) haya finalizado el proceso de validación: | F8: FINALIZADO | G8: 100 | H8: =IF(OR(J8="",K8="",K8<J8),0,NETWORKDAYS(J8,K8,Hoja2!$A$2:$A$53)) -> 1 | I8: 45832 | J8: 45832 | K8: 45832 | L8: 45832 | M8: =IF(OR(J8="",AND(L8="",TODAY()<J8),AND(L8<>"",L8<J8)),0, IF(L8="", NETWORKDAYS(J8,TODAY(),Hoja2!$A$2:$A$53), NETWORKDAYS(J8,L8,Hoja2!$A$2:$A$53) ) ) -> 1 | Q8: 24/06/2025: Se realiza reunión para realización de pruebas e identificación de requerimientos | R8: true
A9: Alejandro | B9: REQ-4-1 | C9: Migración de registros para tipos documentales gabinete 2 (Identificación y failitación al cliente de los tipos documnetales) | F9: FINALIZADO | G9: 100 | H9: =IF(OR(J9="",K9="",K9<J9),0,NETWORKDAYS(J9,K9,Hoja2!$A$2:$A$53)) -> 1 | I9: 45847 | J9: 45847 | K9: 45847 | L9: 45847 | M9: =IF(OR(J9="",AND(L9="",TODAY()<J9),AND(L9<>"",L9<J9)),0, IF(L9="", NETWORKDAYS(J9,TODAY(),Hoja2!$A$2:$A$53), NETWORKDAYS(J9,L9,Hoja2!$A$2:$A$53) ) ) -> 1 | O9: 45847 | Q9: 09/07/2025: Se indica al cliente los distintos tipos de documentación del gabinete 2 | R9: true
A10: Alejandro | B10: REQ-5-1 | C10: Proyecto relacionado con las inconsistencias norma 2381 (Identificación de método de consumo y generación de informe de resultados) | F10: FINALIZADO | G10: 100 | H10: =IF(OR(J10="",K10="",K10<J10),0,NETWORKDAYS(J10,K10,Hoja2!$A$2:$A$53)) -> 1 | I10: 45849 | J10: 45849 | K10: 45849 | L10: 45849 | M10: =IF(OR(J10="",AND(L10="",TODAY()<J10),AND(L10<>"",L10<J10)),0, IF(L10="", NETWORKDAYS(J10,TODAY(),Hoja2!$A$2:$A$53), NETWORKDAYS(J10,L10,Hoja2!$A$2:$A$53) ) ) -> 1 | Q10: 09/07/2025: Se identifica los métodos de consumo posibles, su funcionamiento y se plasma junto con las respuestas a las dudas del cliente en un informe | R10: true
A11: Alejandro | B11: REQ-3-3 | C11: Cambios técnicos en aplicativo imagine para proceso de mesa de control documental solicitud de pensión (Creación de otro método para consumo necesario para tratamiento de trámites de pruebas de protección) | D11: desarrollo de la mesa de validación documental con inteligencia artificial en Filenet que implica las siguientees actividades: Se debe retirar la bandeja de imagine Validación Mesa de Control Unificada ya que la validación de documentos se realizará a través de filenet. Dado que se requiere conservar otras funciones adicionales a la bandeja de validación en el software de imagine que depende de la validación documental, se les notificara a través del siguiente web service cada vez que una solicitud documental (Paquete de documentos relacionado a los diferentes riesgos) haya finalizado el proceso de validación: | F11: FINALIZADO | G11: 100 | H11: =IF(OR(J11="",K11="",K11<J11),0,NETWORKDAYS(J11,K11,Hoja2!$A$2:$A$53)) -> 1 | I11: 45854 | J11: 45854 | K11: 45854 | L11: 45854 | M11: =IF(OR(J11="",AND(L11="",TODAY()<J11),AND(L11<>"",L11<J11)),0, IF(L11="", NETWORKDAYS(J11,TODAY(),Hoja2!$A$2:$A$53), NETWORKDAYS(J11,L11,Hoja2!$A$2:$A$53) ) ) -> 1 | O11: 45854 | Q11: 16/07/2025 Se realiza nuevo método de consumo para cerrar trámites con procesos documentales abiertos y asi, protección pueda ser pruebas de cierre de mesa unificada documental sin necesidad de tener procesos abiertos y con documentos | R11: true
A12: Alejandro | B12: REQ-6-1 | C12: Análisis y corrección de procesos de cargue e identificación de pagos de tipo de riesgo AUX (Análisis de la situación en Imagine) | D12: Se identificaron errores de procesos de cargue que no están identificando correctamente el estado de un trámite en la bandeja de AUX. | F12: FINALIZADO | G12: 100 | H12: =IF(OR(J12="",K12="",K12<J12),0,NETWORKDAYS(J12,K12,Hoja2!$A$2:$A$53)) -> 5 | I12: 45855 | J12: 45856 | K12: 45862 | L12: 45861 | M12: =IF(OR(J12="",AND(L12="",TODAY()<J12),AND(L12<>"",L12<J12)),0, IF(L12="", NETWORKDAYS(J12,TODAY(),Hoja2!$A$2:$A$53), NETWORKDAYS(J12,L12,Hoja2!$A$2:$A$53) ) ) -> 4 | O12: 45861 | Q12: 17/07/2025 Se realiza reunión para identificar las inconsistencias. Se está a la espera de datos de prueba y de análisis de los procesos para la verificación de los mismos 21/07/2025 Se Identificaron lógicas erroneas en el código que se corrigieron y otras lógicas de negocio que no, debido a que primero se deben de socializar los resultados antes de poder pensar en una solución 23/07/2025 Se genera informe de la situación, recomendaciones y procesos a seguir para brindar solución 23/07/2025 Se pasa los cambios que corregian errores a producción | R12: true
A13: Alejandro | B13: REQ-7-1 | C13: Mejoras en los modulos de Imagine (Reunión con las partes interesadas e identificación de requerimientos) | D13: Solicitud de protección para mejoras IMAGINE en el módulo de Auxilios funerarios | F13: FINALIZADO | G13: 100 | H13: =IF(OR(J13="",K13="",K13<J13),0,NETWORKDAYS(J13,K13,Hoja2!$A$2:$A$53)) -> 1 | I13: 45860 | J13: 45860 | K13: 45860 | L13: 45860 | M13: =IF(OR(J13="",AND(L13="",TODAY()<J13),AND(L13<>"",L13<J13)),0, IF(L13="", NETWORKDAYS(J13,TODAY(),Hoja2!$A$2:$A$53), NETWORKDAYS(J13,L13,Hoja2!$A$2:$A$53) ) ) -> 1 | Q13: 22/07/2025 Se realiza reunión para la identificación de requerimientos y necesidades del cliente 23/07/2025 Se comparte archivo de la solicitud | R13: true
A14: Alejandro | B14: Interno-H8 | C14: Automatización y migración de lógica a python ( Ejecuci[on y correcci[on de script y descarga de recursos necesarios para el entrenamiento del modelo de clasificaci[on) | F14: FINALIZADO | G14: 100 | H14: =IF(OR(J14="",K14="",K14<J14),0,NETWORKDAYS(J14,K14,Hoja2!$A$2:$A$53)) -> 2 | I14: 45863 | J14: 45863 | K14: 45866 | L14: 45866 | M14: =IF(OR(J14="",AND(L14="",TODAY()<J14),AND(L14<>"",L14<J14)),0, IF(L14="", NETWORKDAYS(J14,TODAY(),Hoja2!$A$2:$A$53), NETWORKDAYS(J14,L14,Hoja2!$A$2:$A$53) ) ) -> 2 | Q14: 25/07/2025 Se realiza la descarga de 80000 archivos no sin antes reestructurar el script y acoplarlo para no sobrecargar los procesos y que funcionara 25/07/2025 Se empieza proceso de carga en local, todo esto debido a que no se puede generar el modelo de entrenamiento en el servidor por capacidad 25/07/2025 Se termina el proceso de carga en local | R14: true
A15: Alejandro | B15: Interno-H1 | C15: Automatización y migración de lógica a python (Migración de código en donde se importa el lote tanto física como en bases de datos) | F15: FINALIZADO | G15: 100 | H15: =IF(OR(J15="",K15="",K15<J15),0,NETWORKDAYS(J15,K15,Hoja2!$A$2:$A$53)) -> 2 | I15: 45824 | J15: 45825 | K15: 45826 | L15: 45827 | M15: =IF(OR(J15="",AND(L15="",TODAY()<J15),AND(L15<>"",L15<J15)),0, IF(L15="", NETWORKDAYS(J15,TODAY(),Hoja2!$A$2:$A$53), NETWORKDAYS(J15,L15,Hoja2!$A$2:$A$53) ) ) -> 3 | O15: 45826 | Q15: 19/06/2025 Se produjeron ciertos errores en la fase de pruebas y se realizaron todas las correcciones para que el nuevo funcionamiento responda y se acople bien | R15: true
A16: Alejandro | B16: Interno-H2 | C16: Automatización y migración de lógica a python (Migración de código en donde se trata toda la lógica y activación de tareas de la indexación del lote) | F16: FINALIZADO | G16: 100 | H16: =IF(OR(J16="",K16="",K16<J16),0,NETWORKDAYS(J16,K16,Hoja2!$A$2:$A$53)) -> 2 | I16: 45826 | J16: 45828 | K16: 45832 | L16: 45833 | M16: =IF(OR(J16="",AND(L16="",TODAY()<J16),AND(L16<>"",L16<J16)),0, IF(L16="", NETWORKDAYS(J16,TODAY(),Hoja2!$A$2:$A$53), NETWORKDAYS(J16,L16,Hoja2!$A$2:$A$53) ) ) -> 3 | O16: 45833 | Q16: 20/06/2025: Identificación y paso del flujo para la funcionalidad de indexación de lotes de PHP a python 24/06/2025: Se tiene identificado el código necesario para la migración y se avanza en ella. Se han tenido muchos requerimientos adicionales actualmente por lo que se retrasa un poco en su construcción 25/06/2025: Se termina la migracion a python para el flujo de la funcionalidad de indexar lote y se realizaron pruebas de funcionalidad | R16: true
A17: Alejandro | B17: Interno-H3 | C17: Automatización y migración de lógica a python (Acoplar lógica faltante en la migración de código) | F17: FINALIZADO | G17: 100 | H17: =IF(OR(J17="",K17="",K17<J17),0,NETWORKDAYS(J17,K17,Hoja2!$A$2:$A$53)) -> 0 | I17: 45826 | J17: 45869 | K17: 45834 | L17: 45870 | M17: =IF(OR(J17="",AND(L17="",TODAY()<J17),AND(L17<>"",L17<J17)),0, IF(L17="", NETWORKDAYS(J17,TODAY(),Hoja2!$A$2:$A$53), NETWORKDAYS(J17,L17,Hoja2!$A$2:$A$53) ) ) -> 2 | O17: 45870 | Q17: 31/07/2025 Se inicializa el trabajo de acoplamiento de la lógica del módulo con el proceso de clasificación después de tener un modelo entrenado para la tarea | R17: true
A18: Alejandro | B18: Interno-H4 | C18: Automatización y migración de lógica a python (Migración de código para la funcionalidad en donde se consume un web service para la asignación de casos a HRUA) | F18: FINALIZADO | G18: 100 | H18: =IF(OR(J18="",K18="",K18<J18),0,NETWORKDAYS(J18,K18,Hoja2!$A$2:$A$53)) -> 0 | I18: 45833 | J18: 45841 | K18: 45839 | L18: 45845 | M18: =IF(OR(J18="",AND(L18="",TODAY()<J18),AND(L18<>"",L18<J18)),0, IF(L18="", NETWORKDAYS(J18,TODAY(),Hoja2!$A$2:$A$53), NETWORKDAYS(J18,L18,Hoja2!$A$2:$A$53) ) ) -> 3 | O18: 45845 | Q18: 03/07/2025: Se construye los modelos relacionados, el agente y se le asigna el trabajo que corresponde a la funcionalidad en PHP, faltan migrar características y realizar modificaciones 07/07/2025: Se migra la lógica faltante y se realiza una prueba básica de flujo debido a que se conecta y consume un servicio web que en el ambiente local no se puede probar, por lo que esta a la espera de pasarlo al ambiente de QA(Pruebas) para probar definitivamente todas las características | R18: true
A19: Alejandro | B19: Interno-H5 | C19: Automatización y migración de lógica a python (Migración de lógica para el cruce de datos existentes ya en las distintas tablas de pre radicación) | F19: FINALIZADO | G19: 100 | H19: =IF(OR(J19="",K19="",K19<J19),0,NETWORKDAYS(J19,K19,Hoja2!$A$2:$A$53)) -> 1 | I19: 45845 | J19: 45845 | K19: 45845 | L19: 45845 | M19: =IF(OR(J19="",AND(L19="",TODAY()<J19),AND(L19<>"",L19<J19)),0, IF(L19="", NETWORKDAYS(J19,TODAY(),Hoja2!$A$2:$A$53), NETWORKDAYS(J19,L19,Hoja2!$A$2:$A$53) ) ) -> 1 | O19: 45845 | Q19: 07/07/2025: Se migra toda la lógica de la funcionalidad y se realizan pruebas | R19: true
A20: Alejandro | B20: Interno-H6 | C20: Automatización y migración de lógica a python | F20: FINALIZADO | G20: 100 | H20: =IF(OR(J20="",K20="",K20<J20),0,NETWORKDAYS(J20,K20,Hoja2!$A$2:$A$53)) -> 3 | I20: 45854 | J20: 45854 | K20: 45858 | M20: =IF(OR(J20="",AND(L20="",TODAY()<J20),AND(L20<>"",L20<J20)),0, IF(L20="", NETWORKDAYS(J20,TODAY(),Hoja2!$A$2:$A$53), NETWORKDAYS(J20,L20,Hoja2!$A$2:$A$53) ) ) -> 230 | Q20: 16/07/2025 Se identifican los docuemntos a clasificar. Se empieza con la actividad de elección y la forma en que se le dará tratamiento a los documentos 17/07/2025 Se crean queries y scripts necesarios para la descarga y conversión a pdf desde el repositorio S3 de los archivos necesarios para el entrenamiento del modelo | R20: true
A21: Alejandro | B21: REQ-1-3 | C21: Tratamiento especial al radicar trámites de vejez (Fase de desarrollo para la creacion de código para la implementación del requerimiento) | D21: Se está a la espera de la solicitud formal por parte del cliente | F21: CANCELADO | H21: =IF(OR(J21="",K21="",K21<J21),0,NETWORKDAYS(J21,K21,Hoja2!$A$2:$A$53)) -> 0 | M21: =IF(OR(J21="",AND(L21="",TODAY()<J21),AND(L21<>"",L21<J21)),0, IF(L21="", NETWORKDAYS(J21,TODAY(),Hoja2!$A$2:$A$53), NETWORKDAYS(J21,L21,Hoja2!$A$2:$A$53) ) ) -> 0 | Q21: 24/06/2025: El requerimiento esta en pauisa hasta que se identifique la viabilidad de la reforma pensional 06/03/2026 Hasta el momento no se ha obtenido respuesta del parte del cliente | R21: False
A22: Alejandro | B22: REQ-3-2 | C22: Cambios técnicos en aplicativo imagine para proceso de mesa de control documental solicitud de pensión (Creación de método para el cpnsumo como servicio e identificación de código a modificar y procesos que clausurar) | D22: desarrollo de la mesa de validación documental con inteligencia artificial en Filenet que implica las siguientees actividades: Se debe retirar la bandeja de imagine Validación Mesa de Control Unificada ya que la validación de documentos se realizará a través de filenet. Dado que se requiere conservar otras funciones adicionales a la bandeja de validación en el software de imagine que depende de la validación documental, se les notificara a través del siguiente web service cada vez que una solicitud documental (Paquete de documentos relacionado a los diferentes riesgos) haya finalizado el proceso de validación: | F22: FINALIZADO | G22: 100 | H22: =IF(OR(J22="",K22="",K22<J22),0,NETWORKDAYS(J22,K22,Hoja2!$A$2:$A$53)) -> 3 | I22: 45834 | J22: 45834 | K22: 45839 | L22: 45840 | M22: =IF(OR(J22="",AND(L22="",TODAY()<J22),AND(L22<>"",L22<J22)),0, IF(L22="", NETWORKDAYS(J22,TODAY(),Hoja2!$A$2:$A$53), NETWORKDAYS(J22,L22,Hoja2!$A$2:$A$53) ) ) -> 4 | O22: 45840 | Q22: 26/06/2025: Se construye nuevo método de consumo y la lógica para tratamiento de trámites para cerrar mesa unificada 26/06/2025: Se cierra bandeja de mesa unificada 26/06/2025: Se realizan preubas de consumo al nuevo método del servicio 02/07/2025: Se añade código para realizar tratamientos de envío de eventos de normalización si el trámite lo permite 02/07/2025: Se inicia la fase de pruebas con una aún no satisfactoria 03/07/2025: Se realiza correcciones en el flujo y se realiza prueba con resultado satisfactorio, Se está a la espera de realizar pruebas junto con el cliente 29/07/2025 El requerimiento había estado parado debido a la falta de pruebas por parte de protección. Se encuentra la neesidad de realizar ciertas modificaciones 30/07/2025 Se realizan las modificaciones identificadas yse informa nuevamente para la realización de pruebas 31/07/2025 Se crea y comparte documentación técnica del proceso 01/08/2025 Se realizan pruebas satisfactorias y se esta a la espera del cliente para pasar a producción | R22: true
A23: Alejandro | B23: REQ-4-2 | C23: Migracion de servidor y actualizaciones de tecnologías (Acompañamiento de pruebas y validaciones con el cliente) | D23: Migración de servicios y tecnologías para cumplir con requerimientos de seguridad y calidad | F23: FINALIZADO | G23: 100 | H23: =IF(OR(J23="",K23="",K23<J23),0,NETWORKDAYS(J23,K23,Hoja2!$A$2:$A$53)) -> 46 | I23: 45833 | J23: 45833 | K23: 45901 | L23: 45901 | M23: =IF(OR(J23="",AND(L23="",TODAY()<J23),AND(L23<>"",L23<J23)),0, IF(L23="", NETWORKDAYS(J23,TODAY(),Hoja2!$A$2:$A$53), NETWORKDAYS(J23,L23,Hoja2!$A$2:$A$53) ) ) -> 46 | O23: 45901 | Q23: 25/06/2025: Se realizan validaciones para pruebas de servicios generados desde protección 26/06/2025: Se realizan validaciones para pruebas de servicios generados desde protección 01/07/2025: Se realizan validaciones para pruebas de servicios generados desde protección 09/07/2025: Se realizan validaciones para pruebas de servicios generados desde protección 01/09/2025: Setermianron las pruebas por parte del cliente y se gestiona nueva tarea en el que IMAGINE es el encargado | R23: true
A24: Alejandro | B24: Interno-H7 | C24: Automatización y migración de lógica a python ( Creación de script para entrenamiento del modelo de clasificación) | F24: FINALIZADO | G24: 100 | H24: =IF(OR(J24="",K24="",K24<J24),0,NETWORKDAYS(J24,K24,Hoja2!$A$2:$A$53)) -> 5 | I24: 45855 | J24: 45855 | K24: 45861 | L24: 45870 | M24: =IF(OR(J24="",AND(L24="",TODAY()<J24),AND(L24<>"",L24<J24)),0, IF(L24="", NETWORKDAYS(J24,TODAY(),Hoja2!$A$2:$A$53), NETWORKDAYS(J24,L24,Hoja2!$A$2:$A$53) ) ) -> 12 | O24: 45870 | Q24: 17/07/2025 Se realiza reunión con Danilo para identificar enfoque de manejo de dependencias y entre otros temas 18/07/2025 Se construye con ayuda de la IA varios scripts que se usaran como modelo e inferencia del proyecto. No se han probado ni tampoco se han acoplado al sistema de agentes 28/07/2025 Se había detenido la actividad hasta tener todos los recursos al menos en el sistema local para trabajar el modelo de entrenamiento, en este caso faltaba los archivos 28/07/2025 Se realizan correcciones, pruebas y generación de los primeros 5 recorridos completos por todo el dataset de entrenamiento y se obtiene un modelo con 84% de fiabilidad. Cada recorrido tarda alrededor de 2 horas y genera un esfuerzo moderado al PC, por lo que las demás actividades se ven un poco afectadas, se espera conseguir un modelo de mas de 90% de fiabilidad y por lo que serán necesario más entrenamiento, análisis y recorridos por toda la data 29/07/2025 Se siguen ejecutando el entrenamiento para la búsqueda de un modelo más fiable 01/08/2025 Se modifica el script de entrenamiento añadiendo fine-tune y transformaciones con la esperanza de construír un modelo más fiable, pero después de 48 horas de entrenamiento, el modelo se estanca en validación y con los archivos actuales no puede aumentar su aprendizaje, esto es debido a que en algunos tipos documentales no existen suficientes muestras | R24: true
A25: Alejandro | B25: Interno-2-1 | C25: Requerimiento de infraestructura para habilitar monitoreo y encapsulamiento a través de contenedores de aplicaciones ( Informe de requerimientos al área encargada, instalación y prueba de funcionamiento de librerías de monitoreo y de contenedores) | D25: Instalación de dependencias, scripts y demas para dos procesos, uno de auditoria de accesos y otro de encapsulación de aplicaciones a través de contenedores docker | F25: FINALIZADO | G25: 100 | H25: =IF(OR(J25="",K25="",K25<J25),0,NETWORKDAYS(J25,K25,Hoja2!$A$2:$A$53)) -> 5 | I25: 45862 | J25: 45862 | K25: 45868 | L25: 45894 | M25: =IF(OR(J25="",AND(L25="",TODAY()<J25),AND(L25<>"",L25<J25)),0, IF(L25="", NETWORKDAYS(J25,TODAY(),Hoja2!$A$2:$A$53), NETWORKDAYS(J25,L25,Hoja2!$A$2:$A$53) ) ) -> 21 | O25: 45894 | P25: 45894 | Q25: 24/07/2025 Se genera informe para la instalación de dependencias al área encargada, incluyendo información técnica y necesidades en las siguientes solicitudes de protección: SR1267449 SR1267909 SR1267937 25/08/2025 Se habia detenido el proceso debido a la falta de instalación por parte del cliente de las librerias. Se trabajo en la configuración de los dos ambientes el 22 y 25 de agosto, día en el que se completo el requerimiento | R25: true
A26: Alejandro | B26: REQ-8-1 | C26: Definición y cambio de flujo en la activación agente - investigación (Análisis de requerimientos, código y modificación de módulo para cumplirnecesidades) | D26: Modificación del flujo, cargue y almacenamiento de datos de la fase de investigación. Además, de envió de esa información a filenet | F26: FINALIZADO | G26: 100 | H26: =IF(OR(J26="",K26="",K26<J26),0,NETWORKDAYS(J26,K26,Hoja2!$A$2:$A$53)) -> 4 | I26: 45868 | J26: 45868 | K26: 45873 | L26: 45870 | M26: =IF(OR(J26="",AND(L26="",TODAY()<J26),AND(L26<>"",L26<J26)),0, IF(L26="", NETWORKDAYS(J26,TODAY(),Hoja2!$A$2:$A$53), NETWORKDAYS(J26,L26,Hoja2!$A$2:$A$53) ) ) -> 3 | Q26: 30/07/2025 Se inicia el proceso de análisis para la parte de modificación de cargue y se informa de lo encontrado 01/08/2025 Se realiza el análisis del proceso y de los posibles cambios. Se comparte la situación y se está a la espera de una respuesta por parte del cliente para empezar a cambiar el proceso | R26: true
A27: Alejandro | B27: REQ-8-2 | C27: Definición y cambio de flujo en la activación agente - investigación (Cambio del proceso y desarrollo del requerimiento) | D27: Modificación del flujo, cargue y almacenamiento de datos de la fase de investigación. Además, de envió de esa información a filenet | E27: Cambio del proceso y desarrollo del requerimiento | F27: CANCELADO | H27: =IF(OR(J27="",K27="",K27<J27),0,NETWORKDAYS(J27,K27,Hoja2!$A$2:$A$53)) -> 0 | M27: =IF(OR(J27="",AND(L27="",TODAY()<J27),AND(L27<>"",L27<J27)),0, IF(L27="", NETWORKDAYS(J27,TODAY(),Hoja2!$A$2:$A$53), NETWORKDAYS(J27,L27,Hoja2!$A$2:$A$53) ) ) -> 0 | Q27: 06/03/2026 Hasta el momento no se ha obtenido respuesta del parte del cliente | R27: False
A28: Alejandro | B28: Interno-H8_1 | C28: Creación de un sistema distribuido registro - puerta de enlace - aplicacion, todo dockerizado que sirva como estructura base a las aplicaciones por venir y la que se esta trabajando actualmente de sistema de agentes inteligentes | F28: FINALIZADO | G28: 100 | H28: =IF(OR(J28="",K28="",K28<J28),0,NETWORKDAYS(J28,K28,Hoja2!$A$2:$A$53)) -> 3 | I28: 45894 | J28: 45894 | K28: 45896 | L28: 45896 | M28: =IF(OR(J28="",AND(L28="",TODAY()<J28),AND(L28<>"",L28<J28)),0, IF(L28="", NETWORKDAYS(J28,TODAY(),Hoja2!$A$2:$A$53), NETWORKDAYS(J28,L28,Hoja2!$A$2:$A$53) ) ) -> 3 | O28: 45896 | Q28: 01/08/2025 Se habían tenido muchas dificultades debido a las configuraciones del servidor y del mismo docker, pero ya se tiene la plataforma base y se realizarán pruebas con otros contenedores para identificar no solo su funcionamiento, sino también la forma correcta de identificar volumenes de memoria ajenos a la máquina dockerizada, ta les como el local del servidor y los repositorios externos | R28: true
A29: Alejandro | B29: REQ-9-1 | C29: AJUSTES EN CAMPOS DE GESTION DE CASOS INGESTA MANUAL DE FECHA CORRESPONDIENTE AL PAGO DEL PREVISIONAL DE AUXILIOS FUNERARIOS VISUALIZACION DE LA FECHA PAGO PREVISIONAL EN LA PESTAÑA FLUJOS PREVISIONALES ALERTA TRAMITE INVALIDEZ | D29: SOLICITUD MEJORAS IMAGINE PORCESO AUXILIOS FUNERARIOS | F29: FINALIZADO | G29: 100 | H29: =IF(OR(J29="",K29="",K29<J29),0,NETWORKDAYS(J29,K29,Hoja2!$A$2:$A$53)) -> 5 | I29: 45866 | J29: 45866 | K29: 45870 | L29: 45870 | M29: =IF(OR(J29="",AND(L29="",TODAY()<J29),AND(L29<>"",L29<J29)),0, IF(L29="", NETWORKDAYS(J29,TODAY(),Hoja2!$A$2:$A$53), NETWORKDAYS(J29,L29,Hoja2!$A$2:$A$53) ) ) -> 5 | O29: 45870 | R29: true
A30: Alejandro | B30: Interno-H9 | C30: Creación de un sistema distribuido registro - puerta de enlace - aplicacion, todo dockerizado que sirva como estructura base a las aplicaciones por venir y la que se esta trabajando actualmente de sistema de agentes inteligentes | F30: FINALIZADO | G30: 100 | H30: =IF(OR(J30="",K30="",K30<J30),0,NETWORKDAYS(J30,K30,Hoja2!$A$2:$A$53)) -> 5 | I30: 45896 | J30: 45896 | K30: 45902 | L30: 45902 | M30: =IF(OR(J30="",AND(L30="",TODAY()<J30),AND(L30<>"",L30<J30)),0, IF(L30="", NETWORKDAYS(J30,TODAY(),Hoja2!$A$2:$A$53), NETWORKDAYS(J30,L30,Hoja2!$A$2:$A$53) ) ) -> 5 | O30: 45902 | R30: true
A31: Alejandro | B31: Interno-H10 | C31: Desacople de agente de clasificación y su lógica y acople del mismo dento del sistema distribuido. Adicionalmente, acople de la plataforma de agentes y todas las otras aplicaciones del sistema | F31: FINALIZADO | G31: 100 | H31: =IF(OR(J31="",K31="",K31<J31),0,NETWORKDAYS(J31,K31,Hoja2!$A$2:$A$53)) -> 3 | I31: 45902 | J31: 45902 | K31: 45904 | L31: 45903 | M31: =IF(OR(J31="",AND(L31="",TODAY()<J31),AND(L31<>"",L31<J31)),0, IF(L31="", NETWORKDAYS(J31,TODAY(),Hoja2!$A$2:$A$53), NETWORKDAYS(J31,L31,Hoja2!$A$2:$A$53) ) ) -> 2 | O31: 45903 | R31: true
A32: Alejandro | B32: Interno-H12 | C32: Generación de ambiente local a través de lo generado en el ambiente de pruebas, para facilitar la construcción de otros servicios | F32: FINALIZADO | G32: 100 | H32: =IF(OR(J32="",K32="",K32<J32),0,NETWORKDAYS(J32,K32,Hoja2!$A$2:$A$53)) -> 2 | I32: 45904 | J32: 45908 | K32: 45909 | L32: 45908 | M32: =IF(OR(J32="",AND(L32="",TODAY()<J32),AND(L32<>"",L32<J32)),0, IF(L32="", NETWORKDAYS(J32,TODAY(),Hoja2!$A$2:$A$53), NETWORKDAYS(J32,L32,Hoja2!$A$2:$A$53) ) ) -> 1 | R32: true
A33: Alejandro | B33: Interno-H11 | C33: Generación de servicio para el tratamiento de datos usando agentes | F33: FINALIZADO | G33: 100 | H33: =IF(OR(J33="",K33="",K33<J33),0,NETWORKDAYS(J33,K33,Hoja2!$A$2:$A$53)) -> 4 | I33: 45904 | J33: 45909 | K33: 45912 | L33: 45918 | M33: =IF(OR(J33="",AND(L33="",TODAY()<J33),AND(L33<>"",L33<J33)),0, IF(L33="", NETWORKDAYS(J33,TODAY(),Hoja2!$A$2:$A$53), NETWORKDAYS(J33,L33,Hoja2!$A$2:$A$53) ) ) -> 8 | O33: 45918 | Q33: 12/09/2025 Desde el día Mierrcoles 10 de sep no se avanza debido a que se debía de trabajar en requerimientos de mayor impórtancia para el cliente 19/09/2025 Se volvio a retomar el días 15 en la tarde, cuando se termina los pendientes de mayor importancia, terminando sus pruebas el 18 | R33: true
A34: Alejandro | B34: Interno2-1 | C34: Se identificaron, a través de un informe recién creado que había un hueco en la información. | D34: Corrección de datos guardados en BD | F34: FINALIZADO | G34: 100 | H34: =IF(OR(J34="",K34="",K34<J34),0,NETWORKDAYS(J34,K34,Hoja2!$A$2:$A$53)) -> 2 | I34: 45909 | J34: 45910 | K34: 45911 | L34: 45911 | M34: =IF(OR(J34="",AND(L34="",TODAY()<J34),AND(L34<>"",L34<J34)),0, IF(L34="", NETWORKDAYS(J34,TODAY(),Hoja2!$A$2:$A$53), NETWORKDAYS(J34,L34,Hoja2!$A$2:$A$53) ) ) -> 2 | O34: 45911 | Q34: 12/09/2025 Se identifica los datos, se correlacionan entre sí y se completa 3000 datos de 4000 | R34: true
A35: Alejandro | B35: Interno2-2 | C35: Se identificaron, a través de un informe recién creado que había un hueco en la información que debe ser corregido. | D35: Corrección de datos guardados en BD | F35: FINALIZADO | G35: 100 | H35: =IF(OR(J35="",K35="",K35<J35),0,NETWORKDAYS(J35,K35,Hoja2!$A$2:$A$53)) -> 2 | I35: 45909 | J35: 45910 | K35: 45911 | L35: 45911 | M35: =IF(OR(J35="",AND(L35="",TODAY()<J35),AND(L35<>"",L35<J35)),0, IF(L35="", NETWORKDAYS(J35,TODAY(),Hoja2!$A$2:$A$53), NETWORKDAYS(J35,L35,Hoja2!$A$2:$A$53) ) ) -> 2 | O35: 45911 | Q35: 12/09/2025 Se identifica los datos, se correlacionan entre sí y se completa 3000 datos de 4000 | R35: true
A36: Alejandro | B36: REQ-10-1 | C36: Se necesita la descarga de imagenes según varios filtros y necesidades del usuario | D36: Descarga de archivos relacionados a un cargue de datos, que identifican tipo de documento, año y a quien pertenece | F36: FINALIZADO | G36: 100 | H36: =IF(OR(J36="",K36="",K36<J36),0,NETWORKDAYS(J36,K36,Hoja2!$A$2:$A$53)) -> 4 | I36: 45909 | J36: 45910 | K36: 45915 | L36: 45915 | M36: =IF(OR(J36="",AND(L36="",TODAY()<J36),AND(L36<>"",L36<J36)),0, IF(L36="", NETWORKDAYS(J36,TODAY(),Hoja2!$A$2:$A$53), NETWORKDAYS(J36,L36,Hoja2!$A$2:$A$53) ) ) -> 4 | O36: 45915 | Q36: 12/09/2025 Se realiza la descarga y se esta en la espera de habilitación del punto de carga. Además, se indica que se debe de hacer un proceso de descarga adicional 19/09/2025 Se han realizado reuniones a lo largo de la semana para la habilitación de un punto de cargue por parte del cliente | R36: true
A37: Alejandro | B37: Interno-H13 | C37: Generación de servicio para el procesamiento de documentos y generación de un documento general | D37: Automatización de tarea para el proceso de cambios de fondos de cesantías | F37: FINALIZADO | G37: 100 | H37: =IF(OR(J37="",K37="",K37<J37),0,NETWORKDAYS(J37,K37,Hoja2!$A$2:$A$53)) -> 6 | I37: 45918 | J37: 45919 | K37: 45926 | L37: 45926 | M37: =IF(OR(J37="",AND(L37="",TODAY()<J37),AND(L37<>"",L37<J37)),0, IF(L37="", NETWORKDAYS(J37,TODAY(),Hoja2!$A$2:$A$53), NETWORKDAYS(J37,L37,Hoja2!$A$2:$A$53) ) ) -> 6 | O37: 45926 | Q37: 22/09/2025 Este día solo se trabajo en la migración 23/09/2025 Se retomo el trabajo nuevamente 28/10/2025 Se entrega todo el proyeecto incluyendo este modulo de generación de archivo | R37: true
A38: Alejandro | B38: REQ-11-1 | C38: Se necesita organizar una instancia de AWS, de tal modo que su ambiente quedé diospuesto para funcionar en producción | D38: Ambientación de instancia AWS para migración | F38: CANCELADO | G38: 85 | H38: =IF(OR(J38="",K38="",K38<J38),0,NETWORKDAYS(J38,K38,Hoja2!$A$2:$A$53)) -> 8 | I38: 45910 | J38: 45922 | K38: 45931 | M38: =IF(OR(J38="",AND(L38="",TODAY()<J38),AND(L38<>"",L38<J38)),0, IF(L38="", NETWORKDAYS(J38,TODAY(),Hoja2!$A$2:$A$53), NETWORKDAYS(J38,L38,Hoja2!$A$2:$A$53) ) ) -> 184 | Q38: 21/09/2025 Se habilitan todos los accesos para el trabajo en el servidor 23/09/2025 Se paro la ejecución debido a tareas con mayor prioridad 07/10/2025 Se empieza de nuevo con la ejecucción de la migración 10/10/2025 Se encuentra problemas con la comunicación a la base de datos 15/10/2025 Se genera una nueva instancia de bases de datos que sirva de pruebas para el nuevo ambiente 05/11/2025 Debido a nueva directiva se instancia una copia del ambiente de pruebas para confugurarla y ambientarla para producción 06/03/2026 Se estaba ambientando una instancia completamente nueva para la migración, pero el proceso se cancelo y se reformulo, esto debido a que se requerían realizar la menor cantidad de pruebas posibles, por lo que se clonó el servidor de pruebas QA que serviría de base para la migración | R38: False
A39: Alejandro | B39: Interno-H14 | C39: Creación de lógica y vista para la aprobación y rechazos de documentos cargados | D39: Automatización de tarea para el proceso de cambios de fondos de cesantías | F39: FINALIZADO | G39: 100 | H39: =IF(OR(J39="",K39="",K39<J39),0,NETWORKDAYS(J39,K39,Hoja2!$A$2:$A$53)) -> 7 | I39: 45929 | J39: 45929 | K39: 45937 | L39: 45958 | M39: =IF(OR(J39="",AND(L39="",TODAY()<J39),AND(L39<>"",L39<J39)),0, IF(L39="", NETWORKDAYS(J39,TODAY(),Hoja2!$A$2:$A$53), NETWORKDAYS(J39,L39,Hoja2!$A$2:$A$53) ) ) -> 21 | O39: 45958 | Q39: 30/09/2025 Este día solo se decdico la mitad del tiempo debido a camnio de prioridades. Se trabajará en el proyecto a medida que se vaya avanzando con las demás tareas 03/10/2025 Debido a la migración, el trabajo se ve reducido a menos de 2 horas diarias para la terminación de este protyecto 03/10/2025 Se entrega avance y se identifia procesos de mejoras y de añadir operativas para guardar información para cosos de rechazo y de análisis de datos 14/10/2025 Se entrega avance enfocado en las mejoras de procesos indicadas en la entrega anterior 28/10/2025 Se entrega todo el proyeecto incluyendo este modulo y mejoras continuas para incrementarla satisfacción y la operatividad | R39: true
A40: Alejandro | B40: REQ-11-2 | C40: Se necesita la asociación de registros relacionados con pagos de AUF | D40: Relacionar pagos de auxilios no cargados en IMAGINE | F40: FINALIZADO | G40: 100 | H40: =IF(OR(J40="",K40="",K40<J40),0,NETWORKDAYS(J40,K40,Hoja2!$A$2:$A$53)) -> 3 | I40: 45930 | J40: 45930 | K40: 45932 | L40: 45932 | M40: =IF(OR(J40="",AND(L40="",TODAY()<J40),AND(L40<>"",L40<J40)),0, IF(L40="", NETWORKDAYS(J40,TODAY(),Hoja2!$A$2:$A$53), NETWORKDAYS(J40,L40,Hoja2!$A$2:$A$53) ) ) -> 3 | O40: 45932 | P40: 45932 | Q40: 2/10/2025 Se genera informe de las actividades y de gestión con los casos que se necesitaban actualizar | R40: true
...

Sheet FINALIZADOS  despues de actu, i
A1: Asignado a | B1: ID REQ | C1: Requerimiento | D1: Descripcion req | E1: Actividad | F1: ESTADO | G1: % AVANCE | H1: dias estimados | I1: F.Asignado | J1: Fecha inicio | K1: F. estimada de entrega | L1: Finalizado | M1: Dias | N1: FECHA PASO A TEST | O1: FECHA PASO A PRODUCCION | P1: OBSERVACIONES
A2: Alejandro Cardona Ocampo | B2: REQ-1-1 | C2: Tratamiento especial al radicar trámites de vejez | D2: Se está a la espera de la solicitud formal por parte del cliente | E2: Revision de flujo y código | F2: FINALIZADO | G2: 1 | H2: 1 | I2: 45826 | J2: 45827 | K2: 45827 | L2: 45827 | M2: =IF(ISBLANK(L2), NETWORKDAYS(J2, TODAY(),Hoja2!$A$1:$A$18), NETWORKDAYS(J2, L2, Hoja2!$A$1:$A$18)) -> 1 | P2: 19/06/2025 Se identifico el código a intervenir y con el que trabajar en el requerimiento
A3: Alejandro Cardona Ocampo | B3: REQ-1-2 | C3: Tratamiento especial al radicar trámites de vejez | D3: Se está a la espera de la solicitud formal por parte del cliente | E3: Reunión con las partes interesadas para identificar los inputs de trabajo | F3: FINALIZADO | G3: 1 | H3: 1 | I3: 45827 | J3: 45832 | K3: 45832 | L3: 45832 | M3: =IF(ISBLANK(L3), NETWORKDAYS(J3, TODAY(),Hoja2!$A$1:$A$18), NETWORKDAYS(J3, L3, Hoja2!$A$1:$A$18)) -> 1 | P3: 24/06/2025: Se reune con las partes interesadas, se identifican los requisitos, necesidades y material de trabajo, pero se suspende el requerimiento hasta nuevo aviso
A4: Alejandro Cardona Ocampo | B4: REQ-2-1 | C4: Creación de reporte de AUF para identificación de pagos, creación de opción de cargue masivo para cambio de bandejas y creación de opción de consulta de pagos | D4: Creación de Herramientas adicionales para el tratamiento de información y flujo en el módulo de auxilios funerarios | E4: Creación de script para generar reporte de pagos de auxilios funerarios y la vista para su consumo | F4: FINALIZADO | G4: 1 | H4: 1 | I4: 45832 | J4: 45839 | K4: 45833 | L4: 45839 | M4: =IF(ISBLANK(L4), NETWORKDAYS(J4, TODAY(),Hoja2!$A$1:$A$18), NETWORKDAYS(J4, L4, Hoja2!$A$1:$A$18)) -> 1 | N4: 45839 | O4: 45853 | P4: 24/06/2025: Se realiza reunión para la identificación de nuevos requisitos 01/07/2025: Se realiza vista para el consumo y parte de la lóigica para la creación del reporte 01/07/2025: Se está a la espera de validar la información del reporte debido a que se nos envía 2 reportes con estructuras distintas 09/07/2025: Se realiza reunión con las partes interesadas y se acuerda en agregar información obtenida de distintas fuentes al formulario 15/07/2025: Se realizaron aún más cambios propuestos por el usuario y correcciones de fallas en el funcionamiento 15/07/2025: Se pasa a producción
A5: Alejandro Cardona Ocampo | B5: REQ-2-2 | C5: Creación de reporte de AUF para identificación de pagos, creación de opción de cargue masivo para cambio de bandejas y creación de opción de consulta de pagos | D5: Creación de Herramientas adicionales para el tratamiento de información y flujo en el módulo de auxilios funerarios | E5: Creación de script para generar opción de consulta de pagos | F5: FINALIZADO | G5: 1 | H5: 2 | I5: 45839 | J5: 45839 | K5: 45840 | L5: 45848 | M5: =IF(ISBLANK(L5), NETWORKDAYS(J5, TODAY(),Hoja2!$A$1:$A$18), NETWORKDAYS(J5, L5, Hoja2!$A$1:$A$18)) -> 8 | N5: 45848 | O5: 45853 | P5: 09/07/2025: Se Había pospuesto la creación del código y se retoma el día 8 10/07/2025: Se termina el desarrollo y las pruebas e 10 con las modificaciones indicadas en la reunión 15/07/2025: Se realizaron aún más cambios propuestos por el usuario y correcciones de fallas en el funcionamiento 15/07/2025: Se pasa a producción
A6: Alejandro Cardona Ocampo | B6: REQ-2-3 | C6: Creación de reporte de AUF para identificación de pagos, creación de opción de cargue masivo para cambio de bandejas y creación de opción de consulta de pagos | D6: Creación de Herramientas adicionales para el tratamiento de información y flujo en el módulo de auxilios funerarios | E6: Creación de script para generar opción en el de cargue y procesado de datos | F6: FINALIZADO | G6: 1 | H6: 1 | I6: 45839 | J6: 45840 | K6: 45840 | L6: 45840 | M6: =IF(ISBLANK(L6), NETWORKDAYS(J6, TODAY(),Hoja2!$A$1:$A$18), NETWORKDAYS(J6, L6, Hoja2!$A$1:$A$18)) -> 1 | N6: 45840 | O6: 45853 | P6: 01/07/2025: Se realiza reunión para la identificación de nuevos requisitos 02/07/2025: Se Crea vista y lógica para el cargue de documentos y procesamiento de datos 02/07/2025: Se realizan pruebas de funcionamiento y se esta a la espera de que el cliente realice pruebas 15/07/2025: Se realizaron aún más cambios propuestos por el usuario y correcciones de fallas en el funcionamiento 15/07/2025: Se pasa a producción
A7: Alejandro Cardona Ocampo | B7: REQ-2-4 | C7: Creación de reporte de AUF para identificación de pagos, creación de opción de cargue masivo para cambio de bandejas y creación de opción de consulta de pagos | D7: Creación de Herramientas adicionales para el tratamiento de información y flujo en el módulo de auxilios funerarios | E7: Modificación de script para generar reporte de pagos de auxilios funerarios agregando distinta información y lógica para su construcción | F7: FINALIZADO | G7: 1 | H7: 1 | I7: 45847 | J7: 45847 | K7: 45848 | L7: 45848 | M7: =IF(ISBLANK(L7), NETWORKDAYS(J7, TODAY(),Hoja2!$A$1:$A$18), NETWORKDAYS(J7, L7, Hoja2!$A$1:$A$18)) -> 2 | N7: 45848 | O7: 45853 | P7: 10/07/2025: Se termina el desarrollo y las pruebas. Se está en espera del visto bueno para pasar a producción 14/07/2025: Se identifican a través de las pruebas de usuarios modificaciones y añadidos por hacer. Se realizan los debidos cambios y se entrega al cliente resultados para su validación 15/07/2025: Se realizaron aún más cambios propuestos por el usuario y correcciones de fallas en el funcionamiento 15/07/2025: Se pasa a producción
A8: Alejandro Cardona Ocampo | B8: REQ-3-1 | C8: Cambios técnicos en aplicativo imagine para proceso de mesa de control documental solicitud de pensión | D8: desarrollo de la mesa de validación documental con inteligencia artificial en Filenet que implica las siguientees actividades: Se debe retirar la bandeja de imagine Validación Mesa de Control Unificada ya que la validación de documentos se realizará a través de filenet. Dado que se requiere conservar otras funciones adicionales a la bandeja de validación en el software de imagine que depende de la validación documental, se les notificara a través del siguiente web service cada vez que una solicitud documental (Paquete de documentos relacionado a los diferentes riesgos) haya finalizado el proceso de validación: | E8: Reunión con las partes interesadas para identificación de requerimientos | F8: FINALIZADO | G8: 1 | H8: 1 | I8: 45832 | J8: 45832 | K8: 45832 | L8: 45832 | M8: =IF(ISBLANK(L8), NETWORKDAYS(J8, TODAY(),Hoja2!$A$1:$A$18), NETWORKDAYS(J8, L8, Hoja2!$A$1:$A$18)) -> 1 | P8: 24/06/2025: Se realiza reunión para realización de pruebas e identificación de requerimientos
A9: Alejandro Cardona Ocampo | B9: REQ-4-1 | C9: Migración de registros para tipos documentales gabinete 2 | E9: Identificación y failitación al cliente de los tipos documnetales | F9: FINALIZADO | G9: 1 | H9: 1 | I9: 45847 | J9: 45847 | K9: 45847 | L9: 45847 | M9: =IF(ISBLANK(L9), NETWORKDAYS(J9, TODAY(),Hoja2!$A$1:$A$18), NETWORKDAYS(J9, L9, Hoja2!$A$1:$A$18)) -> 1 | N9: 45847 | P9: 09/07/2025: Se indica al cliente los distintos tipos de documentación del gabinete 2
A10: Alejandro Cardona Ocampo | B10: REQ-5-1 | C10: Proyecto relacionado con las inconsistencias norma 2381 | E10: Identificación de método de consumo y generación de informe de resultados | F10: FINALIZADO | G10: 1 | H10: 1 | I10: 45849 | J10: 45849 | K10: 45849 | L10: 45849 | M10: =IF(ISBLANK(L10), NETWORKDAYS(J10, TODAY(),Hoja2!$A$1:$A$18), NETWORKDAYS(J10, L10, Hoja2!$A$1:$A$18)) -> 1 | P10: 09/07/2025: Se identifica los métodos de consumo posibles, su funcionamiento y se plasma junto con las respuestas a las dudas del cliente en un informe
A11: Alejandro Cardona Ocampo | B11: REQ-3-3 | C11: Cambios técnicos en aplicativo imagine para proceso de mesa de control documental solicitud de pensión | D11: desarrollo de la mesa de validación documental con inteligencia artificial en Filenet que implica las siguientees actividades: Se debe retirar la bandeja de imagine Validación Mesa de Control Unificada ya que la validación de documentos se realizará a través de filenet. Dado que se requiere conservar otras funciones adicionales a la bandeja de validación en el software de imagine que depende de la validación documental, se les notificara a través del siguiente web service cada vez que una solicitud documental (Paquete de documentos relacionado a los diferentes riesgos) haya finalizado el proceso de validación: | E11: Creación de otro método para consumo necesario para tratamiento de trámites de pruebas de protección | F11: FINALIZADO | G11: 1 | H11: 1 | I11: 45854 | J11: 45854 | K11: 45854 | L11: 45854 | M11: =IF(ISBLANK(L11), NETWORKDAYS(J11, TODAY(),Hoja2!$A$1:$A$18), NETWORKDAYS(J11, L11, Hoja2!$A$1:$A$18)) -> 1 | N11: 45854 | P11: 16/07/2025 Se realiza nuevo método de consumo para cerrar trámites con procesos documentales abiertos y asi, protección pueda ser pruebas de cierre de mesa unificada documental sin necesidad de tener procesos abiertos y con documentos
A12: Alejandro Cardona Ocampo | B12: REQ-6-1 | C12: Análisis y corrección de procesos de cargue e identificación de pagos de tipo de riesgo AUX | D12: Se identificaron errores de procesos de cargue que no están identificando correctamente el estado de un trámite en la bandeja de AUX. | E12: Análisis de la situación en Imagine | F12: FINALIZADO | G12: 1 | H12: 5 | I12: 45855 | J12: 45856 | K12: 45862 | L12: 45861 | M12: =IF(ISBLANK(K12), NETWORKDAYS(J12, TODAY(),Hoja2!$A$1:$A$18), NETWORKDAYS(J12, K12, Hoja2!$A$1:$A$18)) -> 5 | N12: 45861 | P12: 17/07/2025 Se realiza reunión para identificar las inconsistencias. Se está a la espera de datos de prueba y de análisis de los procesos para la verificación de los mismos 21/07/2025 Se Identificaron lógicas erroneas en el código que se corrigieron y otras lógicas de negocio que no, debido a que primero se deben de socializar los resultados antes de poder pensar en una solución 23/07/2025 Se genera informe de la situación, recomendaciones y procesos a seguir para brindar solución 23/07/2025 Se pasa los cambios que corregian errores a producción
A13: Alejandro Cardona Ocampo | B13: REQ-7-1 | C13: Mejoras en los modulos de Imagine | D13: Solicitud de protección para mejoras IMAGINE en el módulo de Auxilios funerarios | E13: Reunión con las partes interesadas e identificación de requerimientos | F13: FINALIZADO | G13: 1 | H13: 1 | I13: 45860 | J13: 45860 | K13: 45860 | L13: 45860 | M13: =IF(ISBLANK(L13), NETWORKDAYS(J13, TODAY(),Hoja2!$A$1:$A$18), NETWORKDAYS(J13, L13, Hoja2!$A$1:$A$18)) -> 1 | P13: 22/07/2025 Se realiza reunión para la identificación de requerimientos y necesidades del cliente 23/07/2025 Se comparte archivo de la solicitud
A14: Alejandro Cardona Ocampo | B14: Interno-H8 | C14: Automatización y migración de lógica a python | E14: Ejecuci[on y correcci[on de script y descarga de recursos necesarios para el entrenamiento del modelo de clasificaci[on | F14: FINALIZADO | G14: 1 | H14: 2 | I14: 45863 | J14: 45863 | K14: 45866 | L14: 45866 | M14: =IF(ISBLANK(L14), NETWORKDAYS(J14, TODAY(),Hoja2!$A$1:$A$18), NETWORKDAYS(J14, L14, Hoja2!$A$1:$A$18)) -> 2 | P14: 25/07/2025 Se realiza la descarga de 80000 archivos no sin antes reestructurar el script y acoplarlo para no sobrecargar los procesos y que funcionara 25/07/2025 Se empieza proceso de carga en local, todo esto debido a que no se puede generar el modelo de entrenamiento en el servidor por capacidad 25/07/2025 Se termina el proceso de carga en local

Sheet Hoja2
A1: 45292 | B1: Año Nuevo
A2: 45299 | B2: Día de los Reyes Magos
A3: 45376 | B3: Día de San José
A4: 45379 | B4: Jueves Santo (Semana Santa)
A5: 45380 | B5: Viernes Santo (Semana Santa)
A6: 45413 | B6: Día del Trabajo
A7: 45425 | B7: Día de la Ascensión
A8: 45446 | B8: Corpus Christi
A9: 45453 | B9: Sagrado Corazón
A10: 45474 | B10: San Pedro y San Pablo
A11: 45493 | B11: Día de la Independencia
A12: 45511 | B12: Batalla de Boyacá
... A53: 46381 | B53: Navidad

Sheet ASISTENCIA
A1: ASISTENCIA DAYLI
A3: INTEGRANTE | B3: 45596 | C3: 45597 | D3: 45601 | E3: 45602 | F3: 45603 | G3: 45604 | H3: 45608 | I3: 45609 | J3: 45610 | K3: 45611 | L3: 45614 | M3: 45615 | N3: 45616 | O3: 45617 | P3: 45618 | Q3: 45621 | R3: 45622 | S3: 45623 | T3: 45624 | U3: 45625 | V3: 45628 | W3: 45629 | X3: 45630 | Y3: 45631 | Z3: 45632 | AA3: 45635 | AB3: 45636 | AC3: 45637 | AD3: 45638 | AE3: 45639 | AF3: 45642 | AG3: 45643 | AH3: 45644 | AI3: 45645 | AJ3: 45646 | AK3: 45649 | AL3: 45650 | AM3: 45652 | AN3: 45653 | AO3: 45656 | AP3: 45656 | AQ3: 45664 | AR3: 45665 | AS3: 45666 | AT3: 45667 | AU3: 45670 | AV3: 45671 | AW3: 45672 | AX3: 45673 | AY3: 45674 | AZ3: 45677 | BA3: 45678 | BB3: 45679 | BC3: 45680 | BD3: 45681 | BE3: 45684 | BF3: 45685 | BG3: 45686 | BH3: 45687 | BI3: 45688 | BJ3: 45691 | BK3: 45692 | BL3: 45693 | BM3: 45694 | BN3: 45695 | BO3: 45698 | BP3: 45699 | BQ3: 45700 | BR3: 45701 | BS3: 45702 | BT3: 45705 | BU3: 45706 | BV3: 45707 | BW3: 45708 | BX3: 45709 | BY3: 45712 | BZ3: 45713 | CA3: 45714 | CB3: 45715 | CC3: 45716 | CD3: 45719 | CE3: 45720 | CF3: 45721 | CG3: 45722 | CH3: 45723 | CI3: 45726 | CJ3: 45727 | CK3: 45728 | CL3: 45729 | CM3: 45730 | CN3: 45733 | CO3: 45734 | CP3: 45735 | CQ3: 45736 | CR3: 45737 | CS3: 45741
A4: DANILO RAMIREZ | B4: SI | C4: no (Dia de la familia) | D4: SI | E4: SI | F4: SI | G4: SI | H4: SI | I4: SI | J4: SI | K4: SI | L4: SI | M4: SI | N4: SI | O4: No hubo sesion | P4: SI | Q4: SI | R4: SI | S4: SI | T4: SI | U4: NO | V4: SI | W4: SI | X4: SI | Y4: SI | Z4: SI | AA4: SI | AB4: SI | AC4: SI | AD4: SI | AE4: No hubo sesión | AF4: SI | AG4: SI | AH4: SI | AI4: SI | AJ4: SI | AK4: SI | AL4: NO HUBO SESION | AM4: NO | AN4: NO | AO4: SI | AP4: NO HAY SESION | AQ4: SI | AR4: SI | AS4: NO HAY SESION | AT4: SI | AU4: SI | AV4: SI | AW4: SI | AX4: SI | AY4: NO HAY SESION | AZ4: SI | BA4: SI | BB4: SI | BC4: SI | BD4: SI | BE4: SI | BF4: SI | BG4: SI | BH4: SI | BI4: SI | BJ4: NO HAY SESION | BK4: Vacaciones | BL4: Vacaciones | BM4: Vacaciones | BN4: Vacaciones | BO4: Vacaciones | BP4: Vacaciones | BQ4: Vacaciones | BR4: SI | BS4: SI | BT4: SI | BU4: SI | BV4: SI | BW4: SI | BX4: SI | BY4: SI | BZ4: SI | CA4: SI | CB4: SI | CC4: SI | CD4: SI | CE4: SI | CF4: SI | CI4: No hobo sesion por caida de los sitios. | CS4: SI
A5: JAIRO NIÑO | B5: SI | C5: SI | D5: SI | E5: SI | F5: SI | G5: SI | H5: SI | I5: SI | J5: SI | K5: SI | L5: Vacaciones | M5: Vacaciones | N5: Vacaciones | O5: Vacaciones | P5: Vacaciones | Q5: SI | R5: SI | S5: SI | T5: SI | U5: SI | V5: SI | W5: SI | X5: SI | Y5: SI | Z5: SI | AA5: SI | AB5: SI | AC5: SI | AD5: SI | AF5: SI | AG5: SI | AH5: SI | AI5: SI | AJ5: SI | AK5: SI | AM5: SI | AN5: SI | AO5: SI | AQ5: Vacaciones | AR5: Vacaciones | AT5: Vacaciones | AU5: Vacaciones | AV5: Vacaciones | AW5: Vacaciones | AX5: Vacaciones | AZ5: Vacaciones | BA5: SI | BB5: SI | BC5: SI | BD5: SI | BE5: SI | BF5: SI | BG5: SI | BH5: SI | BI5: SI | BK5: SI | BL5: SI | BM5: SI | BN5: SI | BO5: SI | BP5: SI | BQ5: SI | BR5: SI | BS5: SI | BT5: SI | BU5: SI | BV5: SI | BW5: SI | BX5: SI | BY5: SI | BZ5: SI | CA5: SI | CB5: SI | CC5: SI | CD5: SI | CE5: SI | CF5: SI | CS5: SI
A6: JESUS PEÑA | B6: SI | C6: SI | D6: SI | E6: SI | F6: SI | G6: SI | H6: SI | I6: SI | J6: SI | K6: Dia de la familia | L6: SI | M6: SI | N6: SI | O6: No hubo sesion | P6: SI | Q6: SI | R6: SI | S6: SI | T6: SI | U6: SI | V6: SI | W6: SI | X6: SI | Y6: SI | Z6: SI | AA6: SI | AB6: SI | AC6: SI | AD6: SI | AF6: SI | AG6: SI | AH6: SI | AI6: SI | AJ6: SI | AK6: SI | AM6: SI | AN6: SI | AO6: SI | AQ6: SI | AR6: SI | AT6: SI | AU6: SI | AV6: SI | AW6: SI | AX6: SI | AZ6: SI | BA6: SI | BB6: SI | BC6: SI | BD6: SI | BE6: SI | BF6: SI | BG6: SI | BH6: SI | BI6: SI | BK6: SI | BL6: SI | BM6: Falla electrica | BN6: SI | BO6: SI | BP6: SI | BQ6: SI | BR6: SI | BS6: SI | BT6: SI | BU6: SI | BV6: SI | BW6: SI | BX6: SI | BY6: SI | BZ6: SI | CA6: SI | CB6: SI | CC6: SI | CD6: SI | CE6: SI | CF6: SI | CS6: SI
A7: LUIS BEDOYA | B7: SI | C7: SI | D7: SI | E7: SI | F7: SI | G7: SI | H7: SI | I7: SI | J7: SI | K7: SI | L7: Dia de la familia | M7: SI | N7: SI | O7: No hubo sesion | P7: SI | Q7: SI | R7: SI | S7: SI | T7: SI | U7: SIN INTERNET | V7: SI | W7: SI | X7: SI | Y7: SI | Z7: NO | AA7: SI | AB7: SI | AC7: SI | AD7: SI | AF7: SI | AG7: SI | AH7: SI | AI7: SI | AJ7: SI | AK7: SI | AM7: SI | AN7: SI | AO7: SI | AQ7: SI | AR7: SI | AT7: SI | AU7: NO | AV7: SI | AW7: SI | AX7: SI | AZ7: SI | BA7: SI | BB7: SI | BC7: SI | BD7: SI | BE7: SI | BF7: SI | BG7: SI | BH7: SI | BI7: SI | BK7: SI | BL7: SI | BM7: SI | BN7: SI | BO7: NO | BU7: SI | BV7: SI | BW7: SI | BX7: SI
A8: JOHAN QUICENO | B8: SI | C8: SI | D8: SI | E8: SI | F8: SI | G8: SI | H8: SI | I8: SI | J8: SI | K8: SI | L8: NO | M8: SI | N8: SI | O8: No hubo sesion | P8: SI | Q8: SI | R8: SI | S8: SI | T8: SI | U8: SI | V8: SI | W8: Permiso | X8: SI | Y8: SI | Z8: SI | AA8: SI | AB8: NO | AC8: SI | AD8: SI | AF8: SI | AG8: SI | AH8: SI | AI8: SI | AJ8: SI | AK8: SI | AM8: SI | AN8: NO | AO8: SI | AQ8: SI | AR8: SI | AT8: SI | AU8: SI | AV8: SI | AW8: SI | AX8: SI | AZ8: SI | BA8: SI | BB8: SI | BC8: SI | BD8: SI | BE8: SI | BF8: SI | BG8: sin internet | BH8: SI | BI8: SI | BK8: SI | BL8: SI | BM8: SI | BN8: SI | BO8: SI | BP8: SI | BQ8: SI | BR8: SI | BS8: SI | BT8: SI | BU8: SI | BV8: SI | BW8: SI | BX8: TRABAJO HASTA HOY
A9: FABIO FORERO | B9: SI | C9: SI | D9: SI | E9: SI | F9: SI | G9: SI | H9: SI | I9: SI | J9: SI | K9: SI | L9: SI | M9: SI | N9: SI | O9: Dia de la familia | P9: SI | Q9: SI | R9: SI | S9: SI | T9: SI | U9: SI | V9: SI | W9: SI | X9: SI | Y9: SI | Z9: SI | AA9: SI | AB9: SI | AC9: SI | AD9: SI | AF9: SI | AG9: SI | AH9: SI | AI9: SI | AJ9: SI | AK9: SI | AM9: SI | AN9: SI | AO9: SI | AQ9: SI | AR9: SI | AT9: SI | AU9: SI | AV9: SI | AW9: SI | AX9: SI | AZ9: SI | BA9: SI | BB9: SI | BC9: SI | BD9: SI | BE9: SI | BF9: SI | BG9: SI | BH9: SI | BI9: SI | BK9: SI | BL9: SI | BM9: SI | BN9: SI | BO9: SI | BP9: SI | BQ9: SI | BR9: SI | BS9: SI | BT9: SI | BU9: SI | BV9: SI | BW9: SI | BX9: SI | BY9: SI | BZ9: SI | CA9: SI | CB9: SI | CC9: SI | CD9: SI | CE9: SI | CF9: SI | CS9: SI
A10: JENRY HENAO | B10: SI | C10: SI | D10: SI | E10: SI | F10: SI | G10: SI | H10: SI | I10: NO | J10: SI | K10: NO | L10: SI | M10: SI | N10: NO | O10: No hubo sesion | P10: NO | Q10: NO | R10: SI | S10: SI | T10: SI | U10: NO | V10: SI | W10: SI | X10: SI | Y10: SI | Z10: SI | AA10: SI | AB10: SI | AC10: SI | AD10: SI | AF10: SI | AG10: SI | AH10: SI | AI10: SI | AJ10: SI | AK10: NO | AM10: NO | AN10: SI | AO10: SI | AQ10: SI | AR10: SI | AT10: SI | AU10: SI | AV10: SI | AW10: SI | AX10: SI | AZ10: SI | BA10: NO | BB10: NO | BC10: NO | BD10: NO | BE10: NO | BF10: SI | BG10: SI | BH10: SI | BI10: SI | BK10: SI | BL10: SI | BM10: SI | BN10: SI | BO10: SI | BP10: SI | BQ10: SI | BR10: SI | BS10: SI | BT10: SI | BU10: SI | BV10: SI | BW10: NO | BX10: SI | BY10: SI | BZ10: SI | CA10: SI | CB10: SI | CC10: SI | CD10: SI | CE10: SI | CF10: SI | CS10: SI
A11: LIYIBET PEREZ | B11: SI | C11: SI | D11: SI | E11: SI | F11: SI | G11: SI | H11: SI | I11: SI | J11: nomina | K11: NO | L11: SI | M11: NO | N11: SI | O11: No hubo sesion | P11: SI | Q11: SI | R11: SI | S11: NO | T11: NO | U11: NO | V11: SI | W11: SI | X11: SI | Y11: SI | Z11: SI | AA11: SI | AB11: SI | AC11: SI | AD11: NO | AF11: SI | AG11: SI | AH11: SI | AI11: SI | AJ11: SI | AK11: SI | AM11: SI | AN11: SI | AO11: SI | AQ11: SI | AR11: SI | AT11: SI | AU11: NO | AV11: NO | AW11: SI | AX11: SI | AZ11: NO | BA11: SI | BB11: SI | BC11: SI | BD11: SI | BE11: NO | BF11: NO | BG11: NO | BH11: SI | BI11: SI | BK11: SI | BL11: SI | BM11: SI | BN11: SI | BO11: NO | BP11: SI | BQ11: SI | BR11: NOMINA | BS11: SI | BT11: SI | BU11: SI | BV11: SI | BW11: SI | BX11: SI | BY11: SI | BZ11: SI | CA11: SI | CB11: NO | CC11: NO | CD11: SI | CE11: SI | CF11: SI | CS11: SI
A12: WILSON APONTE | B12: SI | C12: NO | D12: SI | E12: SI | F12: NO | G12: NO | H12: SI | I12: NO | J12: SI | K12: NO | L12: SI | M12: NO | N12: NO | O12: No hubo sesion | P12: SI | Q12: NO | R12: NO | S12: NO | T12: NO | U12: NO | V12: NO | W12: SI | X12: NO | Y12: NO | Z12: SI | AA12: NO | AB12: NO | AC12: SI | AD12: NO | AF12: NO | AG12: NO | AH12: NO | AI12: NO | AJ12: SI | AK12: SI | AM12: NO | AN12: NO | AO12: NO | AQ12: NO | AR12: NO | AT12: NO | AU12: NO | AV12: SI | AW12: SI | AX12: NO | AZ12: NO | BA12: NO | BB12: NO | BC12: SI | BD12: NO | BE12: SI | BF12: NO | BG12: NO | BH12: SI | BI12: NO | BK12: NO | BL12: NO | BM12: SI | BN12: NO | BO12: NO | BP12: NO | BQ12: NO | BR12: SI | BS12: NO | BT12: NO | BU12: SI | BV12: SI | BW12: NO | BX12: NO | BY12: SI | BZ12: NO | CA12: NO | CB12: SI | CC12: NO | CD12: NO | CE12: SI | CF12: NO | CS12: NO
A13: JOHN ROLON | B13: SI | C13: NO | D13: NO | E13: NO | F13: NO | G13: NO | H13: NO | I13: NO | J13: SI | K13: NO | L13: NO | M13: SI | N13: NO | O13: No hubo sesion | P13: NO | Q13: NO | R13: NO | S13: NO | T13: NO | U13: NO | V13: SI | W13: NO | X13: NO | Y13: NO | Z13: NO | AA13: NO | AB13: NO | AC13: SI | AD13: NO | AF13: NO | AG13: NO | AH13: NO | AI13: SI | AJ13: NO | AK13: NO | AM13: NO | AN13: NO | AO13: NO | AQ13: NO | AR13: NO | AT13: NO | AU13: NO | AV13: NO | AW13: NO | AX13: NO | AZ13: NO | BA13: NO | BB13: NO | BC13: NO | BD13: NO | BE13: NO | BF13: NO | BG13: NO | BH13: NO | BI13: NO | BK13: NO | BL13: NO | BM13: NO | BN13: NO | BO13: NO | BP13: NO | BQ13: NO | BR13: NOMINA | BS13: NO | BT13: NO | BU13: NO | BV13: NO | BW13: NO | BX13: NO | BY13: NO | BZ13: NO | CA13: NO | CB13: NO | CC13: NO | CD13: SI | CE13: SI | CF13: SI | CS13: NO

Sheet pruebas i
A1: Asignado | B1: Requerimiento | C1: Actividad | D1: ESTADO | E1: F.Asignado | F1: Fecha inicio | G1: F. estimada de entrega | H1: Finalizado | I1: Dias | J1: TEST | K1: PRODUCCION | L1: Observacion
