Workbook

Sheet EN PROCESO (Tuya)
A1: Asignado a | B1: ID REQ | C1: Requerimiento | D1: Descripcion req | E1: Actividad | F1: ESTADO | G1: % Avance | H1: Dias estimados desarrollo | I1: F.Asignado | J1: Fecha inicio | K1: F. estimada de entrega | L1: Finalizado | M1: Dias total desarrollo | N1: Fecha compromiso cliente | O1: FECHA PASO A TEST | P1: FECHA PASO A PRODUCCION | Q1: DESCRIPCION DEL AVANCE | R1: Visible
A2: Faver | B2: 1 | C2: Migración Gestión Documental, Ajustar módulos | D2: Sistema Operativo, PHP | F2: PAUSADO | G2: 5 | H2: =IF(OR(J2="",K2="",K2<J2),0,NETWORKDAYS(J2,K2,Hoja2!$A$2:$A$53)) -> 0 | J2: 45667 | M2: =IF(OR(J2="",AND(L2="",TODAY()<J2),AND(L2<>"",L2<J2)),0, IF(L2="", NETWORKDAYS(J2,TODAY(),Hoja2!$A$2:$A$53), NETWORKDAYS(J2,L2,Hoja2!$A$2:$A$53) ) ) -> 354 | Q2: Se encuentra pausado por el momendo debido a temas de definición de contrato con el cliente | R2: False
A3: Natalia | B3: 1-1 | C3: Pruebas Migración Gestión Documental | D3: Realizar pruebas con el fin de validar el correcto funcionamiento del aplicativo | F3: PAUSADO | H3: =IF(OR(J3="",K3="",K3<J3),0,NETWORKDAYS(J3,K3,Hoja2!$A$2:$A$53)) -> 0 | J3: 45667 | M3: =IF(OR(J3="",AND(L3="",TODAY()<J3),AND(L3<>"",L3<J3)),0, IF(L3="", NETWORKDAYS(J3,TODAY(),Hoja2!$A$2:$A$53), NETWORKDAYS(J3,L3,Hoja2!$A$2:$A$53) ) ) -> 354 | Q3: Se encuentra pausado por el momendo debido a temas de definición de contrato con el cliente | R3: False
A4: Faver | B4: 2 | C4: Migración Legalizaciones y Anticipos Ajustar módulos | D4: Sistema Operativo, PHP | F4: PAUSADO | G4: 60 | H4: =IF(OR(J4="",K4="",K4<J4),0,NETWORKDAYS(J4,K4,Hoja2!$A$2:$A$53)) -> 0 | J4: 45667 | M4: =IF(OR(J4="",AND(L4="",TODAY()<J4),AND(L4<>"",L4<J4)),0, IF(L4="", NETWORKDAYS(J4,TODAY(),Hoja2!$A$2:$A$53), NETWORKDAYS(J4,L4,Hoja2!$A$2:$A$53) ) ) -> 354 | Q4: Se encuentra pausado por el momendo debido a temas de definición de contrato con el cliente | R4: False
A5: Natalia | B5: 2-1 | C5: Pruebas Migración Leg y Anticipos | D5: Realizar pruebas con el fin de validar el correcto funcionamiento del aplicativo | F5: PAUSADO | G5: 60 | H5: =IF(OR(J5="",K5="",K5<J5),0,NETWORKDAYS(J5,K5,Hoja2!$A$2:$A$53)) -> 0 | J5: 45667 | M5: =IF(OR(J5="",AND(L5="",TODAY()<J5),AND(L5<>"",L5<J5)),0, IF(L5="", NETWORKDAYS(J5,TODAY(),Hoja2!$A$2:$A$53), NETWORKDAYS(J5,L5,Hoja2!$A$2:$A$53) ) ) -> 354 | Q5: Se encuentra pausado por el momendo debido a temas de definición de contrato con el cliente | R5: False
A6: Natalia | B6: 9 | C6: Reporte y validación de 9 incidentes via email | D6: Se realiza reporte de 9 incidentes luego de pruebas realizadas en el aplicativo Se valida y a la fecha han sido solucionados 5 incidentes | F6: PAUSADO | G6: 50 | H6: =IF(OR(J6="",K6="",K6<J6),0,NETWORKDAYS(J6,K6,Hoja2!$A$2:$A$53)) -> 0 | J6: 45667 | M6: =IF(OR(J6="",AND(L6="",TODAY()<J6),AND(L6<>"",L6<J6)),0, IF(L6="", NETWORKDAYS(J6,TODAY(),Hoja2!$A$2:$A$53), NETWORKDAYS(J6,L6,Hoja2!$A$2:$A$53) ) ) -> 354 | Q6: Se encuentra pausado por el momendo debido a temas de definición de contrato con el cliente | R6: False
A7: Faver | B7: 3 | C7: Migración Virtualización, Ajustar módulos | D7: Sistema Operativo, PHP | F7: PAUSADO | G7: 100 | H7: =IF(OR(J7="",K7="",K7<J7),0,NETWORKDAYS(J7,K7,Hoja2!$A$2:$A$53)) -> 0 | J7: 45667 | M7: =IF(OR(J7="",AND(L7="",TODAY()<J7),AND(L7<>"",L7<J7)),0, IF(L7="", NETWORKDAYS(J7,TODAY(),Hoja2!$A$2:$A$53), NETWORKDAYS(J7,L7,Hoja2!$A$2:$A$53) ) ) -> 354 | Q7: Se encuentra pausado por el momendo debido a temas de definición de contrato con el cliente 02/12/2025: Este aplicativo ya se encuentra deshabilitado, no se tiene mas contrato con el cliente | R7: True
A8: Natalia | B8: 3-1 | C8: Pruebas Migración Virtualización | D8: Realizar pruebas con el fin de validar el correcto funcionamiento del aplicativo | F8: PAUSADO | G8: 100 | H8: =IF(OR(J8="",K8="",K8<J8),0,NETWORKDAYS(J8,K8,Hoja2!$A$2:$A$53)) -> 0 | J8: 45667 | M8: =IF(OR(J8="",AND(L8="",TODAY()<J8),AND(L8<>"",L8<J8)),0, IF(L8="", NETWORKDAYS(J8,TODAY(),Hoja2!$A$2:$A$53), NETWORKDAYS(J8,L8,Hoja2!$A$2:$A$53) ) ) -> 354 | Q8: Se encuentra pausado por el momendo debido a temas de definición de contrato con el cliente 02/12/2025: Este aplicativo ya se encuentra deshabilitado, no se tiene mas contrato con el cliente | R8: True
A9: Wilson | B9: 4 | C9: Incluir en la operación de anexos el API de pendiente catt | D9: Crear un cliente en nodejs que una vez que se detecten los tipos de anexo envíe vía API el detalle de acuerdo a cada solicitud. | F9: FINALIZADO | G9: 100 | H9: =IF(OR(J9="",K9="",K9<J9),0,NETWORKDAYS(J9,K9,Hoja2!$A$2:$A$53)) -> 0 | J9: 45832 | L9: 45835 | M9: =IF(OR(J9="",AND(L9="",TODAY()<J9),AND(L9<>"",L9<J9)),0, IF(L9="", NETWORKDAYS(J9,TODAY(),Hoja2!$A$2:$A$53), NETWORKDAYS(J9,L9,Hoja2!$A$2:$A$53) ) ) -> 4 | Q9: "Estamos a la espera de la instalación de una librería para conexión a PCO, pero es Tuya quien hace dicha instalación, pero aún no hay fecha. 11/07/2025: se tuvo una reunión en la cual realizaron una ampliación de requerimiento para que los anexos que no tengan una solicitud se queden en cola dos o tres días máximo, y cuando llegue la solicitud se indexen" | R9: True
A10: Wilson | B10: 5 | C10: El código de oficina no debe ser obligatorio para indexar documentos desde la API | D10: El viernes 11 de julio, se tuvo una reunión en la cual realizaron una ampliación de requerimiento para que los anexos que no tengan una solicitud se queden en cola dos o tres días máximo, y cuando llegue la solicitud se indexen" | F10: FINALIZADO | G10: 100 | H10: =IF(OR(J10="",K10="",K10<J10),0,NETWORKDAYS(J10,K10,Hoja2!$A$2:$A$53)) -> 0 | J10: 45832 | L10: 45835 | M10: =IF(OR(J10="",AND(L10="",TODAY()<J10),AND(L10<>"",L10<J10)),0, IF(L10="", NETWORKDAYS(J10,TODAY(),Hoja2!$A$2:$A$53), NETWORKDAYS(J10,L10,Hoja2!$A$2:$A$53) ) ) -> 4 | Q10: 27/06/2025: Se realizó modificación del codigo de oficina como opcional | R10: True
A11: Wilson | B11: 6 | C11: Actualizar documentación para la operación de anexos | F11: FINALIZADO | G11: 100 | H11: =IF(OR(J11="",K11="",K11<J11),0,NETWORKDAYS(J11,K11,Hoja2!$A$2:$A$53)) -> 0 | J11: 45832 | L11: 45835 | M11: =IF(OR(J11="",AND(L11="",TODAY()<J11),AND(L11<>"",L11<J11)),0, IF(L11="", NETWORKDAYS(J11,TODAY(),Hoja2!$A$2:$A$53), NETWORKDAYS(J11,L11,Hoja2!$A$2:$A$53) ) ) -> 4 | Q11: 27/06/2025: Se realizaron ajustes necesarios y se modificó el documento con respecto a mensajes de error | R11: True
A12: Wilson | B12: 7 | C12: Se requiere una nueva operación que reciba la solicitud y sus anexos | D12: Este proceso en una unica operación, la cual debe consumir el API de pendientes para registrar los documentos enviados | F12: FINALIZADO | G12: 100 | H12: =IF(OR(J12="",K12="",K12<J12),0,NETWORKDAYS(J12,K12,Hoja2!$A$2:$A$53)) -> 0 | J12: 45832 | L12: 45896 | M12: =IF(OR(J12="",AND(L12="",TODAY()<J12),AND(L12<>"",L12<J12)),0, IF(L12="", NETWORKDAYS(J12,TODAY(),Hoja2!$A$2:$A$53), NETWORKDAYS(J12,L12,Hoja2!$A$2:$A$53) ) ) -> 44 | Q12: 24/07/2025: Este pundo depende del cliente que se construye con el punto 1. la funcionalidad de envio a pendientes serviria para ambos servicios. 13/08/2025: en el momento el cliente se encuentra haciendo pruebas de la indexación de anexos, y la cola de espera. En cuanto el 3 punto, estamos en espera de la instalación de una libreria para el consumo de un servicio de Soap, esto ya que por medio de métodos manuales no fue posible para todos los casos. Apenas tenga la autorización lo único que haría falta es desarrollar el cliente y traer los datos que se requieren para indexar la solicitud y sus anexos. También en la reunión de entrega surgieron unas validaciones adicionales, pero de esa parte no nos han enviado el requerimiento ya que depende de definiciones de ellos. 20/08/2025: con respecto a el desarrollo del Api, se realizó lo requerido, sin embargo surgió un cambio muy necesario al recibir los documentos, es el siguiente: "Espero que te encuentres bien. Después de revisar la duda planteada, te cuento que: El control para la operación de .zip Si la solicitud existe - no se vuelve a indexar Si los anexos existen – no se vuelven a indexar Si los anexos no existen – se adicionan a los documentos. En caso de que todos los documentos existan devolver: No se requieren agregar nuevamente los documentos. Si, se agrega al menos un documento: Los anexos faltantes fueron agregados a la solicitud. Si, todos se agregan: Proceso exitoso." Voy a agregar la lógica para estas validaciones y realizar pruebas nuevamente con la usuaria, con esto daríamos por finalizado este desarrollo, solo quedaría actualizar la documentación y el paso a producción. 22/08/2025: en cuanto al Api, se realizó la entrega del último método con todos los ajustes y validaciones requeridas, adicionalmente se entregó la documentación técnica al día Queda la implementación por parte de ellos, pruebas de integración y paso a producción. 27/08/2025: Se revisa en conjunto con el cliente de funcionamiento del ultimo método, punto 4, se realizan ajustes de forma en la generación de mensajes de éxito y se ajusta documentación Se realiza ajuste para q reciba solamente documentación de la solicitud sin anexo, esto en caso de falla al momento de la generación de los anexos. | R12: True
A13: Wilson | B13: 8 | C13: Quitar conexiones y modificar método para recibir los datos nuevos: | D13: Ddefinieron que no vamos a realizar la conexión si no que ellos nos envían los datos necesarios, | F13: FINALIZADO | G13: 100 | H13: =IF(OR(J13="",K13="",K13<J13),0,NETWORKDAYS(J13,K13,Hoja2!$A$2:$A$53)) -> 0 | J13: 45870 | L13: 45883 | M13: =IF(OR(J13="",AND(L13="",TODAY()<J13),AND(L13<>"",L13<J13)),0, IF(L13="", NETWORKDAYS(J13,TODAY(),Hoja2!$A$2:$A$53), NETWORKDAYS(J13,L13,Hoja2!$A$2:$A$53) ) ) -> 9 | Q13: 14/08/2025: En cuanto a los desarrollo del Api, ayer definieron que no vamos a realizar la conexión si no que ellos nos envían los datos necesarios, les expliqué la lógica al respecto y como nos deben enviar los datos, surge el cambio en el servicio para recibir y validar los datos. En este caso no quisieron avalar la librería solicitada y para poder poner la que nos ofrecieron nos tocaba migrar todo el Api. En este caso ellos deben validar y enviar la información del producto a ingresar, realmente no es mucho lo que deben hacer para consultar y traer los datos que requerimos En otras palabras es algo que genera un impacto muy bajo de quien lo deba hacer. | R13: True
A14: Faver | B14: 101 | C14: Consulta Solicitudes Pendientes por Validar Venta Cartera Junio | D14: Se requiere que con la base de datos que comparten, identificar si tienen documento de solicitud de crédito en Imagine | F14: FINALIZADO | G14: 100 | H14: =IF(OR(J14="",K14="",K14<J14),0,NETWORKDAYS(J14,K14,Hoja2!$A$2:$A$53)) -> 3 | J14: 45827 | K14: 45832 | L14: 45832 | M14: =IF(OR(J14="",AND(L14="",TODAY()<J14),AND(L14<>"",L14<J14)),0, IF(L14="", NETWORKDAYS(J14,TODAY(),Hoja2!$A$2:$A$53), NETWORKDAYS(J14,L14,Hoja2!$A$2:$A$53) ) ) -> 3 | Q14: Se realiza validación en el sistema y se envía respuesta al usuario solicitante | R14: True
A15: Faver | B15: 111 | C15: Validación Clientes con autorización tratamiento de datos | D15: Validación de 36665 clientes, por medio de archivo adjunto, donde se pueda identificar que clientes cuentan con una autorización de tratamiento de datos personales | F15: FINALIZADO | G15: 100 | H15: =IF(OR(J15="",K15="",K15<J15),0,NETWORKDAYS(J15,K15,Hoja2!$A$2:$A$53)) -> 3 | J15: 45827 | K15: 45832 | L15: 45832 | M15: =IF(OR(J15="",AND(L15="",TODAY()<J15),AND(L15<>"",L15<J15)),0, IF(L15="", NETWORKDAYS(J15,TODAY(),Hoja2!$A$2:$A$53), NETWORKDAYS(J15,L15,Hoja2!$A$2:$A$53) ) ) -> 3 | Q15: Se realiza validación en el sistema y se envía respuesta al usuario solicitante | R15: True
A16: Faver | B16: 121 | C16: Nueva operación que reciba solicitud y anexos | D16: En la opción de Consulta Área de crédito, validar si es posible, donde se realiza la comparación que se pueda discriminar cuando en una misma familia el cliente tenga varias solicitudes. | F16: FINALIZADO | G16: 100 | H16: =IF(OR(J16="",K16="",K16<J16),0,NETWORKDAYS(J16,K16,Hoja2!$A$2:$A$53)) -> 76 | J16: 45828 | K16: 45939 | L16: 45974 | M16: =IF(OR(J16="",AND(L16="",TODAY()<J16),AND(L16<>"",L16<J16)),0, IF(L16="", NETWORKDAYS(J16,TODAY(),Hoja2!$A$2:$A$53), NETWORKDAYS(J16,L16,Hoja2!$A$2:$A$53) ) ) -> 99 | O16: 45940 | P16: 45974 | Q16: oct 01: se tuvo reunión con usuarios para alcaración de dudas con respecto a requerimientos oct 2: se determina un tiempo de desarrollo de 4 semanas oct 10: se realizan pruebas de cambios ejecutados en el aplicativo oct 16: se realiza envio de evidencias de pruebas realizadas al cliente, con el fin de inicio de pruebas por parte de ellos. oct 21: el cliente indica que se finalizan pruebas por parte de ellos, siendo exitosas; estamos a la espera de fecha y aval para paso a producción nov 13: se realiza el paso a producción, siendo exitoso | R16: True
A17: Faver | B17: 131 | C17: Crear opción para generación informe Morosos | D17: Usuario envía archivo con clientes mororos de créditos, para validar soportes existentes en Imagine para los números de cédula enviados. Los documentos son Solicitud de crédito o actualización de datos del deudor y Anexo1 aceptación, autorización. | F17: PAUSADO | H17: =IF(OR(J17="",K17="",K17<J17),0,NETWORKDAYS(J17,K17,Hoja2!$A$2:$A$53)) -> 0 | J17: 45828 | M17: =IF(OR(J17="",AND(L17="",TODAY()<J17),AND(L17<>"",L17<J17)),0, IF(L17="", NETWORKDAYS(J17,TODAY(),Hoja2!$A$2:$A$53), NETWORKDAYS(J17,L17,Hoja2!$A$2:$A$53) ) ) -> 244 | Q17: Esta pendiente de aprobación por Tuya | R17: False
A18: Faver | B18: 141 | C18: Realizar trazabilidad de las solicitudes que anulan y desanulan de los documentos en los anexos. | D18: Hoy en día se cuenta con un log de solo 10 días, pero en el nuevo requerimiento se solicita que no tenga tiempo límite. | F18: FINALIZADO | G18: 100 | H18: =IF(OR(J18="",K18="",K18<J18),0,NETWORKDAYS(J18,K18,Hoja2!$A$2:$A$53)) -> 74 | J18: 45833 | K18: 45939 | L18: 45974 | M18: =IF(OR(J18="",AND(L18="",TODAY()<J18),AND(L18<>"",L18<J18)),0, IF(L18="", NETWORKDAYS(J18,TODAY(),Hoja2!$A$2:$A$53), NETWORKDAYS(J18,L18,Hoja2!$A$2:$A$53) ) ) -> 97 | O18: 45940 | P18: 45974 | Q18: oct 01: se tuvo reunión con usuarios para alcaración de dudas con respecto a requerimientos oct 2: se determina un tiempo de desarrollo de 4 semanas oct 10: se realizan pruebas de cambios ejecutados en el aplicativo oct 16: se realiza envio de evidencias de pruebas realizadas al cliente, con el fin de inicio de pruebas por parte de ellos. oct 21: el cliente indica que se finalizan pruebas por parte de ellos, siendo exitosas; estamos a la espera de fecha y aval para paso a producción nov 13: se realiza el paso a producción, siendo exitoso | R18: True
A19: Faver | B19: 151 | C19: Retirar candado consulta | D19: Se solicita retirar el candado que se tiene actualmente en la consulta inicial, debido a que dicha opción no se encuentra actualizada y se tiene “consulta área de crédito“ para realizar el proceso de comparación | F19: FINALIZADO | G19: 100 | H19: =IF(OR(J19="",K19="",K19<J19),0,NETWORKDAYS(J19,K19,Hoja2!$A$2:$A$53)) -> 74 | J19: 45833 | K19: 45939 | L19: 45974 | M19: =IF(OR(J19="",AND(L19="",TODAY()<J19),AND(L19<>"",L19<J19)),0, IF(L19="", NETWORKDAYS(J19,TODAY(),Hoja2!$A$2:$A$53), NETWORKDAYS(J19,L19,Hoja2!$A$2:$A$53) ) ) -> 97 | O19: 45940 | P19: 45974 | Q19: oct 01: se tuvo reunión con usuarios para alcaración de dudas con respecto a requerimientos oct 10: se realizan pruebas de cambios ejecutados en el aplicativo oct 16: se realiza envio de evidencias de pruebas realizadas al cliente, con el fin de inicio de pruebas por parte de ellos. oct 21: el cliente indica que se finalizan pruebas por parte de ellos, siendo exitosas; estamos a la espera de fecha y aval para paso a producción nov 13: se realiza el paso a producción, siendo exitoso | R19: True
A20: Faver | B20: 161 | C20: Nueva opción consulta área crédito | D20: Se debe crear un nuevo método en el API en el cual se recibe archivo .zip y adicional el listado de tipos de documento que contiene de manera que se agregue un nuevo lote con un documento principal y sus anexos y adicionalmente se reporte a PCO vía API REST los documentos según configuración. | F20: FINALIZADO | G20: 100 | H20: =IF(OR(J20="",K20="",K20<J20),0,NETWORKDAYS(J20,K20,Hoja2!$A$2:$A$53)) -> 0 | J20: 45833 | L20: 45974 | M20: =IF(OR(J20="",AND(L20="",TODAY()<J20),AND(L20<>"",L20<J20)),0, IF(L20="", NETWORKDAYS(J20,TODAY(),Hoja2!$A$2:$A$53), NETWORKDAYS(J20,L20,Hoja2!$A$2:$A$53) ) ) -> 97 | P20: 45974 | Q20: Esta pendiente de aprobación por Tuya | R20: True
A21: Faver | B21: 171 | C21: Solicitud jhon Humberto | D21: Ayudar a Jhon Humberto para validar una solicitud en Ambiente de pruebas por que tiene malo el causal desde PCO | F21: FINALIZADO | G21: 100 | H21: =IF(OR(J21="",K21="",K21<J21),0,NETWORKDAYS(J21,K21,Hoja2!$A$2:$A$53)) -> 0 | J21: 45852 | L21: 45855 | M21: =IF(OR(J21="",AND(L21="",TODAY()<J21),AND(L21<>"",L21<J21)),0, IF(L21="", NETWORKDAYS(J21,TODAY(),Hoja2!$A$2:$A$53), NETWORKDAYS(J21,L21,Hoja2!$A$2:$A$53) ) ) -> 4 | Q21: 16/07/2025: se tuvo reunión en la cual dieron contexto de las pruebas que realizaron y que les esta fallando 17/07/2025: Se realiza validaciones, se determina que en las p ruebas que realizaron se esta recibiendo codigos no parametrizados para la solicitud que tratan de procesar. | R21: True
A22: Faver | B22: 181 | C22: Consulta solicitudes Venta Cartera | D22: Se requiere que con la base de datos que comparten, identificar si tienen documento de solicitud de crédito en Imagine | F22: FINALIZADO | G22: 100 | H22: =IF(OR(J22="",K22="",K22<J22),0,NETWORKDAYS(J22,K22,Hoja2!$A$2:$A$53)) -> 0 | J22: 45852 | L22: 45855 | M22: =IF(OR(J22="",AND(L22="",TODAY()<J22),AND(L22<>"",L22<J22)),0, IF(L22="", NETWORKDAYS(J22,TODAY(),Hoja2!$A$2:$A$53), NETWORKDAYS(J22,L22,Hoja2!$A$2:$A$53) ) ) -> 4 | Q22: 16/07/2025: se tuvo reunión para validación con el usuario para validar bien la informaciòn que requieren. 17/07/2025: luego de validar la información que se brindo en la reunión se genero el informe y se envío al usuario solicitante | R22: True
A23: Faver | B23: 191 | C23: Urgente FGA y FNG Solicitud soportes y base morosos | D23: Generar por favor link de descarga de documentos que requeire el equipo de operaiones para un proceso de la compañia. Adjuntan archivo | F23: FINALIZADO | G23: 100 | H23: =IF(OR(J23="",K23="",K23<J23),0,NETWORKDAYS(J23,K23,Hoja2!$A$2:$A$53)) -> 0 | J23: 45852 | L23: 45853 | M23: =IF(OR(J23="",AND(L23="",TODAY()<J23),AND(L23<>"",L23<J23)),0, IF(L23="", NETWORKDAYS(J23,TODAY(),Hoja2!$A$2:$A$53), NETWORKDAYS(J23,L23,Hoja2!$A$2:$A$53) ) ) -> 2 | R23: True
A24: Natalia | B24: 201 | C24: Creación Ofiicna | D24: Se solicita creación de nueva oficina por apertura de nueva sede | F24: FINALIZADO | G24: 100 | H24: =IF(OR(J24="",K24="",K24<J24),0,NETWORKDAYS(J24,K24,Hoja2!$A$2:$A$53)) -> 0 | J24: 45860 | L24: 45860 | M24: =IF(OR(J24="",AND(L24="",TODAY()<J24),AND(L24<>"",L24<J24)),0, IF(L24="", NETWORKDAYS(J24,TODAY(),Hoja2!$A$2:$A$53), NETWORKDAYS(J24,L24,Hoja2!$A$2:$A$53) ) ) -> 1 | R24: True
A25: Faver | B25: 211 | C25: Solicitud de encriptar un cliente secret que se usa consumcir un Api, es para solventar un riesgo de vulnerabilidad | D25: Es una solicitud para mitigar una vulnerabilidad en un client secret, este se usa para consumir las APIs, por politicas de seguridad se pidio que no se almacene en texto plano, se debe encriptar para evitar la exposición del valor real del secret. | F25: FINALIZADO | G25: 100 | H25: =IF(OR(J25="",K25="",K25<J25),0,NETWORKDAYS(J25,K25,Hoja2!$A$2:$A$53)) -> 0 | L25: 45860 | M25: =IF(OR(J25="",AND(L25="",TODAY()<J25),AND(L25<>"",L25<J25)),0, IF(L25="", NETWORKDAYS(J25,TODAY(),Hoja2!$A$2:$A$53), NETWORKDAYS(J25,L25,Hoja2!$A$2:$A$53) ) ) -> 0 | R25: True
A26: Faver | B26: 221 | C26: Solicitud de validación de unos host de servidores linux de producción, preguntan que si son necesario para funcionar o que si se pueden quitar. | D26: Es un reporte que nos realizan desde infraestructura que en los ambientes productivos se tiene asociado a la IP local de lo servidores un hostname personalizado, nos indican que si no es necesario para nuestros procesos deben retirarlo. | F26: FINALIZADO | G26: 100 | H26: =IF(OR(J26="",K26="",K26<J26),0,NETWORKDAYS(J26,K26,Hoja2!$A$2:$A$53)) -> 0 | J26: 45856 | L26: 45861 | M26: =IF(OR(J26="",AND(L26="",TODAY()<J26),AND(L26<>"",L26<J26)),0, IF(L26="", NETWORKDAYS(J26,TODAY(),Hoja2!$A$2:$A$53), NETWORKDAYS(J26,L26,Hoja2!$A$2:$A$53) ) ) -> 4 | Q26: 22/07/2025: se valida la solicitud del cliente, se socializa con Don Hernan y Jenry, y se les indica que nosotros solo debemos confirmar si se usa o si pueden retirarlo, ya que no deberia estar configurado, ya que ellos tienen unas configuraciones ya establecidas para los nombres de host en los servidores. | R26: True
A27: Faver y Natalia | B27: 231 | C27: Solicitud soportes y bases de morosos a corte 23 julio | D27: Solicitud de usuario para generar base de morosos...como este es un reporte que se genera dos veces al mes, ya se tiene el query para generar la información | F27: FINALIZADO | G27: 100 | H27: =IF(OR(J27="",K27="",K27<J27),0,NETWORKDAYS(J27,K27,Hoja2!$A$2:$A$53)) -> 0 | J27: 45861 | L27: 45866 | M27: =IF(OR(J27="",AND(L27="",TODAY()<J27),AND(L27<>"",L27<J27)),0, IF(L27="", NETWORKDAYS(J27,TODAY(),Hoja2!$A$2:$A$53), NETWORKDAYS(J27,L27,Hoja2!$A$2:$A$53) ) ) -> 4 | Q27: 25/07/2025: Este requerimiento no se pudo validar dado atender hoy debido a que se ha realizado el acompañamiento y seguimiento en Colpatria por la novedad presentada | R27: True
A28: Faver y Natalia | B28: 241 | C28: Solicitud soportes y bases de morosos a corte 31 julio | D28: Solicitud de usuario para generar base de morosos...como este es un reporte que se genera dos veces al mes, ya se tiene el query para generar la información | F28: FINALIZADO | G28: 100 | H28: =IF(OR(J28="",K28="",K28<J28),0,NETWORKDAYS(J28,K28,Hoja2!$A$2:$A$53)) -> 0 | J28: 45874 | L28: 45875 | M28: =IF(OR(J28="",AND(L28="",TODAY()<J28),AND(L28<>"",L28<J28)),0, IF(L28="", NETWORKDAYS(J28,TODAY(),Hoja2!$A$2:$A$53), NETWORKDAYS(J28,L28,Hoja2!$A$2:$A$53) ) ) -> 2 | R28: True
A29: Faver y Natalia | B29: 251 | C29: Certificados digitales | D29: certificados digitales para los aplicativos de virtualizacion y legalizaciones para el día 13 de agosto con tecnología | F29: FINALIZADO | G29: 100 | H29: =IF(OR(J29="",K29="",K29<J29),0,NETWORKDAYS(J29,K29,Hoja2!$A$2:$A$53)) -> 0 | J29: 45882 | L29: 45883 | M29: =IF(OR(J29="",AND(L29="",TODAY()<J29),AND(L29<>"",L29<J29)),0, IF(L29="", NETWORKDAYS(J29,TODAY(),Hoja2!$A$2:$A$53), NETWORKDAYS(J29,L29,Hoja2!$A$2:$A$53) ) ) -> 2 | Q29: 14/08/2025: Se informa que el día 13 de agosto, se hizo el cambio de los certificados, pero un certificado estaba mal, ya se reporto y esperamos nos envien de nuevo para realizar el ajuste antes del 16 de agosto | R29: True
A30: Faver | B30: 261 | C30: Base de datos para recolección de extractos bancarios | D30: Nos solitan entregar un paquete con los extractos bancarios de 10mil solicitudes, para un proceso del cliente de un modelo que van a probar | F30: FINALIZADO | G30: 100 | H30: =IF(OR(J30="",K30="",K30<J30),0,NETWORKDAYS(J30,K30,Hoja2!$A$2:$A$53)) -> 0 | J30: 45884 | L30: 45889 | M30: =IF(OR(J30="",AND(L30="",TODAY()<J30),AND(L30<>"",L30<J30)),0, IF(L30="", NETWORKDAYS(J30,TODAY(),Hoja2!$A$2:$A$53), NETWORKDAYS(J30,L30,Hoja2!$A$2:$A$53) ) ) -> 3 | Q30: 19/08/2025: se realiza sesión para la generaciónn de la información pero estaba quedando muy pesado el archivo, ya que eran demasiados registros, por lo que la entrega se va a realizar por paquetes para evitar problemas con la red 20/08/2025: se realiza generación de varios paquetes para entregar información al usuario. | R30: True
A31: Faver | B31: 271 | C31: solicitud para generar un informe para temas de venta de cartea | D31: Realizar consulta de clientes del mes de junio. | F31: FINALIZADO | G31: 100 | H31: =IF(OR(J31="",K31="",K31<J31),0,NETWORKDAYS(J31,K31,Hoja2!$A$2:$A$53)) -> 0 | J31: 45891 | L31: 45894 | M31: =IF(OR(J31="",AND(L31="",TODAY()<J31),AND(L31<>"",L31<J31)),0, IF(L31="", NETWORKDAYS(J31,TODAY(),Hoja2!$A$2:$A$53), NETWORKDAYS(J31,L31,Hoja2!$A$2:$A$53) ) ) -> 2 | R31: True
A32: Faver y Natalia | B32: 281 | C32: Solicitud soportes y bases de morosos a corte 31 agosto | D32: Solicitud de usuario para generar base de morosos...como este es un reporte que se genera dos veces al mes, ya se tiene el query para generar la información | F32: FINALIZADO | G32: 100 | H32: =IF(OR(J32="",K32="",K32<J32),0,NETWORKDAYS(J32,K32,Hoja2!$A$2:$A$53)) -> 0 | J32: 45904 | L32: 45904 | M32: =IF(OR(J32="",AND(L32="",TODAY()<J32),AND(L32<>"",L32<J32)),0, IF(L32="", NETWORKDAYS(J32,TODAY(),Hoja2!$A$2:$A$53), NETWORKDAYS(J32,L32,Hoja2!$A$2:$A$53) ) ) -> 1 | R32: True
A33: Faver | B33: 291 | C33: Creacion anexo | D33: Creación documento para varias familias | F33: FINALIZADO | G33: 100 | H33: =IF(OR(J33="",K33="",K33<J33),0,NETWORKDAYS(J33,K33,Hoja2!$A$2:$A$53)) -> 0 | J33: 45916 | L33: 45918 | M33: =IF(OR(J33="",AND(L33="",TODAY()<J33),AND(L33<>"",L33<J33)),0, IF(L33="", NETWORKDAYS(J33,TODAY(),Hoja2!$A$2:$A$53), NETWORKDAYS(J33,L33,Hoja2!$A$2:$A$53) ) ) -> 3 | Q33: Se realiza la asignación del anexo en las familias y se le informa al usuario | R33: True
A34: Faver y Natalia | B34: 292 | C34: Solicitud soportes y bases de morosos a corte 23 septiembre | D34: Solicitud de usuario para generar base de morosos...como este es un reporte que se genera dos veces al mes, ya se tiene el query para generar la información | F34: FINALIZADO | G34: 100 | H34: =IF(OR(J34="",K34="",K34<J34),0,NETWORKDAYS(J34,K34,Hoja2!$A$2:$A$53)) -> 0 | J34: 45924 | L34: 45926 | M34: =IF(OR(J34="",AND(L34="",TODAY()<J34),AND(L34<>"",L34<J34)),0, IF(L34="", NETWORKDAYS(J34,TODAY(),Hoja2!$A$2:$A$53), NETWORKDAYS(J34,L34,Hoja2!$A$2:$A$53) ) ) -> 3 | R34: True
A35: Faver | B35: 293 | C35: Habilitar función de anular el pagaré | D35: se requiere esta opción en el aparte de anexos, con el fin de que no se devuelva la acción de anulación. Se debe informar al usuario si esta seguro de realizar la anulación. | F35: PRUEBAS CLIENTE | G35: 95 | H35: =IF(OR(J35="",K35="",K35<J35),0,NETWORKDAYS(J35,K35,Hoja2!$A$2:$A$53)) -> 18 | J35: 45929 | K35: 45953 | M35: =IF(OR(J35="",AND(L35="",TODAY()<J35),AND(L35<>"",L35<J35)),0, IF(L35="", NETWORKDAYS(J35,TODAY(),Hoja2!$A$2:$A$53), NETWORKDAYS(J35,L35,Hoja2!$A$2:$A$53) ) ) -> 177 | O35: 45953 | Q35: oct 01: se tuvo reunión con usuarios para alcaración de dudas con respecto a requerimientos oct 2: se determina un tiempo de desarrollo de 4 semanas oct 16: Faver realiza validación del requerimiento, con el fin de tener mas claridad de la solicitud por parte del cliente y el impacto que genera en el aplicativo oct 23: Se realizan pruebas y se envían evidencias al cliente para pruebas por parte de ellos oct 31: el cliente informa que las pruebas por parte de ellos fueron exitosas, se esta a la espera del paso a producción Marzo 06:De parte del cliente completaron las pruebas pero solo se paso una parte a producción Ellos deben terminar un ajuste y volver a probar el pendiente | R35: True
A36: Faver y Natalia | B36: 294 | C36: Ampliar plazo | D36: en la opción de informe de documentos eliminados, se requiere que sea de al menos 6 meses hacia atrás, para revisión de anulación de documentos | F36: FINALIZADO | G36: 100 | H36: =IF(OR(J36="",K36="",K36<J36),0,NETWORKDAYS(J36,K36,Hoja2!$A$2:$A$53)) -> 9 | J36: 45929 | K36: 45939 | L36: 45974 | M36: =IF(OR(J36="",AND(L36="",TODAY()<J36),AND(L36<>"",L36<J36)),0, IF(L36="", NETWORKDAYS(J36,TODAY(),Hoja2!$A$2:$A$53), NETWORKDAYS(J36,L36,Hoja2!$A$2:$A$53) ) ) -> 32 | O36: 45940 | P36: 45974 | Q36: oct 01: se tuvo reunión con usuarios para alcaración de dudas con respecto a requerimientos oct 2: se determina un tiempo de desarrollo de 4 semanas oct 10: se realizan pruebas de cambios ejecutados en el aplicativo oct 16: se realiza envio de evidencias de pruebas realizadas al cliente, con el fin de inicio de pruebas por parte de ellos. oct 21: el cliente indica que se finalizan pruebas por parte de ellos, siendo exitosas; estamos a la espera de fecha y aval para paso a producción nov 13: se realiza el paso a producción, siendo exitoso | R36: True
A37: Faver | B37: 295 | C37: Solicitudes Venta Cartera en Imagine | D37: Realizar consulta de clientes. | F37: FINALIZADO | G37: 100 | H37: =IF(OR(J37="",K37="",K37<J37),0,NETWORKDAYS(J37,K37,Hoja2!$A$2:$A$53)) -> 0 | J37: 45953 | L37: 45953 | M37: =IF(OR(J37="",AND(L37="",TODAY()<J37),AND(L37<>"",L37<J37)),0, IF(L37="", NETWORKDAYS(J37,TODAY(),Hoja2!$A$2:$A$53), NETWORKDAYS(J37,L37,Hoja2!$A$2:$A$53) ) ) -> 1 | R37: True
A38: Faver | B38: 296 | C38: Solicitud soportes y bases de morosos a corte 23 octubre | D38: Solicitud de usuario para generar base de morosos...como este es un reporte que se genera dos veces al mes, ya se tiene el query para generar la información | F38: FINALIZADO | G38: 100 | H38: =IF(OR(J38="",K38="",K38<J38),0,NETWORKDAYS(J38,K38,Hoja2!$A$2:$A$53)) -> 0 | J38: 45953 | L38: 45954 | M38: =IF(OR(J38="",AND(L38="",TODAY()<J38),AND(L38<>"",L38<J38)),0, IF(L38="", NETWORKDAYS(J38,TODAY(),Hoja2!$A$2:$A$53), NETWORKDAYS(J38,L38,Hoja2!$A$2:$A$53) ) ) -> 2 | Q38: Se realizo gestión de proceso y se envío informacion al usuario | R38: True
A39: Faver | B39: 297 | C39: Solicitudes Venta Cartera en Imagine | D39: Realizar consulta de clientes., primer paquete | F39: FINALIZADO | G39: 100 | H39: =IF(OR(J39="",K39="",K39<J39),0,NETWORKDAYS(J39,K39,Hoja2!$A$2:$A$53)) -> 0 | J39: 45954 | L39: 45954 | M39: =IF(OR(J39="",AND(L39="",TODAY()<J39),AND(L39<>"",L39<J39)),0, IF(L39="", NETWORKDAYS(J39,TODAY(),Hoja2!$A$2:$A$53), NETWORKDAYS(J39,L39,Hoja2!$A$2:$A$53) ) ) -> 1 | R39: True
A40: Faver | B40: 298 | C40: Solicitudes Venta Cartera en Imagine | D40: Realizar consulta de clientes., segundo paquete | F40: FINALIZADO | G40: 100 | H40: =IF(OR(J40="",K40="",K40<J40),0,NETWORKDAYS(J40,K40,Hoja2!$A$2:$A$53)) -> 0 | J40: 45954 | L40: 45954 | M40: =IF(OR(J40="",AND(L40="",TODAY()<J40),AND(L40<>"",L40<J40)),0, IF(L40="", NETWORKDAYS(J40,TODAY(),Hoja2!$A$2:$A$53), NETWORKDAYS(J40,L40,Hoja2!$A$2:$A$53) ) ) -> 1 | Q40: Se deben coordinar tiempos con Tuya | R40: True
...

Sheet Hoja2
A1: 45292 | B1: Año Nuevo
A2: 45299 | B2: Día de los Reyes Magos
A3: 45376 | B3: Día de San José
A4: 45379 | B4: Jueves Santo (Semana Santa)
A5: 45380 | B5: Viernes Santo (Semana Santa)
A6: 45413 | B6: Día del Trabajo
A7: 45425 | B7: Día de la Ascensión
A8: 45446 | B8: Corpus Christi
A9: 45453 | B9: Sagrado Corazón
A10: 45474 | B10: San Pedro y San Pablo
A11: 45493 | B11: Día de la Independencia
A12: 45511 | B12: Batalla de Boyacá
... A53: 46381 | B53: Navidad
